Workbook

Sheet info
A1: PPI Biostat Run #5.
B3: This biostat run will examine the oscillations and low oxygen levels
B4: A seed culture was grown in the sixfors (250 mL, 400 rpm, 1 vvm, pH 5.6, 10% inoculation from YPD) over the weekend.
A7: Initial seed | C7: Culture | D7: OD600 final
C8: 2 mL YPD O/N | D8: 4.84 | E8: 45584
A12: Sixfor seed | F12: #estimated initial OD
B13: Reactor | C13: Description | D13: Volume (no seed) | E13: Volume (w/seed) | F13: OD600 initial$ | G13: OD600 final | H13: pH initial | I13: Time of inoculation | J13: date of Inoculation | K13: RPM control | L13: Aeration Control | M13: pH setpoint | N13: Temp setpoint © | O13: Medium | P13: Species | Q13: file | R13: Note
B14: R1 | C14: seed for Biostat20_2L | D14: 250 mL | E14: 252 | J14: 45585 | K14: 400 | L14: 1 vvm | M14: 5.6 | N14: 30 | O14: YPD100 | P14: Ylip (W29) | Q14: PPI_sixfor_bstat21Seed
B15: R2 | C15: seed for Biostat20_2L | D15: 250 mL | E15: 252 | J15: 45585 | K15: 400 | L15: 1 vvm | M15: 5.6 | N15: 30 | O15: YPD100 | P15: Ylip (W29) | Q15: PPI_sixfor_bstat21Seed
B16: R3 | C16: seed for Biostat20_2L | D16: 250 mL | E16: 252 | J16: 45585 | K16: 400 | L16: 1 vvm | M16: 5.6 | N16: 30 | O16: YPD100 | P16: Ylip (W29) | Q16: PPI_sixfor_bstat21Seed
B17: R4 | C17: seed for Biostat20_2L | D17: 250 mL | E17: 252 | J17: 45585 | K17: 400 | L17: 1 vvm | M17: 5.6 | N17: 30 | O17: YPD100 | P17: Ylip (W29) | Q17: PPI_sixfor_bstat21Seed
A21: Biostat2L
B22: Reactor | C22: Description | D22: Volume (no seed) | E22: Volume (w/seed) | F22: OD600 initial | G22: pH initial | H22: Time of inoculation | I22: date of Inoculation | J22: RPM control | K22: Aeration Control | L22: pH setpoint | M22: Temp setpoint © | N22: Medium | O22: Species | P22: Note
B23: R1 | C23: YPD | D23: 1.4 | E23: 1.5 | O23: Ylp (W29)
B24: R2 | C24: YPD | D24: 1.4 | E24: 1.5 | O24: Ylp (W29)
H26: * changes in controls
H27: initial | I27: 400 (0%)-600(50%)-800(100%) | J27: 0.375 (0%)- 0.375 (50%) - 1.5 (100%)
H28: ~5-6 h | I28: 500 (0%)-600(50%)-800(100%) | J28: Kp from 90%-->200%; Ki from 50 s --> 90 s
H29: ~20.5 h | I29: 400 (0%)-600(50%)-800(100%) | J29: 0.375 (0%)- 0.5 (25%) - 1.5 (100%) | M29: ** based added, 37, 49 mL
G31: ** | H31: SAMPLES ALSO RECORDED EVERY 1 second instead of 5 seconds.

Sheet medium
A1: Medium | AA1: redford ratio
B2: Initial Medium. | AA2: 4.4277894 | AB2: C:N:P
AA3: C/N | AB3: =106/16 -> 6.625
C4: YPD | P4: molecular weight (m.w., g/mol) | S4: Yeast Nitrogen Base W/out Amino acids and Ammonium Sulfate (product number Y1251) | AA4: C/P | AB4: =106 -> 106
B5: 1 | C5: YPD100 | D5: Conc (g/L) | E5: Component | F5: C/N ratio low | G5: C/N ratio (high) | H5: C/P ratio* | I5: N/P ratio* | J5: mol C | K5: low mol N/L | L5: high mol N/L | M5: mol P/L | O5: Potassium Phosphate monobasic | P5: 136.086 | T5: chrome-extension://efaidnbmnnnibpcajpcglclefindmkaj/https://www.sigmaaldrich.com/deepweb/assets/sigmaaldrich/product/documents/411/890/Y1251dat.pdf | AA5: N/P | AB5: 16
C6: 10 | D6: =C6/D11 -> 1.6666667 | E6: Yeast extract | F6: =J6/K6 -> 74.801482 | G6: =J6/L6 -> 59.777253 | H6: =J6/M6 -> 453.2272 | I6: =K6/M6 -> 6.0590671 | J6: =D8/$P$7*6 -> 3.3304469 | K6: =D7*F13/100*1/14+F14/100*D6*1/14 -> 0.04452381 | L6: =D7*G13/100*1/14+G14/100*D6*1/14 -> 0.055714286 | M6: =T7/$P$5 -> 0.0073482945 | O6: Ammonium Sulfate | P6: 132.14 | T6: Conc (g/L) | U6: Component | V6: molecular weight (g/mol) | X6: mol/L
C7: 20 | D7: =C7/D11 -> 3.3333333 | E7: Peptone | O7: Glucose | P7: 180.156 | T7: 1 | U7: Potassium Phosphate monobasic | V7: 136.086
C8: 20 | D8: 100 | E8: Glucose | O8: Xylose | P8: 150.13 | T8: 0.5 | U8: magnesium sulfate
O9: Glycerol | P9: 92.094 | T9: 0.1 | U9: sodium chloride
D10: dilution | O10: Acetate | P10: 59.044 | T10: 0.1 | U10: calcium chloride
D11: 6 | O11: Citric acid | P11: 192.194 | T11: =SUM(T7:T10) -> 1.7 | U11: g/L total
B12: glucose with dilution | C12: glucose to add/L | F12: low (%) | G12: high (%) | O12: Ammonium Chloride | P12: 53.491 | T12: Trace elements
B13: =C8/D11 -> 3.3333333 | C13: =100-B13 -> 96.666667 | D13: =C13*1.5 -> 145 | E13: Peptone Nitrogen range | F13: 14.2 | G13: 17.4 | O13: urea | P13: 60.06 | T13: Conc (µg/L) | U13: Component
E14: Yeast extract Nitrogen range | F14: 9 | G14: 12 | T14: 500 | U14: Boric acid
C15: g of YPD broth to add /L | D15: L | E15: total to add. | T15: 40 | U15: Copper sulfate
C16: =50/D11 -> 8.3333333 | D16: 1.5 | E16: =D16*C16 -> 12.5 | T16: 100 | U16: Potassium iodide
T17: 200 | U17: Ferric Chloride
T18: 400 | U18: Manganese sulfate
T19: 200 | U19: Sodium molybdate
T20: 400 | U20: Zinc Sulfate
T21: =SUM(T14:T20)/1000000 -> 0.00184 | U21: g/L total
T22: Vitamins
T23: Conc (µg/L) | U23: Component
T24: 2 | U24: Biotin | X24: =550*0.3 -> 165
T25: 400 | U25: Calcium pantothenate
T26: 2 | U26: Folic acid
T27: 2000 | U27: Inositol
T28: 400 | U28: Niacin
T29: 200 | U29: p-Aminobeznoic acid
T30: 400 | U30: Pyridoxine hydrochloride
T31: 200 | U31: Riboflavin
T32: 400 | U32: Thiamine hydrochloride
T35: =SUM(T24:T32)/1000000 -> 0.004004 | U35: g/L total
E46: YNB-glucose
C47: Media | D47: YNB Seeds. | G47: High | H47: low | L47: low | M47: high
C48: 1 | D48: YNB-glucose-AC | E48: Conc (g/L) | F48: Component | G48: C/N ratio | H48: C/N ratio | I48: C/P ratio* | J48: N/P ratio* | K48: mol C | L48: mol N/L | M48: mol N/L | N48: mol P/L | P48: to add
E49: 1.7 | F49: Yeast Nitrogen Base W/out Amino acids and Ammonium Sulfate (product number Y1251) | G49: =K49/L49 -> 72.692801 | H49: =K49/M49 -> 70.388281 | I49: =K49/N49 -> 453.2272 | J49: =L49/N49 -> 6.2348293 | K49: =E51/$P$7*6 -> 3.3304469 | L49: =E50/P$12+E52*F14/100*1/14 -> 0.045815361 | M49: =E50/P$12+E52*G14/100*1/14 -> 0.047315361 | N49: =T7/$P$5 -> 0.0073482945 | P49: =E49*1.5 -> 2.55
E50: 2.21 | F50: Ammonium Chloride | P50: =E50*1.5 -> 3.315
E51: 100 | F51: Glucose | P51: =E51*1.5 -> 150
E52: 0.7 | F52: Yeast extract | P52: =E52*1.5 -> 1.05
...

Sheet vessel setup
A1: Agitation Propellers.
B2: Adjusted propellers to account for feeding of liquid into the medium.
B4: 2 cm from bottom for bottom impeller
B5: 4 cm from bottom impeller for top impeller

Sheet history_

Sheet metadata
B4: Strain | C4: inoculation | D4: initial working volume (L) | E4: Temperature (C ) | F4: Agitation | G4: Aeration | H4: Initial medium | I4: feed
B10: Final volume ~ 1.25 L | D10: 1.25 | E10: L
B11: Calculated volume ~ 1.47 L | D11: 1.41 | E11: L
D13: =(D11-D10)*1000 -> 160 | E13: mL evaporated
D14: 236.5 | E14: h fermented
D16: =D13/D14 -> 0.67653277 | E16: mL evaporated per hour
D18: 1 | E18: mL total
D19: =D11/D10 -> 1.128 | E19: times more titer at the end
C24: BlueVary start | D24: CO2 value | E24: 0.041
D25: O2 value | E25: 20.956

Sheet data
V12: moxiflow | Y12: DCW | AO12: rate | BD12: Results in g/L | BQ12: Calculations
A13: # | B13: SampleName | C13: Trehalose | D13: Citric Acid | E13: Glucose | F13: Xylose | G13: Erythritol | H13: Lactic Acid | I13: Glycerol | J13: Acetic Acid | K13: Ethanol | L13: Oxalic Acid | M13: Succinic Acid | N13: Fumaric | P13: date | Q13: time | R13: hour | S13: reactor | T13: sample number | U13: sample volume (mL) | V13: moxiflow D (µm) | W13: OD600 | X13: BASE (mL) | Y13: pre | Z13: post | AA13: volume | AB13: weight (g) | AC13: DCW (g/L) | AD13: FAME bio weight (mg) | AE13: FAME (mg) | AF13: FAME yield (g/g biomass) | AG13: FAME titer (g/L) | AI13: sugar consumed | AJ13: citrate rate | AK13: citrate yield | AL13: biomass rate | AM13: biomass yield | AN13: Fame rate (g/L/h) | AO13: FAME yield (g/g substrate) | AP13: specific sugar consumed (g/L) | AQ13: specific sugar consumed (g/L/h) | AR13: specific biomass rate (g/L/h) | AS13: specific biomass yield (g/g substrate) | AT13: specific citrate rate (g/L/h) | AU13: specific citrate yield (g/g substrate) | AV13: specific Fame (g/L/h) | AW13: total yields (g/g substrate) | BD13: Trehalose | BE13: Citric Acid | BF13: Glucose | BG13: Xylose | BH13: Erythritol | BI13: Lactic Acid | BJ13: Glycerol | BK13: Acetic Acid | BL13: Ethanol | BM13: Oxalic Acid | BN13: Succinic Acid | BO13: Fumaric Acid | BP13: date | BQ13: BLANK | BU13: Citrate (g/L) | BV13: estimated titer with evaporation | BW13: total sugar (g/L) | BX13: equivilant titer (g/L) | BY13: sugar consumed (g/L) | CA13: sugar consumption rates (g/L/h) | CB13: sugar consumed / timepoint | CC13: specific sugar consumption rate (g/L/h) | CD13: specifc biomass formation | CE13: biomass yield
B14: Jeff_SloHot50_Biostat 2L-23-1 | C14: 0.00848 | D14: 0.00349 | E14: 9.79118 | P14: 45602 | Q14: 0.55208333 | R14: 0.5 | S14: r1 | T14: 1 | V14: - | W14: 0.632 | X14: - | Y14: 7.1461 | Z14: 7.1488 | AA14: 8 | AB14: =Z14-Y14 -> 0.0027 | AC14: =AB14/(AA14/1000) -> 0.3375 | AD14: 13 | AE14: =FAMES!L15 -> 0.164 | AF14: =AE14/AD14 -> 0.012615385 | AG14: =AF14*AC14 -> 0.0042576923 | AI14: =$BF$14-BF14 -> 0 | AJ14: =BE14/R14 -> 0.0698 | AK14: =BE14/AI14 -> #DIV/0! | AL14: =AC14/R14 -> 0.675 | AM14: =AC14/AI14 -> #DIV/0! | BD14: =IF(ISNUMBER(C14),C14*1000/100,"") -> 0.0848 | BE14: =IF(ISNUMBER(D14),D14*1000/100,0) -> 0.0349 | BF14: =IF(ISNUMBER(E14),E14*1000/100,"") -> 97.9118 | BG14: =IF(ISNUMBER(F14),F14*1000/100,"") | BH14: =IF(ISNUMBER(G14),G14*1000/100,"") | BI14: =IF(ISNUMBER(H14),H14*1000/100,"") | BJ14: =IF(ISNUMBER(I14),I14*1000/100,"") | BK14: =IF(ISNUMBER(J14),J14*1000/100,"") | BL14: =IF(ISNUMBER(K14),K14*1000/100,"") | BM14: =IF(ISNUMBER(L14),L14*1000/100,"") | ... BO14: =IF(ISNUMBER(N14),N14*1000/100,"") | BQ14: =S14 -> r1 | BS14: =B14 -> Jeff_SloHot50_Biostat 2L-23-1 | BU14: =BE14 -> 0.0349 | BY14: =$BF$14-BF14 -> 0 | CA14: =BY14/R14 -> 0
B15: Jeff_SloHot50_Biostat 2L-23-2 | C15: 0.00917 | D15: 0.00387 | E15: 9.75068 | R15: 0.5 | S15: r2 | T15: 2 | V15: - | W15: 0.648 | X15: - | Y15: 7.1255 | Z15: 7.1284 | AA15: 8 | AB15: =Z15-Y15 -> 0.0029 | AC15: =AB15/(AA15/1000) -> 0.3625 | AD15: 6 | AE15: =FAMES!L16 -> 0.145 | AF15: =AE15/AD15 -> 0.024166667 | AG15: =AF15*AC15 -> 0.0087604167 | AI15: =$BF$15-BF15 -> 0 | AJ15: =BE15/R15 -> 0.0774 | AK15: =BE15/AI15 -> #DIV/0! | AL15: =AC15/R15 -> 0.725 | AM15: =AC15/AI15 -> #DIV/0! | BD15: =IF(ISNUMBER(C15),C15*1000/100,"") -> 0.0917 | BE15: =IF(ISNUMBER(D15),D15*1000/100,0) -> 0.0387 | BF15: =IF(ISNUMBER(E15),E15*1000/100,"") -> 97.5068 | BG15: =IF(ISNUMBER(F15),F15*1000/100,"") | BH15: =IF(ISNUMBER(G15),G15*1000/100,"") | BI15: =IF(ISNUMBER(H15),H15*1000/100,"") | BJ15: =IF(ISNUMBER(I15),I15*1000/100,"") | BK15: =IF(ISNUMBER(J15),J15*1000/100,"") | BL15: =IF(ISNUMBER(K15),K15*1000/100,"") | BM15: =IF(ISNUMBER(L15),L15*1000/100,"") | ... BO15: =IF(ISNUMBER(N15),N15*1000/100,"") | BQ15: =S15 -> r2 | BS15: =B15 -> Jeff_SloHot50_Biostat 2L-23-2 | BU15: =BE15 -> 0.0387 | BY15: =$BF$15-BF15 -> 0 | CA15: =BY15/R15 -> 0
B16: Jeff_SloHot50_Biostat 2L-23-3 | C16: 0.00845 | E16: 9.83995 | P16: 45602 | Q16: 0.6875 | R16: =R14+3.25 -> 3.75 | S16: r1 | T16: 3 | V16: - | W16: - | X16: - | Y16: 7.1552 | Z16: 7.1574 | AA16: 8 | AB16: =Z16-Y16 -> 0.0022 | AC16: =AB16/(AA16/1000) -> 0.275 | AD16: 3 | AE16: =FAMES!L17 -> 0.134 | AF16: =AE16/AD16 -> 0.044666667 | AG16: =AF16*AC16 -> 0.012283333 | AI16: =$BF$14-BF16 -> -0.4877 | AJ16: =BE16/R16 -> 0 | AK16: =BE16/AI16 -> 0 | AL16: =AC16/R16 -> 0.073333333 | AM16: =AC16/AI16 -> -0.56387123 | AP16: =BF14-BF16 -> -0.4877 | AQ16: =AP16/(R16-R14) -> -0.15006154 | AR16: =(AC16-AC14)/(AI16-AI14) -> 0.12815255 | AS16: =AR16/AQ16 -> -0.85399999 | AT16: =(BE16-BE14)/(AI16-AI14) -> 0.071560385 | AU16: =AT16/AP16 -> -0.14673034 | AW16: =AK16+AM16 -> -0.56387123 | BD16: =IF(ISNUMBER(C16),C16*1000/100,"") -> 0.0845 | BE16: =IF(ISNUMBER(D16),D16*1000/100,0) -> 0 | BF16: =IF(ISNUMBER(E16),E16*1000/100,"") -> 98.3995 | BG16: =IF(ISNUMBER(F16),F16*1000/100,"") | BH16: =IF(ISNUMBER(G16),G16*1000/100,"") | BI16: =IF(ISNUMBER(H16),H16*1000/100,"") | BJ16: =IF(ISNUMBER(I16),I16*1000/100,"") | BK16: =IF(ISNUMBER(J16),J16*1000/100,"") | BL16: =IF(ISNUMBER(K16),K16*1000/100,"") | BM16: =IF(ISNUMBER(L16),L16*1000/100,"") | ... BO16: =IF(ISNUMBER(N16),N16*1000/100,"") | BQ16: =S16 -> r1 | BS16: =B16 -> Jeff_SloHot50_Biostat 2L-23-3 | BU16: =BE16 -> 0 | BY16: =$BF$14-BF16 -> -0.4877 | CA16: =BY16/R16 -> -0.13005333 | CB16: =BY16-BY14 -> -0.4877 | CC16: =CB16/(R16-R14) -> -0.15006154 | CD16: =AC16-AC14 -> -0.0625 | CE16: =CD16/CB16 -> 0.12815255
B17: Jeff_SloHot50_Biostat 2L-23-4 | E17: 9.83409 | R17: =R15+3.25 -> 3.75 | S17: r2 | T17: 4 | V17: - | W17: - | X17: - | Y17: 7.1206 | Z17: 7.1236 | AA17: 8 | AB17: =Z17-Y17 -> 0.003 | AC17: =AB17/(AA17/1000) -> 0.375 | AD17: - | AE17: =FAMES!L18 -> 0.119 | AF17: =AE17/AD17 -> #VALUE! | AG17: =AF17*AC17 -> #VALUE! | AI17: =$BF$15-BF17 -> -0.8341 | AJ17: =BE17/R17 -> 0 | AK17: =BE17/AI17 -> 0 | AL17: =AC17/R17 -> 0.1 | AM17: =AC17/AI17 -> -0.44958638 | AP17: =BF15-BF17 -> -0.8341 | AQ17: =AP17/(R17-R15) -> -0.25664615 | AR17: =(AC17-AC15)/(AI17-AI15) -> -0.014986213 | AS17: =AR17/AQ17 -> 0.058392508 | AT17: =(BE17-BE15)/(AI17-AI15) -> 0.046397314 | AU17: =AT17/AP17 -> -0.055625602 | AW17: =AK17+AM17 -> -0.44958638 | BD17: =IF(ISNUMBER(C17),C17*1000/100,"") | BE17: =IF(ISNUMBER(D17),D17*1000/100,0) -> 0 | BF17: =IF(ISNUMBER(E17),E17*1000/100,"") -> 98.3409 | BG17: =IF(ISNUMBER(F17),F17*1000/100,"") | BH17: =IF(ISNUMBER(G17),G17*1000/100,"") | BI17: =IF(ISNUMBER(H17),H17*1000/100,"") | BJ17: =IF(ISNUMBER(I17),I17*1000/100,"") | BK17: =IF(ISNUMBER(J17),J17*1000/100,"") | BL17: =IF(ISNUMBER(K17),K17*1000/100,"") | BM17: =IF(ISNUMBER(L17),L17*1000/100,"") | ... BO17: =IF(ISNUMBER(N17),N17*1000/100,"") | BQ17: =S17 -> r2 | BS17: =B17 -> Jeff_SloHot50_Biostat 2L-23-4 | BU17: =BE17 -> 0 | BY17: =$BF$15-BF17 -> -0.8341 | CA17: =BY17/R17 -> -0.22242667 | CB17: =BY17-BY15 -> -0.8341 | CC17: =CB17/(R17-R15) -> -0.25664615 | CD17: =AC17-AC15 -> 0.0125 | CE17: =CD17/CB17 -> -0.014986213
B18: Jeff_SloHot50_Biostat 2L-23-5 | C18: 0.02806 | D18: 0.00579 | E18: 8.69831 | P18: 45603 | Q18: 0.30208333 | R18: =R16+12+2.75 -> 18.5 | S18: r1 | T18: 5 | V18: - | W18: - | X18: - | Y18: 7.1404 | Z18: 7.2002 | AA18: 8 | AB18: =Z18-Y18 -> 0.0598 | AC18: =AB18/(AA18/1000) -> 7.475 | AD18: 13.4 | AE18: =FAMES!L19 -> 0.837 | AF18: =AE18/AD18 -> 0.062462687 | AG18: =AF18*AC18 -> 0.46690858 | AI18: =$BF$14-BF18 -> 10.9287 | AJ18: =BE18/R18 -> 0.0031297297 | AK18: =BE18/AI18 -> 0.0052979769 | AL18: =AC18/R18 -> 0.40405405 | AM18: =AC18/AI18 -> 0.68397888 | AP18: =BF16-BF18 -> 11.4164 | AQ18: =AP18/(R18-R16) -> 0.77399322 | AR18: =(AC18-AC16)/(AI18-AI16) -> 0.63067167 | AS18: =AR18/AQ18 -> 0.81482841 | AT18: =(BE18-BE16)/(AI18-AI16) -> 0.0050716513 | AU18: =AT18/AP18 -> 0.00044424261 | AW18: =AK18+AM18 -> 0.68927686 | BD18: =IF(ISNUMBER(C18),C18*1000/100,"") -> 0.2806 | BE18: =IF(ISNUMBER(D18),D18*1000/100,0) -> 0.0579 | BF18: =IF(ISNUMBER(E18),E18*1000/100,"") -> 86.9831 | BG18: =IF(ISNUMBER(F18),F18*1000/100,"") | BH18: =IF(ISNUMBER(G18),G18*1000/100,"") | BI18: =IF(ISNUMBER(H18),H18*1000/100,"") | BJ18: =IF(ISNUMBER(I18),I18*1000/100,"") | BK18: =IF(ISNUMBER(J18),J18*1000/100,"") | BL18: =IF(ISNUMBER(K18),K18*1000/100,"") | BM18: =IF(ISNUMBER(L18),L18*1000/100,"") | ... BO18: =IF(ISNUMBER(N18),N18*1000/100,"") | BQ18: =S18 -> r1 | BS18: =B18 -> Jeff_SloHot50_Biostat 2L-23-5 | BU18: =BE18 -> 0.0579 | BY18: =$BF$14-BF18 -> 10.9287 | CA18: =BY18/R18 -> 0.59074054 | CB18: =BY18-BY16 -> 11.4164 | CC18: =CB18/(R18-R16) -> 0.77399322
B19: Jeff_SloHot50_Biostat 2L-23-6 | C19: 0.0252 | E19: 9.01807 | R19: =R17+12+2.75 -> 18.5 | S19: r2 | T19: 6 | V19: - | W19: - | X19: - | Y19: 7.4392 | Z19: 7.5015 | AA19: 8 | AB19: =Z19-Y19 -> 0.0623 | AC19: =AB19/(AA19/1000) -> 7.7875 | AD19: 18.5 | AE19: =FAMES!L20 -> 0.9445 | AF19: =AE19/AD19 -> 0.051054054 | AG19: =AF19*AC19 -> 0.39758345 | AI19: =$BF$15-BF19 -> 7.3261 | AJ19: =BE19/R19 -> 0 | AK19: =BE19/AI19 -> 0 | AL19: =AC19/R19 -> 0.42094595 | AM19: =AC19/AI19 -> 1.0629803 | AP19: =BF17-BF19 -> 8.1602 | AQ19: =AP19/(R19-R17) -> 0.5532339 | AR19: =(AC19-AC17)/(AI19-AI17) -> 0.90837234 | AS19: =AR19/AQ19 -> 1.6419318 | AT19: =(BE19-BE17)/(AI19-AI17) -> 0 | AU19: =AT19/AP19 -> 0 | AW19: =AK19+AM19 -> 1.0629803 | BD19: =IF(ISNUMBER(C19),C19*1000/100,"") -> 0.252 | BE19: =IF(ISNUMBER(D19),D19*1000/100,0) -> 0 | BF19: =IF(ISNUMBER(E19),E19*1000/100,"") -> 90.1807 | BG19: =IF(ISNUMBER(F19),F19*1000/100,"") | BH19: =IF(ISNUMBER(G19),G19*1000/100,"") | BI19: =IF(ISNUMBER(H19),H19*1000/100,"") | BJ19: =IF(ISNUMBER(I19),I19*1000/100,"") | BK19: =IF(ISNUMBER(J19),J19*1000/100,"") | BL19: =IF(ISNUMBER(K19),K19*1000/100,"") | BM19: =IF(ISNUMBER(L19),L19*1000/100,"") | ... BO19: =IF(ISNUMBER(N19),N19*1000/100,"") | BQ19: =S19 -> r2 | BS19: =B19 -> Jeff_SloHot50_Biostat 2L-23-6 | BU19: =BE19 -> 0 | BY19: =$BF$15-BF19 -> 7.3261 | CA19: =BY19/R19 -> 0.39600541 | CB19: =BY19-BY17 -> 8.1602 | CC19: =CB19/(R19-R17) -> 0.5532339
B20: Jeff_SloHot50_Biostat 2L-23-7 | C20: 0.04216 | D20: 0.027 | E20: 8.4095 | Q20: 0.46875 | R20: =R18+4 -> 22.5 | S20: r1 | T20: 7 | V20: - | W20: 16.46 | X20: 19 | Y20: 7.1512 | Z20: 7.215 | AA20: 8 | AB20: =Z20-Y20 -> 0.0638 | AC20: =AB20/(AA20/1000) -> 7.975 | AD20: 13.6 | AE20: =FAMES!L21 -> 1.1905 | AF20: =AE20/AD20 -> 0.087536765 | AG20: =AF20*AC20 -> 0.6981057 | AI20: =$BF$14-BF20 -> 13.8168 | AJ20: =BE20/R20 -> 0.012 | AK20: =BE20/AI20 -> 0.019541428 | AL20: =AC20/R20 -> 0.35444444 | AM20: =AC20/AI20 -> 0.57719588 | AP20: =BF18-BF20 -> 2.8881 | AQ20: =AP20/(R20-R18) -> 0.722025 | AR20: =(AC20-AC18)/(AI20-AI18) -> 0.1731242 | AS20: =AR20/AQ20 -> 0.23977591 | AT20: =(BE20-BE18)/(AI20-AI18) -> 0.073439285 | AU20: =AT20/AP20 -> 0.025428235 | AW20: =AK20+AM20 -> 0.59673731 | BD20: =IF(ISNUMBER(C20),C20*1000/100,"") -> 0.4216 | BE20: =IF(ISNUMBER(D20),D20*1000/100,0) -> 0.27 | BF20: =IF(ISNUMBER(E20),E20*1000/100,"") -> 84.095 | BG20: =IF(ISNUMBER(F20),F20*1000/100,"") | BH20: =IF(ISNUMBER(G20),G20*1000/100,"") | BI20: =IF(ISNUMBER(H20),H20*1000/100,"") | BJ20: =IF(ISNUMBER(I20),I20*1000/100,"") | BK20: =IF(ISNUMBER(J20),J20*1000/100,"") | BL20: =IF(ISNUMBER(K20),K20*1000/100,"") | BM20: =IF(ISNUMBER(L20),L20*1000/100,"") | ... BO20: =IF(ISNUMBER(N20),N20*1000/100,"") | BQ20: =S20 -> r1 | BS20: =B20 -> Jeff_SloHot50_Biostat 2L-23-7 | BU20: =BE20 -> 0.27 | BY20: =$BF$14-BF20 -> 13.8168 | CA20: =BY20/R20 -> 0.61408 | CB20: =BY20-BY18 -> 2.8881 | CC20: =CB20/(R20-R18) -> 0.722025
B21: Jeff_SloHot50_Biostat 2L-23-8 | C21: 0.03302 | E21: 8.78483 | R21: =R19+4 -> 22.5 | S21: r2 | T21: 8 | V21: - | W21: 16.56 | X21: 11 | Y21: 7.1276 | Z21: 7.1892 | AA21: 8 | AB21: =Z21-Y21 -> 0.0616 | AC21: =AB21/(AA21/1000) -> 7.7 | AD21: 15.5 | AE21: =FAMES!L22 -> 1.097 | AF21: =AE21/AD21 -> 0.070774194 | AG21: =AF21*AC21 -> 0.54496129 | AI21: =$BF$15-BF21 -> 9.6585 | AJ21: =BE21/R21 -> 0 | AK21: =BE21/AI21 -> 0 | AL21: =AC21/R21 -> 0.34222222 | AM21: =AC21/AI21 -> 0.79722524 | AP21: =BF19-BF21 -> 2.3324 | AQ21: =AP21/(R21-R19) -> 0.5831 | AR21: =(AC21-AC19)/(AI21-AI19) -> -0.037515006 | AS21: =AR21/AQ21 -> -0.064337174 | AT21: =(BE21-BE19)/(AI21-AI19) -> 0 | AU21: =AT21/AP21 -> 0 | AW21: =AK21+AM21 -> 0.79722524 | BD21: =IF(ISNUMBER(C21),C21*1000/100,"") -> 0.3302 | BE21: =IF(ISNUMBER(D21),D21*1000/100,0) -> 0 | BF21: =IF(ISNUMBER(E21),E21*1000/100,"") -> 87.8483 | BG21: =IF(ISNUMBER(F21),F21*1000/100,"") | BH21: =IF(ISNUMBER(G21),G21*1000/100,"") | BI21: =IF(ISNUMBER(H21),H21*1000/100,"") | BJ21: =IF(ISNUMBER(I21),I21*1000/100,"") | BK21: =IF(ISNUMBER(J21),J21*1000/100,"") | BL21: =IF(ISNUMBER(K21),K21*1000/100,"") | BM21: =IF(ISNUMBER(L21),L21*1000/100,"") | ... BO21: =IF(ISNUMBER(N21),N21*1000/100,"") | BQ21: =S21 -> r2 | BS21: =B21 -> Jeff_SloHot50_Biostat 2L-23-8 | BU21: =BE21 -> 0 | BY21: =$BF$15-BF21 -> 9.6585 | CA21: =BY21/R21 -> 0.42926667 | CB21: =BY21-BY19 -> 2.3324 | CC21: =CB21/(R21-R19) -> 0.5831
B22: Jeff_SloHot50_Biostat 2L-23-9 | C22: 0.04332 | D22: 0.09277 | E22: 7.98779 | Q22: 0.66666667 | R22: =R20+3+0.75 -> 26.25 | S22: r1 | T22: 9 | V22: - | W22: 23.44 | X22: 22 | Y22: 7.16 | Z22: 7.2432 | AA22: 8 | AB22: =Z22-Y22 -> 0.0832 | AC22: =AB22/(AA22/1000) -> 10.4 | AD22: 17 | AE22: =FAMES!L23 -> 1.547 | AF22: =AE22/AD22 -> 0.091 | AG22: =AF22*AC22 -> 0.9464 | AI22: =$BF$14-BF22 -> 18.0339 | AJ22: =BE22/R22 -> 0.035340952 | AK22: =BE22/AI22 -> 0.051442006 | AL22: =AC22/R22 -> 0.39619048 | AM22: =AC22/AI22 -> 0.57669168 | AP22: =BF20-BF22 -> 4.2171 | AQ22: =AP22/(R22-R20) -> 1.12456 | AR22: =(AC22-AC20)/(AI22-AI20) -> 0.57503972 | AS22: =AR22/AQ22 -> 0.51134641 | AT22: =(BE22-BE20)/(AI22-AI20) -> 0.15596026 | AU22: =AT22/AP22 -> 0.036982822 | AW22: =AK22+AM22 -> 0.62813368 | BD22: =IF(ISNUMBER(C22),C22*1000/100,"") -> 0.4332 | BE22: =IF(ISNUMBER(D22),D22*1000/100,0) -> 0.9277 | BF22: =IF(ISNUMBER(E22),E22*1000/100,"") -> 79.8779 | BG22: =IF(ISNUMBER(F22),F22*1000/100,"") | BH22: =IF(ISNUMBER(G22),G22*1000/100,"") | BI22: =IF(ISNUMBER(H22),H22*1000/100,"") | BJ22: =IF(ISNUMBER(I22),I22*1000/100,"") | BK22: =IF(ISNUMBER(J22),J22*1000/100,"") | BL22: =IF(ISNUMBER(K22),K22*1000/100,"") | BM22: =IF(ISNUMBER(L22),L22*1000/100,"") | ... BO22: =IF(ISNUMBER(N22),N22*1000/100,"") | BQ22: =S24 -> r1 | BS22: =B22 -> Jeff_SloHot50_Biostat 2L-23-9 | BU22: =BE22 -> 0.9277 | BY22: =$BF$14-BF22 -> 18.0339 | CA22: =BY22/R24 -> 0.41220343 | CB22: =BY22-BY20 -> 4.2171 | CC22: =CB22/(R24-R20) -> 0.19845176 | CD22: =AC22-AC16 -> 10.125 | CE22: =CD22/CB22 -> 2.400939
B23: Jeff_SloHot50_Biostat 2L-23-10 | C23: 0.04163 | D23: 0.02981 | E23: 8.41679 | R23: =R21+3.75 -> 26.25 | S23: r2 | T23: 10 | V23: - | W23: 23.68 | X23: 13 | Y23: 7.1661 | Z23: 7.2542 | AA23: 8 | AB23: =Z23-Y23 -> 0.0881 | AC23: =AB23/(AA23/1000) -> 11.0125 | AD23: 12.6 | AE23: =FAMES!L24 -> 0.917 | AF23: =AE23/AD23 -> 0.072777778 | AG23: =AF23*AC23 -> 0.80146528 | AI23: =$BF$15-BF23 -> 13.3389 | AJ23: =BE23/R23 -> 0.01135619 | AK23: =BE23/AI23 -> 0.02234817 | AL23: =AC23/R23 -> 0.41952381 | AM23: =AC23/AI23 -> 0.82559281 | AP23: =BF21-BF23 -> 3.6804 | AQ23: =AP23/(R23-R21) -> 0.98144 | AR23: =(AC23-AC21)/(AI23-AI21) -> 0.90003804 | AS23: =AR23/AQ23 -> 0.91705865 | AT23: =(BE23-BE21)/(AI23-AI21) -> 0.080996631 | AU23: =AT23/AP23 -> 0.022007562 | AW23: =AK23+AM23 -> 0.84794098 | BD23: =IF(ISNUMBER(C23),C23*1000/100,"") -> 0.4163 | BE23: =IF(ISNUMBER(D23),D23*1000/100,0) -> 0.2981 | BF23: =IF(ISNUMBER(E23),E23*1000/100,"") -> 84.1679 | BG23: =IF(ISNUMBER(F23),F23*1000/100,"") | BH23: =IF(ISNUMBER(G23),G23*1000/100,"") | BI23: =IF(ISNUMBER(H23),H23*1000/100,"") | BJ23: =IF(ISNUMBER(I23),I23*1000/100,"") | BK23: =IF(ISNUMBER(J23),J23*1000/100,"") | BL23: =IF(ISNUMBER(K23),K23*1000/100,"") | BM23: =IF(ISNUMBER(L23),L23*1000/100,"") | ... BO23: =IF(ISNUMBER(N23),N23*1000/100,"") | BQ23: =S25 -> r2 | BS23: =B23 -> Jeff_SloHot50_Biostat 2L-23-10 | BU23: =BE23 -> 0.2981 | BY23: =$BF$15-BF23 -> 13.3389 | CA23: =BY23/R25 -> 0.30488914 | CB23: =BY23-BY21 -> 3.6804 | CC23: =CB23/(R25-R21) -> 0.17319529 | CD23: =AC23-AC17 -> 10.6375 | CE23: =CD23/CB23 -> 2.8903108
B24: Jeff_SloHot50_Biostat 2L-23-11 | C24: 0.04253 | D24: 0.43969 | E24: 7.03516 | P24: 45604 | Q24: 0.39583333 | R24: =R22+12+5.5 -> 43.75 | S24: r1 | T24: 11 | V24: - | W24: 30.25 | X24: 37 | Y24: 7.1431 | Z24: 7.2436 | AA24: 8 | AB24: =Z24-Y24 -> 0.1005 | AC24: =AB24/(AA24/1000) -> 12.5625 | AD24: 15.8 | AE24: =FAMES!L25 -> 2.1085 | AF24: =AE24/AD24 -> 0.13344937 | AG24: =AF24*AC24 -> 1.6764577 | AI24: =$BF$14-BF24 -> 27.5602 | AJ24: =BE24/R24 -> 0.10050057 | AK24: =BE24/AI24 -> 0.15953803 | AL24: =AC24/R24 -> 0.28714286 | AM24: =AC24/AI24 -> 0.45582035 | AP24: =BF22-BF24 -> 9.5263 | AQ24: =AP24/(R24-R22) -> 0.54436 | AR24: =(AC24-AC22)/(AI24-AI22) -> 0.22700314 | AS24: =AR24/AQ24 -> 0.41700922 | AT24: =(BE24-BE22)/(AI24-AI22) -> 0.36417077 | AU24: =AT24/AP24 -> 0.038227934 | AW24: =AK24+AM24 -> 0.61535838 | BD24: =IF(ISNUMBER(C24),C24*1000/100,"") -> 0.4253 | BE24: =IF(ISNUMBER(D24),D24*1000/100,0) -> 4.3969 | BF24: =IF(ISNUMBER(E24),E24*1000/100,"") -> 70.3516 | BG24: =IF(ISNUMBER(F24),F24*1000/100,"") | BH24: =IF(ISNUMBER(G24),G24*1000/100,"") | BI24: =IF(ISNUMBER(H24),H24*1000/100,"") | BJ24: =IF(ISNUMBER(I24),I24*1000/100,"") | BK24: =IF(ISNUMBER(J24),J24*1000/100,"") | BL24: =IF(ISNUMBER(K24),K24*1000/100,"") | BM24: =IF(ISNUMBER(L24),L24*1000/100,"") | ... BO24: =IF(ISNUMBER(N24),N24*1000/100,"") | BQ24: =S26 -> r1 | BS24: =B24 -> Jeff_SloHot50_Biostat 2L-23-11 | BU24: =BE24 -> 4.3969 | BY24: =$BF$14-BF24 -> 27.5602 | CA24: =BY24/R26 -> 0.58119359 | CB24: =BY24-BY22 -> 9.5263 | CC24: =CB24/(R26-R24) -> 2.5957221
B25: Jeff_SloHot50_Biostat 2L-23-12 | C25: 0.0433 | D25: 0.26967 | E25: 7.29352 | R25: =R23+12+5.5 -> 43.75 | S25: r2 | T25: 12 | V25: - | W25: 34.35 | X25: 24 | Y25: 7.1243 | Z25: 7.234 | AA25: 8 | AB25: =Z25-Y25 -> 0.1097 | AC25: =AB25/(AA25/1000) -> 13.7125 | AD25: 20 | AE25: =FAMES!L26 -> 2.432 | AF25: =AE25/AD25 -> 0.1216 | AG25: =AF25*AC25 -> 1.66744 | AI25: =$BF$15-BF25 -> 24.5716 | AJ25: =BE25/R25 -> 0.061638857 | AK25: =BE25/AI25 -> 0.10974865 | AL25: =AC25/R25 -> 0.31342857 | AM25: =AC25/AI25 -> 0.55806297 | AP25: =BF23-BF25 -> 11.2327 | AQ25: =AP25/(R25-R23) -> 0.64186857 | AR25: =(AC25-AC23)/(AI25-AI23) -> 0.24036964 | AS25: =AR25/AQ25 -> 0.37448419 | AT25: =(BE25-BE23)/(AI25-AI23) -> 0.21353726 | AU25: =AT25/AP25 -> 0.019010324 | AW25: =AK25+AM25 -> 0.66781162 | BD25: =IF(ISNUMBER(C25),C25*1000/100,"") -> 0.433 | BE25: =IF(ISNUMBER(D25),D25*1000/100,0) -> 2.6967 | BF25: =IF(ISNUMBER(E25),E25*1000/100,"") -> 72.9352 | BG25: =IF(ISNUMBER(F25),F25*1000/100,"") | BH25: =IF(ISNUMBER(G25),G25*1000/100,"") | BI25: =IF(ISNUMBER(H25),H25*1000/100,"") | BJ25: =IF(ISNUMBER(I25),I25*1000/100,"") | BK25: =IF(ISNUMBER(J25),J25*1000/100,"") | BL25: =IF(ISNUMBER(K25),K25*1000/100,"") | BM25: =IF(ISNUMBER(L25),L25*1000/100,"") | ... BO25: =IF(ISNUMBER(N25),N25*1000/100,"") | BQ25: =S27 -> r2 | BS25: =B25 -> Jeff_SloHot50_Biostat 2L-23-12 | BU25: =BE25 -> 2.6967 | BY25: =$BF$15-BF25 -> 24.5716 | CA25: =BY25/R27 -> 0.51816955 | CB25: =BY25-BY23 -> 11.2327 | CC25: =CB25/(R27-R25) -> 3.0606812
B26: Jeff_SloHot50_Biostat 2L-23-13 | C26: 0.03985 | D26: 0.54816 | E26: 6.72942 | Q26: 0.54861111 | R26: =R24+3.67 -> 47.42 | S26: r1 | T26: 13 | V26: - | W26: 27.55 | X26: 41 | Y26: 7.2564 | Z26: 7.3654 | AA26: 8 | AB26: =Z26-Y26 -> 0.109 | AC26: =AB26/(AA26/1000) -> 13.625 | AD26: 15 | AE26: =FAMES!L27 -> 1.962 | AF26: =AE26/AD26 -> 0.1308 | AG26: =AF26*AC26 -> 1.78215 | AI26: =$BF$14-BF26 -> 30.6176 | AJ26: =BE26/R26 -> 0.11559679 | AK26: =BE26/AI26 -> 0.17903428 | AL26: =AC26/R26 -> 0.28732602 | AM26: =AC26/AI26 -> 0.44500549 | AP26: =BF24-BF26 -> 3.0574 | AQ26: =AP26/(R26-R24) -> 0.83307902 | AR26: =(AC26-AC24)/(AI26-AI24) -> 0.3475175 | AS26: =AR26/AQ26 -> 0.4171483 | AT26: =(BE26-BE24)/(AI26-AI24) -> 0.35477857 | AU26: =AT26/AP26 -> 0.1160393 | AW26: =AK26+AM26 -> 0.62403977 | BD26: =IF(ISNUMBER(C26),C26*1000/100,"") -> 0.3985 | BE26: =IF(ISNUMBER(D26),D26*1000/100,0) -> 5.4816 | BF26: =IF(ISNUMBER(E26),E26*1000/100,"") -> 67.2942 | BG26: =IF(ISNUMBER(F26),F26*1000/100,"") | BH26: =IF(ISNUMBER(G26),G26*1000/100,"") | BI26: =IF(ISNUMBER(H26),H26*1000/100,"") | BJ26: =IF(ISNUMBER(I26),I26*1000/100,"") | BK26: =IF(ISNUMBER(J26),J26*1000/100,"") | BL26: =IF(ISNUMBER(K26),K26*1000/100,"") | BM26: =IF(ISNUMBER(L26),L26*1000/100,"") | ... BO26: =IF(ISNUMBER(N26),N26*1000/100,"") | BQ26: =S28 -> r1 | BS26: =B26 -> Jeff_SloHot50_Biostat 2L-23-13 | BU26: =BE26 -> 5.4816 | BY26: =$BF$15-BF26 -> 30.2126 | CA26: =BY26/R28 -> 0.5972404 | CB26: =BY26-BY24 -> 2.6524 | CC26: =CB26/(R28-R26) -> 0.83751184
B27: Jeff_SloHot50_Biostat 2L-23-14 | C27: 0.04348 | D27: 0.36614 | E27: 7.0627 | R27: =R25+3.67 -> 47.42 | S27: r2 | T27: 14 | V27: - | W27: 33.1 | X27: 29 | Y27: 7.1276 | Z27: 7.2574 | AA27: 8 | AB27: =Z27-Y27 -> 0.1298 | AC27: =AB27/(AA27/1000) -> 16.225 | AD27: 10.5 | AE27: =FAMES!L28 -> 1.668 | AF27: =AE27/AD27 -> 0.15885714 | AG27: =AF27*AC27 -> 2.5774571 | AI27: =$BF$15-BF27 -> 26.8798 | AJ27: =BE27/R27 -> 0.077212147 | AK27: =BE27/AI27 -> 0.13621381 | AL27: =AC27/R27 -> 0.34215521 | AM27: =AC27/AI27 -> 0.60361312 | AP27: =BF25-BF27 -> 2.3082 | AQ27: =AP27/(R27-R25) -> 0.62893733 | AR27: =(AC27-AC25)/(AI27-AI25) -> 1.0885105 | AS27: =AR27/AQ27 -> 1.7307138 | AT27: =(BE27-BE25)/(AI27-AI25) -> 0.41794472 | AU27: =AT27/AP27 -> 0.18106954 | AW27: =AK27+AM27 -> 0.73982693 | BD27: =IF(ISNUMBER(C27),C27*1000/100,"") -> 0.4348 | BE27: =IF(ISNUMBER(D27),D27*1000/100,0) -> 3.6614 | BF27: =IF(ISNUMBER(E27),E27*1000/100,"") -> 70.627 | BG27: =IF(ISNUMBER(F27),F27*1000/100,"") | BH27: =IF(ISNUMBER(G27),G27*1000/100,"") | BI27: =IF(ISNUMBER(H27),H27*1000/100,"") | BJ27: =IF(ISNUMBER(I27),I27*1000/100,"") | BK27: =IF(ISNUMBER(J27),J27*1000/100,"") | BL27: =IF(ISNUMBER(K27),K27*1000/100,"") | BM27: =IF(ISNUMBER(L27),L27*1000/100,"") | ... BO27: =IF(ISNUMBER(N27),N27*1000/100,"") | BQ27: =S29 -> r2 | BS27: =B27 -> Jeff_SloHot50_Biostat 2L-23-14 | BU27: =BE27 -> 3.6614 | BY27: =$BF$15-BF27 -> 26.8798 | CA27: =BY27/R29 -> 0.53135786 | CB27: =BY27-BY25 -> 2.3082 | CC27: =CB27/(R29-R27) -> 0.72882854
B28: Jeff_SloHot50_Biostat 2L-23-15 | C28: 0.03881 | D28: 0.63627 | E28: 6.62925 | Q28: 0.68055556 | R28: =R26+3.167 -> 50.587 | S28: r1 | T28: 15 | W28: 34.8 | X28: 45 | Y28: 7.263 | Z28: 7.3673 | AA28: 8 | AB28: =Z28-Y28 -> 0.1043 | AC28: =AB28/(AA28/1000) -> 13.0375 | AD28: 15 | AE28: =FAMES!L29 -> 2.1875 | AF28: =AE28/AD28 -> 0.14583333 | AG28: =AF28*AC28 -> 1.9013021 | AI28: =$BF$14-BF28 -> 31.6193 | AJ28: =BE28/R28 -> 0.12577737 | AK28: =BE28/AI28 -> 0.20122836 | AL28: =AC28/R28 -> 0.25772432 | AM28: =AC28/AI28 -> 0.41232728 | AP28: =BF26-BF28 -> 1.0017 | AQ28: =AP28/(R28-R26) -> 0.31629302 | AR28: =(AC28-AC26)/(AI28-AI26) -> -0.58650294 | AS28: =AR28/AQ28 -> -1.8543025 | AT28: =(BE28-BE26)/(AI28-AI26) -> 0.87960467 | AU28: =AT28/AP28 -> 0.87811188 | AW28: =AK28+AM28 -> 0.61355564 | BD28: =IF(ISNUMBER(C28),C28*1000/100,"") -> 0.3881 | BE28: =IF(ISNUMBER(D28),D28*1000/100,0) -> 6.3627 | BF28: =IF(ISNUMBER(E28),E28*1000/100,"") -> 66.2925 | BG28: =IF(ISNUMBER(F28),F28*1000/100,"") | BH28: =IF(ISNUMBER(G28),G28*1000/100,"") | BI28: =IF(ISNUMBER(H28),H28*1000/100,"") | BJ28: =IF(ISNUMBER(I28),I28*1000/100,"") | BK28: =IF(ISNUMBER(J28),J28*1000/100,"") | BL28: =IF(ISNUMBER(K28),K28*1000/100,"") | BM28: =IF(ISNUMBER(L28),L28*1000/100,"") | ... BO28: =IF(ISNUMBER(N28),N28*1000/100,"") | BQ28: =S30 -> r1 | BS28: =B28 -> Jeff_SloHot50_Biostat 2L-23-15 | BU28: =BE28 -> 6.3627 | BY28: =$BF$15-BF28 -> 31.2143 | CA28: =BY28/R30 -> 0.44749118 | CB28: =BY28-BY26 -> 1.0017 | CC28: =CB28/(R30-R28) -> 0.0522617
B29: Jeff_SloHot50_Biostat 2L-23-16 | C29: 0.04326 | D29: 0.46219 | E29: 6.84351 | R29: =R27+3.167 -> 50.587 | S29: r2 | T29: 16 | W29: 40.6 | X29: 34 | Y29: 7.1247 | Z29: 7.2512 | AA29: 8 | AB29: =Z29-Y29 -> 0.1265 | AC29: =AB29/(AA29/1000) -> 15.8125 | AD29: 14 | AE29: =FAMES!L30 -> 2.115 | AF29: =AE29/AD29 -> 0.15107143 | AG29: =AF29*AC29 -> 2.388817 | AI29: =$BF$15-BF29 -> 29.0717 | AJ29: =BE29/R29 -> 0.091365371 | AK29: =BE29/AI29 -> 0.15898279 | AL29: =AC29/R29 -> 0.31258031 | AM29: =AC29/AI29 -> 0.54391384 | AP29: =BF27-BF29 -> 2.1919 | AQ29: =AP29/(R29-R27) -> 0.69210609 | AR29: =(AC29-AC27)/(AI29-AI27) -> -0.18819289 | AS29: =AR29/AQ29 -> -0.27191336 | AT29: =(BE29-BE27)/(AI29-AI27) -> 0.4382043 | AU29: =AT29/AP29 -> 0.19991984 | AW29: =AK29+AM29 -> 0.70289663 | BD29: =IF(ISNUMBER(C29),C29*1000/100,"") -> 0.4326 | BE29: =IF(ISNUMBER(D29),D29*1000/100,0) -> 4.6219 | BF29: =IF(ISNUMBER(E29),E29*1000/100,"") -> 68.4351 | BG29: =IF(ISNUMBER(F29),F29*1000/100,"") | BH29: =IF(ISNUMBER(G29),G29*1000/100,"") | BI29: =IF(ISNUMBER(H29),H29*1000/100,"") | BJ29: =IF(ISNUMBER(I29),I29*1000/100,"") | BK29: =IF(ISNUMBER(J29),J29*1000/100,"") | BL29: =IF(ISNUMBER(K29),K29*1000/100,"") | BM29: =IF(ISNUMBER(L29),L29*1000/100,"") | ... BO29: =IF(ISNUMBER(N29),N29*1000/100,"") | BQ29: =S31 -> r2 | BS29: =B29 -> Jeff_SloHot50_Biostat 2L-23-16 | BU29: =BE29 -> 4.6219 | BY29: =$BF$15-BF29 -> 29.0717 | CA29: =BY29/R31 -> 0.41677467 | CB29: =BY29-BY27 -> 2.1919 | CC29: =CB29/(R31-R29) -> 0.11435801
B30: Jeff_SloHot50_Biostat 2L-23-17 | C30: 0.04149 | D30: 1.13281 | E30: 5.82304 | P30: 45605 | Q30: 0.47916667 | R30: =R28+12+7.167 -> 69.754 | S30: r1 | T30: 17 | W30: 29.16 | X30: 70 | Y30: 7.1244 | Z30: 7.2425 | AA30: 8 | AB30: =Z30-Y30 -> 0.1181 | AC30: =AB30/(AA30/1000) -> 14.7625 | AD30: 15.7 | AE30: =FAMES!L31 -> 2.102 | AF30: =AE30/AD30 -> 0.13388535 | AG30: =AF30*AC30 -> 1.9764825 | AI30: =$BF$14-BF30 -> 39.6814 | AJ30: =BE30/R30 -> 0.16240072 | AK30: =BE30/AI30 -> 0.28547632 | AL30: =AC30/R30 -> 0.21163661 | AM30: =AC30/AI30 -> 0.37202568 | AP30: =BF28-BF30 -> 8.0621 | AQ30: =AP30/(R30-R28) -> 0.42062399 | AR30: =(AC30-AC28)/(AI30-AI28) -> 0.2139641 | AS30: =AR30/AQ30 -> 0.5086826 | AT30: =(BE30-BE28)/(AI30-AI28) -> 0.61589412 | AU30: =AT30/AP30 -> 0.076393759 | AW30: =AK30+AM30 -> 0.657502 | BD30: =IF(ISNUMBER(C30),C30*1000/100,"") -> 0.4149 | BE30: =IF(ISNUMBER(D30),D30*1000/100,0) -> 11.3281 | BF30: =IF(ISNUMBER(E30),E30*1000/100,"") -> 58.2304 | BG30: =IF(ISNUMBER(F30),F30*1000/100,"") | BH30: =IF(ISNUMBER(G30),G30*1000/100,"") | BI30: =IF(ISNUMBER(H30),H30*1000/100,"") | BJ30: =IF(ISNUMBER(I30),I30*1000/100,"") | BK30: =IF(ISNUMBER(J30),J30*1000/100,"") | BL30: =IF(ISNUMBER(K30),K30*1000/100,"") | BM30: =IF(ISNUMBER(L30),L30*1000/100,"") | ... BO30: =IF(ISNUMBER(N30),N30*1000/100,"") | BQ30: r1 | BS30: =B30 -> Jeff_SloHot50_Biostat 2L-23-17 | BU30: =BE30 -> 11.3281
B31: Jeff_SloHot50_Biostat 2L-23-18 | C31: 0.04599 | D31: 1.2221 | E31: 5.58772 | R31: =R29+12+7.167 -> 69.754 | S31: r2 | T31: 18 | W31: 33.36 | X31: 70 | Y31: 7.4738 | Z31: 7.5984 | AA31: 8 | AB31: =Z31-Y31 -> 0.1246 | AC31: =AB31/(AA31/1000) -> 15.575 | AD31: 14.3 | AE31: =FAMES!L32 -> 2.3725 | AF31: =AE31/AD31 -> 0.16590909 | AG31: =AF31*AC31 -> 2.5840341 | AI31: =$BF$15-BF31 -> 41.6296 | AJ31: =BE31/R31 -> 0.17520142 | AK31: =BE31/AI31 -> 0.29356516 | AL31: =AC31/R31 -> 0.22328469 | AM31: =AC31/AI31 -> 0.37413283 | AP31: =BF29-BF31 -> 12.5579 | AQ31: =AP31/(R31-R29) -> 0.65518339 | AR31: =(AC31-AC29)/(AI31-AI29) -> -0.018912398 | AS31: =AR31/AQ31 -> -0.028865808 | AT31: =(BE31-BE29)/(AI31-AI29) -> 0.60512506 | AU31: =AT31/AP31 -> 0.048186804 | AW31: =AK31+AM31 -> 0.66769798 | BD31: =IF(ISNUMBER(C31),C31*1000/100,"") -> 0.4599 | BE31: =IF(ISNUMBER(D31),D31*1000/100,0) -> 12.221 | BF31: =IF(ISNUMBER(E31),E31*1000/100,"") -> 55.8772 | BG31: =IF(ISNUMBER(F31),F31*1000/100,"") | BH31: =IF(ISNUMBER(G31),G31*1000/100,"") | BI31: =IF(ISNUMBER(H31),H31*1000/100,"") | BJ31: =IF(ISNUMBER(I31),I31*1000/100,"") | BK31: =IF(ISNUMBER(J31),J31*1000/100,"") | BL31: =IF(ISNUMBER(K31),K31*1000/100,"") | BM31: =IF(ISNUMBER(L31),L31*1000/100,"") | ... BO31: =IF(ISNUMBER(N31),N31*1000/100,"") | BQ31: r2 | BS31: =B31 -> Jeff_SloHot50_Biostat 2L-23-18 | BU31: =BE31 -> 12.221
B32: Jeff_SloHot50_Biostat 2L-23-19 | C32: 0.04108 | D32: 1.2964 | E32: 5.54645 | Q32: 0.70833333 | R32: =R30+4.5 -> 74.254 | S32: r1 | T32: 19 | W32: 27.44 | X32: 77 | Y32: 7.1579 | Z32: 7.2746 | AA32: 8 | AB32: =Z32-Y32 -> 0.1167 | AC32: =AB32/(AA32/1000) -> 14.5875 | AD32: 15 | AE32: =FAMES!L33 -> 2.1245 | AF32: =AE32/AD32 -> 0.14163333 | AG32: =AF32*AC32 -> 2.0660763 | AI32: =$BF$14-BF32 -> 42.4473 | AJ32: =BE32/R32 -> 0.17458992 | AK32: =BE32/AI32 -> 0.30541401 | AL32: =AC32/R32 -> 0.19645406 | AM32: =AC32/AI32 -> 0.34366143 | AP32: =BF30-BF32 -> 2.7659 | AQ32: =AP32/(R32-R30) -> 0.61464444 | AR32: =(AC32-AC30)/(AI32-AI30) -> -0.063270545 | AS32: =AR32/AQ32 -> -0.10293845 | AT32: =(BE32-BE30)/(AI32-AI30) -> 0.59145305 | AU32: =AT32/AP32 -> 0.21383747 | AW32: =AK32+AM32 -> 0.64907544 | BD32: =IF(ISNUMBER(C32),C32*1000/100,"") -> 0.4108 | BE32: =IF(ISNUMBER(D32),D32*1000/100,0) -> 12.964 | BF32: =IF(ISNUMBER(E32),E32*1000/100,"") -> 55.4645 | BG32: =IF(ISNUMBER(F32),F32*1000/100,"") | BH32: =IF(ISNUMBER(G32),G32*1000/100,"") | BI32: =IF(ISNUMBER(H32),H32*1000/100,"") | BJ32: =IF(ISNUMBER(I32),I32*1000/100,"") | BK32: =IF(ISNUMBER(J32),J32*1000/100,"") | BL32: =IF(ISNUMBER(K32),K32*1000/100,"") | BM32: =IF(ISNUMBER(L32),L32*1000/100,"") | ... BO32: =IF(ISNUMBER(N32),N32*1000/100,"") | BU32: =BE32 -> 12.964
B33: Jeff_SloHot50_Biostat 2L-23-20 | C33: 0.04732 | D33: 1.45258 | E33: 5.27606 | R33: =R31+4.5 -> 74.254 | S33: r2 | T33: 20 | W33: 32.12 | X33: 85 | Y33: 7.1522 | Z33: 7.284 | AA33: 8 | AB33: =Z33-Y33 -> 0.1318 | AC33: =AB33/(AA33/1000) -> 16.475 | AD33: 15.9 | AE33: =FAMES!L34 -> 2.5155 | AF33: =AE33/AD33 -> 0.15820755 | AG33: =AF33*AC33 -> 2.6064693 | AI33: =$BF$15-BF33 -> 44.7462 | AJ33: =BE33/R33 -> 0.19562313 | AK33: =BE33/AI33 -> 0.32462645 | AL33: =AC33/R33 -> 0.22187357 | AM33: =AC33/AI33 -> 0.36818769 | AP33: =BF31-BF33 -> 3.1166 | AQ33: =AP33/(R33-R31) -> 0.69257778 | AR33: =(AC33-AC31)/(AI33-AI31) -> 0.28877623 | AS33: =AR33/AQ33 -> 0.41695856 | AT33: =(BE33-BE31)/(AI33-AI31) -> 0.73952384 | AU33: =AT33/AP33 -> 0.23728545 | AW33: =AK33+AM33 -> 0.69281414 | BD33: =IF(ISNUMBER(C33),C33*1000/100,"") -> 0.4732 | BE33: =IF(ISNUMBER(D33),D33*1000/100,0) -> 14.5258 | BF33: =IF(ISNUMBER(E33),E33*1000/100,"") -> 52.7606 | BG33: =IF(ISNUMBER(F33),F33*1000/100,"") | BH33: =IF(ISNUMBER(G33),G33*1000/100,"") | BI33: =IF(ISNUMBER(H33),H33*1000/100,"") | BJ33: =IF(ISNUMBER(I33),I33*1000/100,"") | BK33: =IF(ISNUMBER(J33),J33*1000/100,"") | BL33: =IF(ISNUMBER(K33),K33*1000/100,"") | BM33: =IF(ISNUMBER(L33),L33*1000/100,"") | ... BO33: =IF(ISNUMBER(N33),N33*1000/100,"") | BU33: =BE33 -> 14.5258
B34: Jeff_SloHot50_Biostat 2L-23-21 | C34: 0.04414 | D34: 1.71344 | E34: 4.97307 | P34: 45606 | Q34: 0.32291667 | R34: =R32+12+2.75 -> 89.004 | S34: r1 | T34: 21 | W34: 30.32 | X34: 99 | Y34: 7.1387 | Z34: 7.2624 | AA34: 8 | AB34: =Z34-Y34 -> 0.1237 | AC34: =AB34/(AA34/1000) -> 15.4625 | AD34: 16.2 | AE34: =FAMES!L35 -> 2.767 | AF34: =AE34/AD34 -> 0.17080247 | AG34: =AF34*AC34 -> 2.6410332 | AI34: =$BF$14-BF34 -> 48.1811 | AJ34: =BE34/R34 -> 0.1925127 | AK34: =BE34/AI34 -> 0.35562492 | AL34: =AC34/R34 -> 0.17372815 | AM34: =AC34/AI34 -> 0.32092459 | AP34: =BF32-BF34 -> 5.7338 | AQ34: =AP34/(R34-R32) -> 0.3887322 | AR34: =(AC34-AC32)/(AI34-AI32) -> 0.15260386 | AS34: =AR34/AQ34 -> 0.39256809 | AT34: =(BE34-BE32)/(AI34-AI32) -> 0.72733615 | AU34: =AT34/AP34 -> 0.12685063 | AW34: =AK34+AM34 -> 0.67654952 | BD34: =IF(ISNUMBER(C34),C34*1000/100,"") -> 0.4414 | BE34: =IF(ISNUMBER(D34),D34*1000/100,0) -> 17.1344 | BF34: =IF(ISNUMBER(E34),E34*1000/100,"") -> 49.7307 | BG34: =IF(ISNUMBER(F34),F34*1000/100,"") | BH34: =IF(ISNUMBER(G34),G34*1000/100,"") | BI34: =IF(ISNUMBER(H34),H34*1000/100,"") | BJ34: =IF(ISNUMBER(I34),I34*1000/100,"") | BK34: =IF(ISNUMBER(J34),J34*1000/100,"") | BL34: =IF(ISNUMBER(K34),K34*1000/100,"") | BM34: =IF(ISNUMBER(L34),L34*1000/100,"") | ... BO34: =IF(ISNUMBER(N34),N34*1000/100,"") | BU34: =BE34 -> 17.1344
B35: Jeff_SloHot50_Biostat 2L-23-22 | C35: 0.05057 | D35: 2.11966 | E35: 4.30847 | R35: =R33+12+2.75 -> 89.004 | S35: r2 | T35: 22 | W35: 32.56 | X35: 151 | Y35: 7.1358 | Z35: 7.2655 | AA35: 8 | AB35: =Z35-Y35 -> 0.1297 | AC35: =AB35/(AA35/1000) -> 16.2125 | AD35: 19 | AF35: =AE35/AD35 -> 0 | AG35: =AF35*AC35 -> 0 | AI35: =$BF$15-BF35 -> 54.4221 | AJ35: =BE35/R35 -> 0.23815334 | AK35: =BE35/AI35 -> 0.38948515 | AL35: =AC35/R35 -> 0.18215473 | AM35: =AC35/AI35 -> 0.29790287 | AP35: =BF33-BF35 -> 9.6759 | AQ35: =AP35/(R35-R33) -> 0.65599322 | AR35: =(AC35-AC33)/(AI35-AI33) -> -0.027129259 | AS35: =AR35/AQ35 -> -0.041356006 | AT35: =(BE35-BE33)/(AI35-AI33) -> 0.68942424 | AU35: =AT35/AP35 -> 0.071251691 | AW35: =AK35+AM35 -> 0.68738803 | BD35: =IF(ISNUMBER(C35),C35*1000/100,"") -> 0.5057 | BE35: =IF(ISNUMBER(D35),D35*1000/100,0) -> 21.1966 | BF35: =IF(ISNUMBER(E35),E35*1000/100,"") -> 43.0847 | BG35: =IF(ISNUMBER(F35),F35*1000/100,"") | BH35: =IF(ISNUMBER(G35),G35*1000/100,"") | BI35: =IF(ISNUMBER(H35),H35*1000/100,"") | BJ35: =IF(ISNUMBER(I35),I35*1000/100,"") | BK35: =IF(ISNUMBER(J35),J35*1000/100,"") | BL35: =IF(ISNUMBER(K35),K35*1000/100,"") | BM35: =IF(ISNUMBER(L35),L35*1000/100,"") | ... BO35: =IF(ISNUMBER(N35),N35*1000/100,"") | BU35: =BE35 -> 21.1966
BD36: =IF(ISNUMBER(C36),C36*1000/100,"") | BE36: =IF(ISNUMBER(D36),D36*1000/100,0) -> 0 | BF36: =IF(ISNUMBER(E36),E36*1000/100,"") | BG36: =IF(ISNUMBER(F36),F36*1000/100,"") | BH36: =IF(ISNUMBER(G36),G36*1000/100,"") | BI36: =IF(ISNUMBER(H36),H36*1000/100,"") | BJ36: =IF(ISNUMBER(I36),I36*1000/100,"") | BK36: =IF(ISNUMBER(J36),J36*1000/100,"") | BL36: =IF(ISNUMBER(K36),K36*1000/100,"") | BM36: =IF(ISNUMBER(L36),L36*1000/100,"") | ... BO36: =IF(ISNUMBER(N36),N36*1000/100,"") | BU36: =BE36 -> 0
BD37: =IF(ISNUMBER(C37),C37*1000/100,"") | BE37: =IF(ISNUMBER(D37),D37*1000/100,0) -> 0 | BF37: =IF(ISNUMBER(E37),E37*1000/100,"") | BG37: =IF(ISNUMBER(F37),F37*1000/100,"") | BH37: =IF(ISNUMBER(G37),G37*1000/100,"") | BI37: =IF(ISNUMBER(H37),H37*1000/100,"") | BJ37: =IF(ISNUMBER(I37),I37*1000/100,"") | BK37: =IF(ISNUMBER(J37),J37*1000/100,"") | BL37: =IF(ISNUMBER(K37),K37*1000/100,"") | BM37: =IF(ISNUMBER(L37),L37*1000/100,"") | ... BO37: =IF(ISNUMBER(N37),N37*1000/100,"") | BU37: =BE37 -> 0
BD38: =IF(ISNUMBER(C38),C38*1000/100,"") | BE38: =IF(ISNUMBER(D38),D38*1000/100,0) -> 0 | BF38: =IF(ISNUMBER(E38),E38*1000/100,"") | BG38: =IF(ISNUMBER(F38),F38*1000/100,"") | BH38: =IF(ISNUMBER(G38),G38*1000/100,"") | BI38: =IF(ISNUMBER(H38),H38*1000/100,"") | BJ38: =IF(ISNUMBER(I38),I38*1000/100,"") | BK38: =IF(ISNUMBER(J38),J38*1000/100,"") | BL38: =IF(ISNUMBER(K38),K38*1000/100,"") | BM38: =IF(ISNUMBER(L38),L38*1000/100,"") | ... BO38: =IF(ISNUMBER(N38),N38*1000/100,"")
U71: =390/24 -> 16.25

Sheet FAMES
B2: 1 | C2: 2 | D2: 3 | E2: 4 | F2: 5 | G2: 6 | H2: 7 | I2: 8 | J2: 9 | K2: 10 | L2: 11 | M2: 12 | N2: 13 | O2: 14 | P2: 15 | Q2: 16 | R2: 17 | S2: 18 | T2: 19 | U2: 20 | V2: 21
A3: C13:0 | B3: 0.91 | C3: 0.959 | D3: 1.006 | E3: 0.988 | F3: 0.932 | G3: 0.922 | H3: 0.999 | I3: 0.946 | J3: 0.874 | K3: 0.945 | L3: 0.933 | M3: 0.993 | N3: 0.929 | O3: 1.023 | P3: 0.942 | Q3: 0.978 | R3: 0.895 | S3: 0.938 | T3: 0.931 | U3: 0.898 | V3: 1.024
A4: C14:0 | B4: 0 | C4: N.D. | D4: N.D. | E4: N.D. | F4: N.D. | G4: 0.008 | H4: 0.004 | I4: 0.009 | J4: 0.004 | K4: 0.006 | L4: 0.007 | M4: 0.012 | N4: 0.007 | O4: 0.009 | P4: 0.007 | Q4: 0.01 | R4: 0.007 | S4: 0.009 | T4: 0.006 | U4: 0.009 | V4: 0.008
A5: C16:0 | B5: 0.131 | C5: 0.139 | D5: 0.145 | E5: 0.135 | F5: 0.266 | G5: 0.272 | H5: 0.345 | I5: 0.327 | J5: 0.447 | K5: 0.295 | L5: 0.682 | M5: 0.731 | N5: 0.649 | O5: 0.56 | P5: 0.718 | Q5: 0.672 | R5: 0.672 | S5: 0.725 | T5: 0.669 | U5: 0.77 | V5: 0.816
A6: C16:1 | B6: 0.011 | C6: 0.004 | D6: N.D. | E6: N.D. | F6: 0.108 | G6: 0.126 | H6: 0.159 | I6: 0.154 | J6: 0.229 | K6: 0.124 | L6: 0.377 | M6: 0.406 | N6: 0.358 | O6: 0.274 | P6: 0.402 | Q6: 0.36 | R6: 0.397 | S6: 0.411 | T6: 0.397 | U6: 0.44 | V6: 0.529
A7: C18:0 | B7: 0.092 | C7: 0.101 | D7: 0.112 | E7: 0.103 | F7: 0.146 | G7: 0.141 | H7: 0.185 | I7: 0.183 | J7: 0.227 | K7: 0.19 | L7: 0.305 | M7: 0.448 | N7: 0.29 | O7: 0.355 | P7: 0.32 | Q7: 0.414 | R7: 0.31 | S7: 0.469 | T7: 0.322 | U7: 0.497 | V7: 0.395
A8: C18:1 | B8: 0.044 | C8: 0.021 | D8: N.D. | E8: N.D. | F8: 0.883 | G8: 0.993 | H8: 1.355 | I8: 1.16 | J8: 1.814 | K8: 0.933 | L8: 2.435 | M8: 2.627 | N8: 2.254 | O8: 1.72 | P8: 2.521 | Q8: 2.239 | R8: 2.441 | S8: 2.542 | T8: 2.474 | U8: 2.697 | V8: 3.293
A9: C18:2 | B9: 0.05 | C9: 0.025 | D9: 0.011 | E9: N.D. | F9: 0.254 | G9: 0.324 | H9: 0.296 | I9: 0.324 | J9: 0.322 | K9: 0.246 | L9: 0.333 | M9: 0.513 | N9: 0.295 | O9: 0.337 | P9: 0.323 | Q9: 0.434 | R9: 0.301 | S9: 0.472 | T9: 0.304 | U9: 0.505 | V9: 0.396
A10: C21:0 | B10: N.D. | C10: N.D. | D10: N.D. | E10: N.D. | F10: N.D. | G10: N.D. | H10: N.D. | I10: N.D. | J10: N.D. | K10: N.D. | L10: N.D. | M10: N.D. | N10: N.D. | O10: N.D. | P10: N.D. | Q10: N.D. | R10: N.D. | S10: N.D. | T10: N.D. | U10: N.D. | V10: N.D.
A11: C24:0 | B11: N.D. | C11: N.D. | D11: N.D. | E11: N.D. | F11: 0.017 | G11: 0.025 | H11: 0.037 | I11: 0.037 | J11: 0.051 | K11: 0.04 | L11: 0.078 | M11: 0.127 | N11: 0.071 | O11: 0.081 | P11: 0.084 | Q11: 0.101 | R11: 0.076 | S11: 0.117 | T11: 0.077 | U11: 0.113 | V11: 0.097
A14: C13:0 | B14: C14:0 | C14: C16:0 | D14: C16:1 | E14: C18:0 | F14: C18:1 | G14: C18:2 | H14: C21:0 | I14: C24:0 | K14: mg/mL | L14: mg 500 uL hexane
A15: 0.91 | B15: 0 | C15: 0.131 | D15: 0.011 | E15: 0.092 | F15: 0.044 | G15: 0.05 | H15: N.D. | I15: N.D. | K15: =SUM(B15:I15) -> 0.328 | L15: =K15*0.5 -> 0.164
A16: 0.959 | B16: N.D. | C16: 0.139 | D16: 0.004 | E16: 0.101 | F16: 0.021 | G16: 0.025 | H16: N.D. | I16: N.D. | K16: =SUM(B16:I16) -> 0.29 | L16: =K16*0.5 -> 0.145
A17: 1.006 | B17: N.D. | C17: 0.145 | D17: N.D. | E17: 0.112 | F17: N.D. | G17: 0.011 | H17: N.D. | I17: N.D. | K17: =SUM(B17:I17) -> 0.268 | L17: =K17*0.5 -> 0.134
A18: 0.988 | B18: N.D. | C18: 0.135 | D18: N.D. | E18: 0.103 | F18: N.D. | G18: N.D. | H18: N.D. | I18: N.D. | K18: =SUM(B18:I18) -> 0.238 | L18: =K18*0.5 -> 0.119
A19: 0.932 | B19: N.D. | C19: 0.266 | D19: 0.108 | E19: 0.146 | F19: 0.883 | G19: 0.254 | H19: N.D. | I19: 0.017 | K19: =SUM(B19:I19) -> 1.674 | L19: =K19*0.5 -> 0.837
A20: 0.922 | B20: 0.008 | C20: 0.272 | D20: 0.126 | E20: 0.141 | F20: 0.993 | G20: 0.324 | H20: N.D. | I20: 0.025 | K20: =SUM(B20:I20) -> 1.889 | L20: =K20*0.5 -> 0.9445
A21: 0.999 | B21: 0.004 | C21: 0.345 | D21: 0.159 | E21: 0.185 | F21: 1.355 | G21: 0.296 | H21: N.D. | I21: 0.037 | K21: =SUM(B21:I21) -> 2.381 | L21: =K21*0.5 -> 1.1905
A22: 0.946 | B22: 0.009 | C22: 0.327 | D22: 0.154 | E22: 0.183 | F22: 1.16 | G22: 0.324 | H22: N.D. | I22: 0.037 | K22: =SUM(B22:I22) -> 2.194 | L22: =K22*0.5 -> 1.097
A23: 0.874 | B23: 0.004 | C23: 0.447 | D23: 0.229 | E23: 0.227 | F23: 1.814 | G23: 0.322 | H23: N.D. | I23: 0.051 | K23: =SUM(B23:I23) -> 3.094 | L23: =K23*0.5 -> 1.547
A24: 0.945 | B24: 0.006 | C24: 0.295 | D24: 0.124 | E24: 0.19 | F24: 0.933 | G24: 0.246 | H24: N.D. | I24: 0.04 | K24: =SUM(B24:I24) -> 1.834 | L24: =K24*0.5 -> 0.917
A25: 0.933 | B25: 0.007 | C25: 0.682 | D25: 0.377 | E25: 0.305 | F25: 2.435 | G25: 0.333 | H25: N.D. | I25: 0.078 | K25: =SUM(B25:I25) -> 4.217 | L25: =K25*0.5 -> 2.1085
A26: 0.993 | B26: 0.012 | C26: 0.731 | D26: 0.406 | E26: 0.448 | F26: 2.627 | G26: 0.513 | H26: N.D. | I26: 0.127 | K26: =SUM(B26:I26) -> 4.864 | L26: =K26*0.5 -> 2.432
A27: 0.929 | B27: 0.007 | C27: 0.649 | D27: 0.358 | E27: 0.29 | F27: 2.254 | G27: 0.295 | H27: N.D. | I27: 0.071 | K27: =SUM(B27:I27) -> 3.924 | L27: =K27*0.5 -> 1.962
A28: 1.023 | B28: 0.009 | C28: 0.56 | D28: 0.274 | E28: 0.355 | F28: 1.72 | G28: 0.337 | H28: N.D. | I28: 0.081 | K28: =SUM(B28:I28) -> 3.336 | L28: =K28*0.5 -> 1.668
A29: 0.942 | B29: 0.007 | C29: 0.718 | D29: 0.402 | E29: 0.32 | F29: 2.521 | G29: 0.323 | H29: N.D. | I29: 0.084 | K29: =SUM(B29:I29) -> 4.375 | L29: =K29*0.5 -> 2.1875
A30: 0.978 | B30: 0.01 | C30: 0.672 | D30: 0.36 | E30: 0.414 | F30: 2.239 | G30: 0.434 | H30: N.D. | I30: 0.101 | K30: =SUM(B30:I30) -> 4.23 | L30: =K30*0.5 -> 2.115
A31: 0.895 | B31: 0.007 | C31: 0.672 | D31: 0.397 | E31: 0.31 | F31: 2.441 | G31: 0.301 | H31: N.D. | I31: 0.076 | K31: =SUM(B31:I31) -> 4.204 | L31: =K31*0.5 -> 2.102
... A35: 1.024 | B35: 0.008 | C35: 0.816 | D35: 0.529 | E35: 0.395 | F35: 3.293 | G35: 0.396 | H35: N.D. | I35: 0.097 | K35: =SUM(B35:I35) -> 5.534 | L35: =K35*0.5 -> 2.767

Sheet questions

Sheet seedCultureNotes
