Workbook

Sheet info
A1: PPI Biostat Run #5.
B3: This biostat run will examine the morhpology and growth of Ylp on YPD100 medium.
B4: A seed culture was grown in the sixfors (250 mL, 400 rpm, 1 vvm, pH 5.6, 10% inoculation from YPD) over the weekend.
A7: Initial seed | C7: Culture | D7: OD600 final
C8: 2 mL YPD O/N | D8: 4.84 | E8: 45584
A12: Sixfor seed | F12: #estimated initial OD
B13: Reactor | C13: Description | D13: Volume (no seed) | E13: Volume (w/seed) | F13: OD600 initial$ | G13: OD600 final | H13: pH initial | I13: Time of inoculation | J13: date of Inoculation | K13: RPM control | L13: Aeration Control | M13: pH setpoint | N13: Temp setpoint © | O13: Medium | P13: Species | Q13: file | R13: Note
B14: R1 | C14: seed for Biostat20_2L | D14: 250 mL | E14: 252 | J14: 45585 | K14: 400 | L14: 1 vvm | M14: 5.6 | N14: 30 | O14: YPD100 | P14: Ylip (W29) | Q14: PPI_sixfor_bstat21Seed
B15: R2 | C15: seed for Biostat20_2L | D15: 250 mL | E15: 252 | J15: 45585 | K15: 400 | L15: 1 vvm | M15: 5.6 | N15: 30 | O15: YPD100 | P15: Ylip (W29) | Q15: PPI_sixfor_bstat21Seed
B16: R3 | C16: seed for Biostat20_2L | D16: 250 mL | E16: 252 | J16: 45585 | K16: 400 | L16: 1 vvm | M16: 5.6 | N16: 30 | O16: YPD100 | P16: Ylip (W29) | Q16: PPI_sixfor_bstat21Seed
B17: R4 | C17: seed for Biostat20_2L | D17: 250 mL | E17: 252 | J17: 45585 | K17: 400 | L17: 1 vvm | M17: 5.6 | N17: 30 | O17: YPD100 | P17: Ylip (W29) | Q17: PPI_sixfor_bstat21Seed
A21: Biostat2L
B22: Reactor | C22: Description | D22: Volume (no seed) | E22: Volume (w/seed) | F22: OD600 initial | G22: pH initial | H22: Time of inoculation | I22: date of Inoculation | J22: RPM control | K22: Aeration Control | L22: pH setpoint | M22: Temp setpoint © | N22: Medium | O22: Species | P22: Note
B23: R1 | C23: YPD | D23: 1.4 | E23: 1.5 | O23: Ylp (W29)
B24: R2 | C24: YPD | D24: 1.4 | E24: 1.5 | O24: Ylp (W29)
H26: * changes in controls
H27: initial | I27: 400 (0%)-600(50%)-800(100%) | J27: 0.375 (0%)- 0.375 (50%) - 1.5 (100%)
H28: ~5-6 h | I28: 500 (0%)-600(50%)-800(100%) | J28: Kp from 90%-->200%; Ki from 50 s --> 90 s
H29: ~20.5 h | I29: 400 (0%)-600(50%)-800(100%) | J29: 0.375 (0%)- 0.5 (25%) - 1.5 (100%) | M29: ** based added, 37, 49 mL
G31: ** | H31: SAMPLES ALSO RECORDED EVERY 1 second instead of 5 seconds.

Sheet medium
A1: Medium | AA1: redford ratio
B2: Initial Medium. | AA2: 4.4277894 | AB2: C:N:P
AA3: C/N | AB3: =106/16 -> 6.625
C4: YPD | P4: molecular weight (m.w., g/mol) | S4: Yeast Nitrogen Base W/out Amino acids and Ammonium Sulfate (product number Y1251) | AA4: C/P | AB4: =106 -> 106
B5: 1 | C5: YPD100 | D5: Conc (g/L) | E5: Component | F5: C/N ratio low | G5: C/N ratio (high) | H5: C/P ratio* | I5: N/P ratio* | J5: mol C | K5: low mol N/L | L5: high mol N/L | M5: mol P/L | O5: Potassium Phosphate monobasic | P5: 136.086 | T5: chrome-extension://efaidnbmnnnibpcajpcglclefindmkaj/https://www.sigmaaldrich.com/deepweb/assets/sigmaaldrich/product/documents/411/890/Y1251dat.pdf | AA5: N/P | AB5: 16
C6: 10 | D6: =C6/D11 -> 1.6666667 | E6: Yeast extract | F6: =J6/K6 -> 74.801482 | G6: =J6/L6 -> 59.777253 | H6: =J6/M6 -> 453.2272 | I6: =K6/M6 -> 6.0590671 | J6: =D8/$P$7*6 -> 3.3304469 | K6: =D7*F13/100*1/14+F14/100*D6*1/14 -> 0.04452381 | L6: =D7*G13/100*1/14+G14/100*D6*1/14 -> 0.055714286 | M6: =T7/$P$5 -> 0.0073482945 | O6: Ammonium Sulfate | P6: 132.14 | T6: Conc (g/L) | U6: Component | V6: molecular weight (g/mol) | X6: mol/L
C7: 20 | D7: =C7/D11 -> 3.3333333 | E7: Peptone | O7: Glucose | P7: 180.156 | T7: 1 | U7: Potassium Phosphate monobasic | V7: 136.086
C8: 20 | D8: 100 | E8: Glucose | O8: Xylose | P8: 150.13 | T8: 0.5 | U8: magnesium sulfate
O9: Glycerol | P9: 92.094 | T9: 0.1 | U9: sodium chloride
D10: dilution | O10: Acetate | P10: 59.044 | T10: 0.1 | U10: calcium chloride
D11: 6 | O11: Citric acid | P11: 192.194 | T11: =SUM(T7:T10) -> 1.7 | U11: g/L total
B12: glucose with dilution | C12: glucose to add/L | F12: low (%) | G12: high (%) | O12: Ammonium Chloride | P12: 53.491 | T12: Trace elements
B13: =C8/D11 -> 3.3333333 | C13: =100-B13 -> 96.666667 | D13: =C13*1.5 -> 145 | E13: Peptone Nitrogen range | F13: 14.2 | G13: 17.4 | O13: urea | P13: 60.06 | T13: Conc (µg/L) | U13: Component
E14: Yeast extract Nitrogen range | F14: 9 | G14: 12 | T14: 500 | U14: Boric acid
C15: g of YPD broth to add /L | D15: L | E15: total to add. | T15: 40 | U15: Copper sulfate
C16: =50/D11 -> 8.3333333 | D16: 1.5 | E16: =D16*C16 -> 12.5 | T16: 100 | U16: Potassium iodide
T17: 200 | U17: Ferric Chloride
T18: 400 | U18: Manganese sulfate
T19: 200 | U19: Sodium molybdate
T20: 400 | U20: Zinc Sulfate
T21: =SUM(T14:T20)/1000000 -> 0.00184 | U21: g/L total
T22: Vitamins
T23: Conc (µg/L) | U23: Component
T24: 2 | U24: Biotin | X24: =550*0.3 -> 165
T25: 400 | U25: Calcium pantothenate
T26: 2 | U26: Folic acid
T27: 2000 | U27: Inositol
T28: 400 | U28: Niacin
T29: 200 | U29: p-Aminobeznoic acid
T30: 400 | U30: Pyridoxine hydrochloride
T31: 200 | U31: Riboflavin
T32: 400 | U32: Thiamine hydrochloride
T35: =SUM(T24:T32)/1000000 -> 0.004004 | U35: g/L total
E46: YNB-glucose
C47: Media | D47: YNB Seeds. | G47: High | H47: low | L47: low | M47: high
C48: 1 | D48: YNB-glucose-AC | E48: Conc (g/L) | F48: Component | G48: C/N ratio | H48: C/N ratio | I48: C/P ratio* | J48: N/P ratio* | K48: mol C | L48: mol N/L | M48: mol N/L | N48: mol P/L | P48: to add
E49: 1.7 | F49: Yeast Nitrogen Base W/out Amino acids and Ammonium Sulfate (product number Y1251) | G49: =K49/L49 -> 72.692801 | H49: =K49/M49 -> 70.388281 | I49: =K49/N49 -> 453.2272 | J49: =L49/N49 -> 6.2348293 | K49: =E51/$P$7*6 -> 3.3304469 | L49: =E50/P$12+E52*F14/100*1/14 -> 0.045815361 | M49: =E50/P$12+E52*G14/100*1/14 -> 0.047315361 | N49: =T7/$P$5 -> 0.0073482945 | P49: =E49*1.5 -> 2.55
E50: 2.21 | F50: Ammonium Chloride | P50: =E50*1.5 -> 3.315
E51: 100 | F51: Glucose | P51: =E51*1.5 -> 150
E52: 0.7 | F52: Yeast extract | P52: =E52*1.5 -> 1.05
...

Sheet vessel setup
A1: Agitation Propellers.
B2: Adjusted propellers to account for feeding of liquid into the medium.
B4: 2 cm from bottom for bottom impeller
B5: 4 cm from bottom impeller for top impeller

Sheet history_

Sheet metadata
B4: Strain | C4: inoculation | D4: initial working volume (L) | E4: Temperature (C ) | F4: Agitation | G4: Aeration | H4: Initial medium | I4: feed
B10: Final volume ~ 1.25 L | D10: 1.25 | E10: L
B11: Calculated volume ~ 1.47 L | D11: 1.41 | E11: L
D13: =(D11-D10)*1000 -> 160 | E13: mL evaporated
D14: 236.5 | E14: h fermented
D16: =D13/D14 -> 0.67653277 | E16: mL evaporated per hour
D18: 1 | E18: mL total
D19: =D11/D10 -> 1.128 | E19: times more titer at the end
C24: BlueVary start | D24: CO2 value | E24: 0.041
D25: O2 value | E25: 20.956

Sheet data
V12: moxiflow | Y12: DCW | BA12: Results in g/L | BN12: Calculations
A13: # | B13: SampleName | C13: Trehalose | D13: Citric Acid | E13: Glucose | F13: Xylose | G13: Erythritol | H13: Lactic Acid | I13: Glycerol | J13: Acetic Acid | K13: Ethanol | L13: Oxalic Acid | M13: Succinic Acid | N13: Fumaric | P13: date | Q13: time | R13: hour | S13: reactor | T13: sample number | U13: sample volume (mL) | V13: moxiflow D (µm) | W13: OD600 | X13: BASE (mL) | Y13: pre | Z13: post | AA13: volume | AB13: weight (g) | AC13: DCW (g/L) | AD13: Fame bio weight (mg) | AE13: FAME (mg) | AF13: FAME yield (g/g biomass) | AG13: FAME titer (g/L) | AH13: OD600:DCW | AI13: specific sugar consumed (g/L) | AJ13: specific sugar consumed (g/L/h) | AK13: specific biomass rate (g/L/h) | AL13: specific biomass yield (g/g substrate) | AM13: specific citrate rate (g/L/h) | AN13: specific citrate yield (g/g substrate) | AO13: specific Fame (g/L/h) | AP13: FAME yield (g/g substrate) | AQ13: yield total | AR13: sugar consumed | AS13: citrate rate | AT13: citrate yield | AU13: biomass rate | AV13: biomass yield | AW13: FAME rate (g/L/h) | AX13: FAME yield (g/g substrate) | BA13: Trehalose | BB13: Citric Acid | BC13: Glucose | BD13: Xylose | BE13: Erythritol | BF13: Lactic Acid | BG13: Glycerol | BH13: Acetic Acid | BI13: Ethanol | BJ13: Oxalic Acid | BK13: Succinic Acid | BL13: Fumaric Acid | BM13: date | BN13: BLANK | BR13: Titer (g/L) | BS13: estimated titer with evaporation | BT13: total sugar (g/L) | BU13: equivilant titer (g/L) | BV13: sugar consumed (g/L) | BX13: sugar consumption rates (g/L/h) | BY13: sugar consumed / timepoint | BZ13: specific sugar consumption rate (g/L/h) | CA13: specifc biomass formation | CB13: biomass yield
B14: Jeff_SloHot50_Biostat 2L-21-1 | E14: 9.91581 | P14: 45586 | Q14: 0.39583333 | R14: 0.5 | S14: r1 | T14: 1 | V14: - | W14: 1.085 | X14: 0 | Y14: 6.6757 | Z14: 6.6783 | AA14: 8 | AB14: =Z14-Y14 -> 0.0026 | AC14: =AB14/(AA14/1000) -> 0.325 | AD14: 4 | AE14: =FAME!P118 -> 0.2415 | AF14: =AE14/AD14 -> 0.060375 | AG14: =AF14*AC14 -> 0.019621875 | AH14: =W14/AC14 -> 3.3384615 | BA14: =IF(ISNUMBER(C14),C14*1000/100,0) -> 0 | BB14: =IF(ISNUMBER(D14),D14*1000/100,0) -> 0 | BC14: =IF(ISNUMBER(E14),E14*1000/100,0) -> 99.1581 | BD14: =IF(ISNUMBER(F14),F14*1000/100,"") | BE14: =IF(ISNUMBER(G14),G14*1000/100,"") | BF14: =IF(ISNUMBER(H14),H14*1000/100,"") | BG14: =IF(ISNUMBER(I14),I14*1000/100,"") | BH14: =IF(ISNUMBER(J14),J14*1000/100,"") | BI14: =IF(ISNUMBER(K14),K14*1000/100,"") | BJ14: =IF(ISNUMBER(L14),L14*1000/100,"") | BK14: =IF(ISNUMBER(M14),M14*1000/100,"") | BL14: =IF(ISNUMBER(N14),N14*1000/100,"") | BN14: =S14 -> r1 | BP14: =B14 -> Jeff_SloHot50_Biostat 2L-21-1 | BV14: =$BC$14-BC14 -> 0 | BX14: =BV14/R14 -> 0
B15: Jeff_SloHot50_Biostat 2L-21-2 | E15: 7.50818 | K15: 0.46526 | P15: 45586 | Q15: 0.39583333 | R15: 0.5 | S15: r2 | T15: 2 | U15: 3 | V15: - | W15: 0.555 | X15: 1 | Y15: 6.7434 | Z15: 6.745 | AA15: 8 | AB15: =Z15-Y15 -> 0.0016 | AC15: =AB15/(AA15/1000) -> 0.2 | AD15: 2 | AE15: =FAME!P119 -> 0.203 | AF15: =AE15/AD15 -> 0.1015 | AG15: =AF15*AC15 -> 0.0203 | AH15: =W15/AC15 -> 2.775 | BA15: =IF(ISNUMBER(C15),C15*1000/100,0) -> 0 | BB15: =IF(ISNUMBER(D15),D15*1000/100,0) -> 0 | BC15: =IF(ISNUMBER(E15),E15*1000/100,0) -> 75.0818 | BD15: =IF(ISNUMBER(F15),F15*1000/100,"") | BE15: =IF(ISNUMBER(G15),G15*1000/100,"") | BF15: =IF(ISNUMBER(H15),H15*1000/100,"") | BG15: =IF(ISNUMBER(I15),I15*1000/100,"") | BH15: =IF(ISNUMBER(J15),J15*1000/100,"") | BI15: =IF(ISNUMBER(K15),K15*1000/100,"") -> 4.6526 | BJ15: =IF(ISNUMBER(L15),L15*1000/100,"") | BK15: =IF(ISNUMBER(M15),M15*1000/100,"") | BL15: =IF(ISNUMBER(N15),N15*1000/100,"") | BN15: =S15 -> r2 | BP15: =B15 -> Jeff_SloHot50_Biostat 2L-21-2 | BV15: =$BC$15-BC15 -> 0 | BX15: =BV15/R15 -> 0
B16: Jeff_SloHot50_Biostat 2L-21-3 | C16: 0.01323 | E16: 9.92048 | P16: 45586 | Q16: 0.51041667 | R16: 2.75 | S16: r1 | T16: 3 | U16: 3 | V16: - | W16: 2.725 | X16: 1 | Y16: 6.701 | Z16: 6.7151 | AA16: 8 | AB16: =Z16-Y16 -> 0.0141 | AC16: =AB16/(AA16/1000) -> 1.7625 | AD16: 10 | AE16: =FAME!P120 -> 0.6185 | AF16: =AE16/AD16 -> 0.06185 | AG16: =AF16*AC16 -> 0.10901062 | AH16: =W16/AC16 -> 1.5460993 | AI16: =BC14-BC16 -> -0.0467 | AJ16: =AI16/(R16-R14) -> -0.020755556 | AK16: =(AC16-AC14)/(R16-R14) -> 0.63888889 | AL16: =AK16/AJ16 -> -30.781585 | AM16: =(BB16-BB14)/(R16-R14) -> 0 | AN16: =AM16/AJ16 -> 0 | AO16: =(AG16-AG14)/(R16-R14) -> 0.039728333 | AR16: =$BC$16-BC16 -> 0 | AS16: =BB16/R16 -> 0 | AT16: =BB16/AR16 -> #DIV/0! | AU16: =AC16/R16 -> 0.64090909 | AV16: =AC16/AR16 -> #DIV/0! | AW16: =AG16/R16 -> 0.039640227 | AX16: =AG16/AR16 -> #DIV/0! | BA16: =IF(ISNUMBER(C16),C16*1000/100,0) -> 0.1323 | BB16: =IF(ISNUMBER(D16),D16*1000/100,0) -> 0 | BC16: =IF(ISNUMBER(E16),E16*1000/100,0) -> 99.2048 | BD16: =IF(ISNUMBER(F16),F16*1000/100,"") | BE16: =IF(ISNUMBER(G16),G16*1000/100,"") | BF16: =IF(ISNUMBER(H16),H16*1000/100,"") | BG16: =IF(ISNUMBER(I16),I16*1000/100,"") | BH16: =IF(ISNUMBER(J16),J16*1000/100,"") | BI16: =IF(ISNUMBER(K16),K16*1000/100,"") | BJ16: =IF(ISNUMBER(L16),L16*1000/100,"") | BK16: =IF(ISNUMBER(M16),M16*1000/100,"") | BL16: =IF(ISNUMBER(N16),N16*1000/100,"") | BN16: =S16 -> r1 | BP16: =B16 -> Jeff_SloHot50_Biostat 2L-21-3 | BV16: =$BC$14-BC16 -> -0.0467 | BX16: =BV16/R16 -> -0.016981818 | BY16: =BV16-BV14 -> -0.0467 | BZ16: =BY16/(R16-R14) -> -0.020755556 | CA16: =AC16-AC14 -> 1.4375 | CB16: =CA16/BY16 -> -30.781585
B17: Jeff_SloHot50_Biostat 2L-21-4 | E17: 9.28284 | K17: 0.1459 | P17: 45586 | Q17: 0.51041667 | R17: 2.75 | S17: r2 | T17: 4 | U17: 3 | V17: - | W17: 1.141 | X17: 2 | Y17: 6.6654 | Z17: 6.6721 | AA17: 8 | AB17: =Z17-Y17 -> 0.0067 | AC17: =AB17/(AA17/1000) -> 0.8375 | AD17: 4 | AE17: =FAME!P121 -> 0.327 | AF17: =AE17/AD17 -> 0.08175 | AG17: =AF17*AC17 -> 0.068465625 | AH17: =W17/AC17 -> 1.3623881 | AI17: =BC15-BC17 -> -17.7466 | AJ17: =AI17/(R17-R15) -> -7.8873778 | AK17: =(AC17-AC15)/(R17-R15) -> 0.28333333 | AL17: =AK17/AJ17 -> -0.035922374 | AM17: =(BB17-BB15)/(R17-R15) -> 0 | AN17: =AM17/AJ17 -> 0 | AO17: =(AG17-AG15)/(R17-R15) -> 0.021406944 | AP17: =AO17/AJ17 -> -0.0027140762 | AQ17: =AN17+AL17 -> -0.035922374 | AR17: =$BC$17-BC17 -> 0 | AS17: =BB17/R17 -> 0 | AT17: =BB17/AR17 -> #DIV/0! | AU17: =AC17/R17 -> 0.30454545 | AV17: =AC17/AR17 -> #DIV/0! | AW17: =AG17/R17 -> 0.024896591 | AX17: =AG17/AR17 -> #DIV/0! | BA17: =IF(ISNUMBER(C17),C17*1000/100,0) -> 0 | BB17: =IF(ISNUMBER(D17),D17*1000/100,0) -> 0 | BC17: =IF(ISNUMBER(E17),E17*1000/100,0) -> 92.8284 | BD17: =IF(ISNUMBER(F17),F17*1000/100,"") | BE17: =IF(ISNUMBER(G17),G17*1000/100,"") | BF17: =IF(ISNUMBER(H17),H17*1000/100,"") | BG17: =IF(ISNUMBER(I17),I17*1000/100,"") | BH17: =IF(ISNUMBER(J17),J17*1000/100,"") | BI17: =IF(ISNUMBER(K17),K17*1000/100,"") -> 1.459 | BJ17: =IF(ISNUMBER(L17),L17*1000/100,"") | BK17: =IF(ISNUMBER(M17),M17*1000/100,"") | BL17: =IF(ISNUMBER(N17),N17*1000/100,"") | BN17: =S17 -> r2 | BP17: =B17 -> Jeff_SloHot50_Biostat 2L-21-4 | BV17: =$BC$15-BC17 -> -17.7466 | BX17: =BV17/R17 -> -6.4533091 | BY17: =BV17-BV15 -> -17.7466 | BZ17: =BY17/(R17-R15) -> -7.8873778 | CA17: =AC17-AC15 -> 0.6375 | CB17: =CA17/BY17 -> -0.035922374
B18: Jeff_SloHot50_Biostat 2L-21-5 | C18: 0.01575 | E18: 9.83461 | P18: 45586 | Q18: 0.59375 | R18: 4.75 | S18: r1 | T18: 5 | U18: 3 | V18: - | W18: 5.11 | X18: 2 | Y18: 6.6898 | Z18: 6.7093 | AA18: 8 | AB18: =Z18-Y18 -> 0.0195 | AC18: =AB18/(AA18/1000) -> 2.4375 | AD18: 18 | AE18: =FAME!P122 -> 1.1595 | AF18: =AE18/AD18 -> 0.064416667 | AG18: =AF18*AC18 -> 0.15701562 | AH18: =W18/AC18 -> 2.0964103 | AI18: =BC16-BC18 -> 0.8587 | AJ18: =AI18/(R18-R16) -> 0.42935 | AK18: =(AC18-AC16)/(R18-R16) -> 0.3375 | AL18: =AK18/AJ18 -> 0.78607197 | AM18: =(BB18-BB16)/(R18-R16) -> 0 | AN18: =AM18/AJ18 -> 0 | AO18: =(AG18-AG16)/(R18-R16) -> 0.0240025 | AP18: =AO18/AJ18 -> 0.055904274 | AR18: =$BC$16-BC18 -> 0.8587 | AS18: =BB18/R18 -> 0 | AT18: =BB18/AR18 -> 0 | AU18: =AC18/R18 -> 0.51315789 | AV18: =AC18/AR18 -> 2.8385932 | AW18: =AG18/R18 -> 0.033055921 | AX18: =AG18/AR18 -> 0.18285271 | AY18: =AT18+AV18 -> 2.8385932 | BA18: =IF(ISNUMBER(C18),C18*1000/100,0) -> 0.1575 | BB18: =IF(ISNUMBER(D18),D18*1000/100,0) -> 0 | BC18: =IF(ISNUMBER(E18),E18*1000/100,0) -> 98.3461 | BD18: =IF(ISNUMBER(F18),F18*1000/100,"") | BE18: =IF(ISNUMBER(G18),G18*1000/100,"") | BF18: =IF(ISNUMBER(H18),H18*1000/100,"") | BG18: =IF(ISNUMBER(I18),I18*1000/100,"") | BH18: =IF(ISNUMBER(J18),J18*1000/100,"") | BI18: =IF(ISNUMBER(K18),K18*1000/100,"") | BJ18: =IF(ISNUMBER(L18),L18*1000/100,"") | BK18: =IF(ISNUMBER(M18),M18*1000/100,"") | BL18: =IF(ISNUMBER(N18),N18*1000/100,"") | BN18: =S18 -> r1 | BP18: =B18 -> Jeff_SloHot50_Biostat 2L-21-5 | BV18: =$BC$14-BC18 -> 0.812 | BX18: =BV18/R18 -> 0.17094737 | BY18: =BV18-BV16 -> 0.8587 | BZ18: =BY18/(R18-R16) -> 0.42935
B19: Jeff_SloHot50_Biostat 2L-21-6 | C19: 0.00873 | E19: 9.25201 | K19: 0.12405 | P19: 45586 | Q19: 0.59375 | R19: 4.75 | S19: r2 | T19: 6 | U19: 3 | V19: - | W19: 2.505 | X19: 16 | Y19: 6.6642 | Z19: 6.6747 | AA19: 8 | AB19: =Z19-Y19 -> 0.0105 | AC19: =AB19/(AA19/1000) -> 1.3125 | AD19: 9 | AE19: =FAME!P123 -> 0.5925 | AF19: =AE19/AD19 -> 0.065833333 | AG19: =AF19*AC19 -> 0.08640625 | AH19: =W19/AC19 -> 1.9085714 | AI19: =BC17-BC19 -> 0.3083 | AJ19: =AI19/(R19-R17) -> 0.15415 | AK19: =(AC19-AC17)/(R19-R17) -> 0.2375 | AL19: =AK19/AJ19 -> 1.5407071 | AM19: =(BB19-BB17)/(R19-R17) -> 0 | AN19: =AM19/AJ19 -> 0 | AO19: =(AG19-AG17)/(R19-R17) -> 0.0089703125 | AP19: =AO19/AJ19 -> 0.058192102 | AQ19: =AN19+AL19 -> 1.5407071 | AR19: =$BC$17-BC19 -> 0.3083 | AS19: =BB19/R19 -> 0 | AT19: =BB19/AR19 -> 0 | AU19: =AC19/R19 -> 0.27631579 | AV19: =AC19/AR19 -> 4.257217 | AW19: =AG19/R19 -> 0.018190789 | AX19: =AG19/AR19 -> 0.28026679 | AY19: =AT19+AV19 -> 4.257217 | BA19: =IF(ISNUMBER(C19),C19*1000/100,0) -> 0.0873 | BB19: =IF(ISNUMBER(D19),D19*1000/100,0) -> 0 | BC19: =IF(ISNUMBER(E19),E19*1000/100,0) -> 92.5201 | BD19: =IF(ISNUMBER(F19),F19*1000/100,"") | BE19: =IF(ISNUMBER(G19),G19*1000/100,"") | BF19: =IF(ISNUMBER(H19),H19*1000/100,"") | BG19: =IF(ISNUMBER(I19),I19*1000/100,"") | BH19: =IF(ISNUMBER(J19),J19*1000/100,"") | BI19: =IF(ISNUMBER(K19),K19*1000/100,"") -> 1.2405 | BJ19: =IF(ISNUMBER(L19),L19*1000/100,"") | BK19: =IF(ISNUMBER(M19),M19*1000/100,"") | BL19: =IF(ISNUMBER(N19),N19*1000/100,"") | BN19: =S19 -> r2 | BP19: =B19 -> Jeff_SloHot50_Biostat 2L-21-6 | BV19: =$BC$15-BC19 -> -17.4383 | BX19: =BV19/R19 -> -3.6712211 | BY19: =BV19-BV17 -> 0.3083 | BZ19: =BY19/(R19-R17) -> 0.15415
B20: Jeff_SloHot50_Biostat 2L-21-7 | C20: 0.02456 | E20: 9.69707 | P20: 45586 | Q20: 0.66666667 | R20: 6.5 | S20: r1 | T20: 7 | U20: 3 | V20: - | W20: 8.34 | X20: 2 | Y20: 6.7243 | Z20: 6.762 | AA20: 8 | AB20: =Z20-Y20 -> 0.0377 | AC20: =AB20/(AA20/1000) -> 4.7125 | AD20: 11 | AE20: =FAME!P124 -> 1.059 | AF20: =AE20/AD20 -> 0.096272727 | AG20: =AF20*AC20 -> 0.45368523 | AH20: =W20/AC20 -> 1.7697613 | AI20: =BC18-BC20 -> 1.3754 | AJ20: =AI20/(R20-R18) -> 0.78594286 | AK20: =(AC20-AC18)/(R20-R18) -> 1.3 | AL20: =AK20/AJ20 -> 1.6540643 | AM20: =(BB20-BB18)/(R20-R18) -> 0 | AN20: =AM20/AJ20 -> 0 | AO20: =(AG20-AG18)/(R20-R18) -> 0.16952549 | AP20: =AO20/AJ20 -> 0.21569696 | AR20: =$BC$16-BC20 -> 2.2341 | AS20: =BB20/R20 -> 0 | AT20: =BB20/AR20 -> 0 | AU20: =AC20/R20 -> 0.725 | AV20: =AC20/AR20 -> 2.1093505 | AW20: =AG20/R20 -> 0.069797727 | AX20: =AG20/AR20 -> 0.20307293 | AY20: =AT20+AV20 -> 2.1093505 | BA20: =IF(ISNUMBER(C20),C20*1000/100,0) -> 0.2456 | BB20: =IF(ISNUMBER(D20),D20*1000/100,0) -> 0 | BC20: =IF(ISNUMBER(E20),E20*1000/100,0) -> 96.9707 | BD20: =IF(ISNUMBER(F20),F20*1000/100,"") | BE20: =IF(ISNUMBER(G20),G20*1000/100,"") | BF20: =IF(ISNUMBER(H20),H20*1000/100,"") | BG20: =IF(ISNUMBER(I20),I20*1000/100,"") | BH20: =IF(ISNUMBER(J20),J20*1000/100,"") | BI20: =IF(ISNUMBER(K20),K20*1000/100,"") | BJ20: =IF(ISNUMBER(L20),L20*1000/100,"") | BK20: =IF(ISNUMBER(M20),M20*1000/100,"") | BL20: =IF(ISNUMBER(N20),N20*1000/100,"") | BN20: =S20 -> r1 | BP20: =B20 -> Jeff_SloHot50_Biostat 2L-21-7 | BV20: =$BC$14-BC20 -> 2.1874 | BX20: =BV20/R20 -> 0.33652308 | BY20: =BV20-BV18 -> 1.3754 | BZ20: =BY20/(R20-R18) -> 0.78594286
B21: Jeff_SloHot50_Biostat 2L-21-8 | C21: 0.01179 | E21: 9.08076 | K21: 0.05957 | P21: 45586 | Q21: 0.66666667 | R21: 6.5 | S21: r2 | T21: 8 | U21: 3 | V21: - | W21: 4.1 | X21: 19 | Y21: 6.7056 | Z21: 6.7353 | AA21: 8 | AB21: =Z21-Y21 -> 0.0297 | AC21: =AB21/(AA21/1000) -> 3.7125 | AD21: 16 | AE21: =FAME!P125 -> 1.0915 | AF21: =AE21/AD21 -> 0.06821875 | AG21: =AF21*AC21 -> 0.25326211 | AH21: =W21/AC21 -> 1.1043771 | AI21: =BC19-BC21 -> 1.7125 | AJ21: =AI21/(R21-R19) -> 0.97857143 | AK21: =(AC21-AC19)/(R21-R19) -> 1.3714286 | AL21: =AK21/AJ21 -> 1.4014599 | AM21: =(BB21-BB19)/(R21-R19) -> 0 | AN21: =AM21/AJ21 -> 0 | AO21: =(AG21-AG19)/(R21-R19) -> 0.095346205 | AP21: =AO21/AJ21 -> 0.097434078 | AQ21: =AN21+AL21 -> 1.4014599 | AR21: =$BC$17-BC21 -> 2.0208 | AS21: =BB21/R21 -> 0 | AT21: =BB21/AR21 -> 0 | AU21: =AC21/R21 -> 0.57115385 | AV21: =AC21/AR21 -> 1.8371437 | AW21: =AG21/R21 -> 0.038963401 | AX21: =AG21/AR21 -> 0.12532765 | AY21: =AT21+AV21 -> 1.8371437 | BA21: =IF(ISNUMBER(C21),C21*1000/100,0) -> 0.1179 | BB21: =IF(ISNUMBER(D21),D21*1000/100,0) -> 0 | BC21: =IF(ISNUMBER(E21),E21*1000/100,0) -> 90.8076 | BD21: =IF(ISNUMBER(F21),F21*1000/100,"") | BE21: =IF(ISNUMBER(G21),G21*1000/100,"") | BF21: =IF(ISNUMBER(H21),H21*1000/100,"") | BG21: =IF(ISNUMBER(I21),I21*1000/100,"") | BH21: =IF(ISNUMBER(J21),J21*1000/100,"") | BI21: =IF(ISNUMBER(K21),K21*1000/100,"") -> 0.5957 | BJ21: =IF(ISNUMBER(L21),L21*1000/100,"") | BK21: =IF(ISNUMBER(M21),M21*1000/100,"") | BL21: =IF(ISNUMBER(N21),N21*1000/100,"") | BN21: =S21 -> r2 | BP21: =B21 -> Jeff_SloHot50_Biostat 2L-21-8 | BV21: =$BC$15-BC21 -> -15.7258 | BX21: =BV21/R21 -> -2.4193538 | BY21: =BV21-BV19 -> 1.7125 | BZ21: =BY21/(R21-R19) -> 0.97857143
B22: Jeff_SloHot50_Biostat 2L-21-9 | C22: 0.04266 | D22: 0.61993 | E22: 7.63091 | P22: 45587 | Q22: 0.27083333 | R22: 21 | S22: r1 | T22: 9 | U22: 1 | V22: - | W22: 23 | X22: 71 | Y22: 6.6975 | Z22: 6.7867 | AA22: 8 | AB22: =Z22-Y22 -> 0.0892 | AC22: =AB22/(AA22/1000) -> 11.15 | AD22: 15 | AE22: =FAME!P126 -> 2.351 | AF22: =AE22/AD22 -> 0.15673333 | AG22: =AF22*AC22 -> 1.7475767 | AH22: =W22/AC22 -> 2.0627803 | AI22: =BC20-BC22 -> 20.6616 | AJ22: =AI22/(R22-R20) -> 1.4249379 | AK22: =(AC22-AC20)/(R22-R20) -> 0.44396552 | AL22: =AK22/AJ22 -> 0.31156832 | AM22: =(BB22-BB20)/(R22-R20) -> 0.42753793 | AN22: =AM22/AJ22 -> 0.30003969 | AO22: =(AG22-AG20)/(R22-R20) -> 0.089233892 | AP22: =AO22/AJ22 -> 0.062623003 | AR22: =$BC$16-BC22 -> 22.8957 | AS22: =BB22/R22 -> 0.29520476 | AT22: =BB22/AR22 -> 0.27076263 | AU22: =AC22/R22 -> 0.53095238 | AV22: =AC22/AR22 -> 0.48699101 | AW22: =AG22/R22 -> 0.083217937 | AX22: =AG22/AR22 -> 0.076327724 | AY22: =AT22+AV22 -> 0.75775364 | BA22: =IF(ISNUMBER(C22),C22*1000/100,0) -> 0.4266 | BB22: =IF(ISNUMBER(D22),D22*1000/100,0) -> 6.1993 | BC22: =IF(ISNUMBER(E22),E22*1000/100,0) -> 76.3091 | BD22: =IF(ISNUMBER(F22),F22*1000/100,"") | BE22: =IF(ISNUMBER(G22),G22*1000/100,"") | BF22: =IF(ISNUMBER(H22),H22*1000/100,"") | BG22: =IF(ISNUMBER(I22),I22*1000/100,"") | BH22: =IF(ISNUMBER(J22),J22*1000/100,"") | BI22: =IF(ISNUMBER(K22),K22*1000/100,"") | BJ22: =IF(ISNUMBER(L22),L22*1000/100,"") | BK22: =IF(ISNUMBER(M22),M22*1000/100,"") | BL22: =IF(ISNUMBER(N22),N22*1000/100,"") | BN22: =S24 -> r1 | BP22: =#REF! -> #REF! | BV22: =$BC$14-BC22 -> 22.849 | BX22: =BV22/R24 -> 0.91396 | BY22: =BV22-BV20 -> 20.6616 | BZ22: =BY22/(R24-R20) -> 1.1168432 | CA22: =AC22-AC16 -> 9.3875 | CB22: =CA22/BY22 -> 0.45434526
B23: Jeff_SloHot50_Biostat 2L-21-10 | C23: 0.03779 | D23: 0.34731 | E23: 6.58951 | P23: 45587 | Q23: 0.27083333 | R23: 21 | S23: r2 | T23: 10 | U23: 1 | V23: - | W23: 26 | X23: 80 | Y23: 6.7058 | Z23: 6.8324 | AA23: 8 | AB23: =Z23-Y23 -> 0.1266 | AC23: =AB23/(AA23/1000) -> 15.825 | AD23: 15 | AE23: =FAME!P127 -> 1.128 | AF23: =AE23/AD23 -> 0.0752 | AG23: =AF23*AC23 -> 1.19004 | AH23: =W23/AC23 -> 1.64297 | AI23: =BC21-BC23 -> 24.9125 | AJ23: =AI23/(R23-R21) -> 1.7181034 | AK23: =(AC23-AC21)/(R23-R21) -> 0.83534483 | AL23: =AK23/AJ23 -> 0.48620171 | AM23: =(BB23-BB21)/(R23-R21) -> 0.23952414 | AN23: =AM23/AJ23 -> 0.13941194 | AO23: =(AG23-AG21)/(R23-R21) -> 0.064605372 | AP23: =AO23/AJ23 -> 0.037602725 | AQ23: =AN23+AL23 -> 0.62561365 | AR23: =$BC$17-BC23 -> 26.9333 | AS23: =BB23/R23 -> 0.16538571 | AT23: =BB23/AR23 -> 0.12895189 | AU23: =AC23/R23 -> 0.75357143 | AV23: =AC23/AR23 -> 0.58756261 | AW23: =AG23/R23 -> 0.056668571 | AX23: =AG23/AR23 -> 0.044184708 | AY23: =AT23+AV23 -> 0.7165145 | BA23: =IF(ISNUMBER(C23),C23*1000/100,0) -> 0.3779 | BB23: =IF(ISNUMBER(D23),D23*1000/100,0) -> 3.4731 | BC23: =IF(ISNUMBER(E23),E23*1000/100,0) -> 65.8951 | BD23: =IF(ISNUMBER(F23),F23*1000/100,"") | BE23: =IF(ISNUMBER(G23),G23*1000/100,"") | BF23: =IF(ISNUMBER(H23),H23*1000/100,"") | BG23: =IF(ISNUMBER(I23),I23*1000/100,"") | BH23: =IF(ISNUMBER(J23),J23*1000/100,"") | BI23: =IF(ISNUMBER(K23),K23*1000/100,"") | BJ23: =IF(ISNUMBER(L23),L23*1000/100,"") | BK23: =IF(ISNUMBER(M23),M23*1000/100,"") | BL23: =IF(ISNUMBER(N23),N23*1000/100,"") | BN23: =S25 -> r2 | BP23: =#REF! -> #REF! | BV23: =$BC$15-BC23 -> 9.1867 | BX23: =BV23/R25 -> 0.367468 | BY23: =BV23-BV21 -> 24.9125 | BZ23: =BY23/(R25-R21) -> 1.3466216 | CA23: =AC23-AC17 -> 14.9875 | CB23: =CA23/BY23 -> 0.60160562
B24: Jeff_SloHot50_Biostat 2L-21-11 | C24: 0.04386 | D24: 0.9072 | E24: 6.97496 | G24: 0.01383 | P24: 45587 | Q24: 0.4375 | R24: 25 | S24: r1 | T24: 11 | V24: - | W24: 26.68 | X24: 100 | Y24: 6.6882 | Z24: 6.7713 | AA24: 8 | AB24: =Z24-Y24 -> 0.0831 | AC24: =AB24/(AA24/1000) -> 10.3875 | AD24: 19 | AE24: =FAME!P128 -> 3.3845 | AF24: =AE24/AD24 -> 0.17813158 | AG24: =AF24*AC24 -> 1.8503418 | AH24: =W24/AC24 -> 2.5684717 | AI24: =BC22-BC24 -> 6.5595 | AJ24: =AI24/(R24-R22) -> 1.639875 | AK24: =(AC24-AC22)/(R24-R22) -> -0.190625 | AL24: =AK24/AJ24 -> -0.11624362 | AM24: =(BB24-BB22)/(R24-R22) -> 0.718175 | AN24: =AM24/AJ24 -> 0.43794497 | AO24: =(AG24-AG22)/(R24-R22) -> 0.025691277 | AP24: =AO24/AJ24 -> 0.015666607 | AQ24: =AN24+AL24 -> 0.32170135 | AR24: =$BC$16-BC24 -> 29.4552 | AS24: =BB24/R24 -> 0.36288 | AT24: =BB24/AR24 -> 0.30799316 | AU24: =AC24/R24 -> 0.4155 | AV24: =AC24/AR24 -> 0.3526542 | AW24: =AG24/R24 -> 0.074013671 | AX24: =AG24/AR24 -> 0.06281885 | AY24: =AT24+AV24 -> 0.66064736 | BA24: =IF(ISNUMBER(C24),C24*1000/100,0) -> 0.4386 | BB24: =IF(ISNUMBER(D24),D24*1000/100,0) -> 9.072 | BC24: =IF(ISNUMBER(E24),E24*1000/100,0) -> 69.7496 | BD24: =IF(ISNUMBER(F24),F24*1000/100,"") | BE24: =IF(ISNUMBER(G24),G24*1000/100,"") -> 0.1383 | BF24: =IF(ISNUMBER(H24),H24*1000/100,"") | BG24: =IF(ISNUMBER(I24),I24*1000/100,"") | BH24: =IF(ISNUMBER(J24),J24*1000/100,"") | BI24: =IF(ISNUMBER(K24),K24*1000/100,"") | BJ24: =IF(ISNUMBER(L24),L24*1000/100,"") | BK24: =IF(ISNUMBER(M24),M24*1000/100,"") | BL24: =IF(ISNUMBER(N24),N24*1000/100,"") | BN24: =S26 -> r1 | BP24: =B22 -> Jeff_SloHot50_Biostat 2L-21-9 | BV24: =$BC$14-BC24 -> 29.4085 | BX24: =BV24/R26 -> 0.98852101 | BY24: =BV24-BV22 -> 6.5595 | BZ24: =BY24/(R26-R24) -> 1.3809474
B25: Jeff_SloHot50_Biostat 2L-21-12 | C25: 0.03611 | D25: 0.61956 | E25: 5.85382 | P25: 45587 | Q25: 0.4375 | R25: 25 | S25: r2 | T25: 12 | V25: - | W25: 31 | X25: 108 | Y25: 6.6942 | Z25: 6.8273 | AA25: 8 | AB25: =Z25-Y25 -> 0.1331 | AC25: =AB25/(AA25/1000) -> 16.6375 | AD25: 18 | AE25: =FAME!P129 -> 2.0945 | AF25: =AE25/AD25 -> 0.11636111 | AG25: =AF25*AC25 -> 1.935958 | AH25: =W25/AC25 -> 1.8632607 | AI25: =BC23-BC25 -> 7.3569 | AJ25: =AI25/(R25-R23) -> 1.839225 | AK25: =(AC25-AC23)/(R25-R23) -> 0.203125 | AL25: =AK25/AJ25 -> 0.11044054 | AM25: =(BB25-BB23)/(R25-R23) -> 0.680625 | AN25: =AM25/AJ25 -> 0.37006076 | AO25: =(AG25-AG23)/(R25-R23) -> 0.1864795 | AP25: =AO25/AJ25 -> 0.10139026 | AQ25: =AN25+AL25 -> 0.4805013 | AR25: =$BC$17-BC25 -> 34.2902 | AS25: =BB25/R25 -> 0.247824 | AT25: =BB25/AR25 -> 0.18068136 | AU25: =AC25/R25 -> 0.6655 | AV25: =AC25/AR25 -> 0.48519694 | AW25: =AG25/R25 -> 0.077438319 | AX25: =AG25/AR25 -> 0.056458055 | AY25: =AT25+AV25 -> 0.6658783 | BA25: =IF(ISNUMBER(C25),C25*1000/100,0) -> 0.3611 | BB25: =IF(ISNUMBER(D25),D25*1000/100,0) -> 6.1956 | BC25: =IF(ISNUMBER(E25),E25*1000/100,0) -> 58.5382 | BD25: =IF(ISNUMBER(F25),F25*1000/100,"") | BE25: =IF(ISNUMBER(G25),G25*1000/100,"") | BF25: =IF(ISNUMBER(H25),H25*1000/100,"") | BG25: =IF(ISNUMBER(I25),I25*1000/100,"") | BH25: =IF(ISNUMBER(J25),J25*1000/100,"") | BI25: =IF(ISNUMBER(K25),K25*1000/100,"") | BJ25: =IF(ISNUMBER(L25),L25*1000/100,"") | BK25: =IF(ISNUMBER(M25),M25*1000/100,"") | BL25: =IF(ISNUMBER(N25),N25*1000/100,"") | BN25: =S27 -> r2 | BP25: =B23 -> Jeff_SloHot50_Biostat 2L-21-10 | BV25: =$BC$15-BC25 -> 16.5436 | BX25: =BV25/R27 -> 0.55608739 | BY25: =BV25-BV23 -> 7.3569 | BZ25: =BY25/(R27-R25) -> 1.5488211
B26: Jeff_SloHot50_Biostat 2L-21-13 | C26: 0.04216 | D26: 1.20728 | E26: 6.30927 | G26: 0.02 | P26: 45587 | Q26: 0.63541667 | R26: 29.75 | S26: r1 | T26: 13 | V26: - | W26: - | X26: 133 | Y26: 6.6979 | Z26: 6.7916 | AA26: 8 | AB26: =Z26-Y26 -> 0.0937 | AC26: =AB26/(AA26/1000) -> 11.7125 | AD26: 17 | AE26: =FAME!P130 -> 3.4315 | AF26: =AE26/AD26 -> 0.20185294 | AG26: =AF26*AC26 -> 2.3642026 | AH26: - | AI26: =BC24-BC26 -> 6.6569 | AJ26: =AI26/(R26-R24) -> 1.4014526 | AK26: =(AC26-AC24)/(R26-R24) -> 0.27894737 | AL26: =AK26/AJ26 -> 0.1990416 | AM26: =(BB26-BB24)/(R26-R24) -> 0.63174737 | AN26: =AM26/AJ26 -> 0.45078039 | AO26: =(AG26-AG24)/(R26-R24) -> 0.10818122 | AP26: =AO26/AJ26 -> 0.077192206 | AR26: =$BC$16-BC26 -> 36.1121 | AS26: =BB26/R26 -> 0.4058084 | AT26: =BB26/AR26 -> 0.33431454 | AU26: =AC26/R26 -> 0.39369748 | AV26: =AC26/AR26 -> 0.32433727 | AW26: =AG26/R26 -> 0.079468994 | AX26: =AG26/AR26 -> 0.065468432 | AY26: =AT26+AV26 -> 0.65865181 | BA26: =IF(ISNUMBER(C26),C26*1000/100,0) -> 0.4216 | BB26: =IF(ISNUMBER(D26),D26*1000/100,0) -> 12.0728 | BC26: =IF(ISNUMBER(E26),E26*1000/100,0) -> 63.0927 | BD26: =IF(ISNUMBER(F26),F26*1000/100,"") | BE26: =IF(ISNUMBER(G26),G26*1000/100,"") -> 0.2 | BF26: =IF(ISNUMBER(H26),H26*1000/100,"") | BG26: =IF(ISNUMBER(I26),I26*1000/100,"") | BH26: =IF(ISNUMBER(J26),J26*1000/100,"") | BI26: =IF(ISNUMBER(K26),K26*1000/100,"") | BJ26: =IF(ISNUMBER(L26),L26*1000/100,"") | BK26: =IF(ISNUMBER(M26),M26*1000/100,"") | BL26: =IF(ISNUMBER(N26),N26*1000/100,"") | BN26: =S28 -> r1 | BP26: =B24 -> Jeff_SloHot50_Biostat 2L-21-11 | BV26: =$BC$15-BC26 -> 11.9891 | BX26: =BV26/R28 -> 0.25783011 | BY26: =BV26-BV24 -> -17.4194 | BZ26: =BY26/(R28-R26) -> -1.0399642
B27: Jeff_SloHot50_Biostat 2L-21-14 | C27: 0.03486 | D27: 0.96685 | E27: 5.13681 | P27: 45587 | Q27: 0.63541667 | R27: 29.75 | S27: r2 | T27: 14 | V27: - | W27: - | X27: 144 | Y27: 6.7071 | Z27: 6.8478 | AA27: 8 | AB27: =Z27-Y27 -> 0.1407 | AC27: =AB27/(AA27/1000) -> 17.5875 | AD27: 12 | AE27: =FAME!P131 -> 1.916 | AF27: =AE27/AD27 -> 0.15966667 | AG27: =AF27*AC27 -> 2.8081375 | AH27: - | AI27: =BC25-BC27 -> 7.1701 | AJ27: =AI27/(R27-R25) -> 1.5094947 | AK27: =(AC27-AC25)/(R27-R25) -> 0.2 | AL27: =AK27/AJ27 -> 0.13249467 | AM27: =(BB27-BB25)/(R27-R25) -> 0.73113684 | AN27: =AM27/AJ27 -> 0.48435866 | AO27: =(AG27-AG25)/(R27-R25) -> 0.18361674 | AP27: =AO27/AJ27 -> 0.12164119 | AQ27: =AN27+AL27 -> 0.61685332 | AR27: =$BC$17-BC27 -> 41.4603 | AS27: =BB27/R27 -> 0.3249916 | AT27: =BB27/AR27 -> 0.23319899 | AU27: =AC27/R27 -> 0.59117647 | AV27: =AC27/AR27 -> 0.42420098 | AW27: =AG27/R27 -> 0.094391176 | AX27: =AG27/AR27 -> 0.067730757 | AY27: =AT27+AV27 -> 0.65739997 | BA27: =IF(ISNUMBER(C27),C27*1000/100,0) -> 0.3486 | BB27: =IF(ISNUMBER(D27),D27*1000/100,0) -> 9.6685 | BC27: =IF(ISNUMBER(E27),E27*1000/100,0) -> 51.3681 | BD27: =IF(ISNUMBER(F27),F27*1000/100,"") | BE27: =IF(ISNUMBER(G27),G27*1000/100,"") | BF27: =IF(ISNUMBER(H27),H27*1000/100,"") | BG27: =IF(ISNUMBER(I27),I27*1000/100,"") | BH27: =IF(ISNUMBER(J27),J27*1000/100,"") | BI27: =IF(ISNUMBER(K27),K27*1000/100,"") | BJ27: =IF(ISNUMBER(L27),L27*1000/100,"") | BK27: =IF(ISNUMBER(M27),M27*1000/100,"") | BL27: =IF(ISNUMBER(N27),N27*1000/100,"") | BN27: =S29 -> r2 | BP27: =B25 -> Jeff_SloHot50_Biostat 2L-21-12 | BV27: =$BC$15-BC27 -> 23.7137 | BX27: =BV27/R29 -> 0.50997204 | BY27: =BV27-BV25 -> 7.1701 | BZ27: =BY27/(R29-R27) -> 0.42806567
B28: Biostat 21-15 | D28: 2.324 | E28: 4.147 | F28: 0.144 | P28: 45588 | Q28: 0.33333333 | R28: 46.5 | S28: r1 | T28: 15 | U28: 3 | W28: 32.28 | X28: 254 | Y28: 6.7393 | Z28: 6.837 | AA28: 8 | AB28: =Z28-Y28 -> 0.0977 | AC28: =AB28/(AA28/1000) -> 12.2125 | AD28: 14 | AE28: =FAME!P132 -> 2.969 | AF28: =AE28/AD28 -> 0.21207143 | AG28: =AF28*AC28 -> 2.5899223 | AH28: =W28/AC28 -> 2.6431934 | AI28: =BC26-BC28 -> 21.6227 | AJ28: =AI28/(R28-R26) -> 1.2909075 | AK28: =(AC28-AC26)/(R28-R26) -> 0.029850746 | AL28: =AK28/AJ28 -> 0.023123847 | AM28: =(BB28-BB26)/(R28-R26) -> 0.66669851 | AN28: =AM28/AJ28 -> 0.51645724 | AO28: =(AG28-AG26)/(R28-R26) -> 0.013475806 | AP28: =AO28/AJ28 -> 0.010439018 | AR28: =$BC$16-BC28 -> 57.7348 | AS28: =BB28/R28 -> 0.49978495 | AT28: =BB28/AR28 -> 0.40253019 | AU28: =AC28/R28 -> 0.26263441 | AV28: =AC28/AR28 -> 0.21152754 | AW28: =AG28/R28 -> 0.055697254 | AX28: =AG28/AR28 -> 0.044858947 | AY28: =AT28+AV28 -> 0.61405773 | BA28: =IF(ISNUMBER(C28),C28*1000/100,0) -> 0 | BB28: =IF(ISNUMBER(D28),D28*1000/100,0) -> 23.24 | BC28: =IF(ISNUMBER(E28),E28*1000/100,0) -> 41.47 | BD28: =IF(ISNUMBER(F28),F28*1000/100,"") -> 1.44 | BE28: =IF(ISNUMBER(G28),G28*1000/100,"") | BF28: =IF(ISNUMBER(H28),H28*1000/100,"") | BG28: =IF(ISNUMBER(I28),I28*1000/100,"") | BH28: =IF(ISNUMBER(J28),J28*1000/100,"") | BI28: =IF(ISNUMBER(K28),K28*1000/100,"") | BJ28: =IF(ISNUMBER(L28),L28*1000/100,"") | BK28: =IF(ISNUMBER(M28),M28*1000/100,"") | BL28: =IF(ISNUMBER(N28),N28*1000/100,"") | BN28: =S30 -> r1 | BP28: =B26 -> Jeff_SloHot50_Biostat 2L-21-13 | BV28: =$BC$15-BC28 -> 33.6118 | BX28: =BV28/R30 -> 0.66230148 | BY28: =BV28-BV26 -> 21.6227 | BZ28: =BY28/(R30-R28) -> 5.0876941
B29: Biostat 21-16 | D29: 2.456 | E29: 2.497 | F29: 0.157 | P29: 45588 | Q29: 0.33333333 | R29: 46.5 | S29: r2 | T29: 16 | U29: 3 | W29: 33.6 | X29: 305 | Y29: 6.6955 | Z29: 6.8477 | AA29: 8 | AB29: =Z29-Y29 -> 0.1522 | AC29: =AB29/(AA29/1000) -> 19.025 | AD29: 14 | AE29: =FAME!P133 -> 2.26 | AF29: =AE29/AD29 -> 0.16142857 | AG29: =AF29*AC29 -> 3.0711786 | AH29: =W29/AC29 -> 1.7660972 | AI29: =BC27-BC29 -> 26.3981 | AJ29: =AI29/(R29-R27) -> 1.576006 | AK29: =(AC29-AC27)/(R29-R27) -> 0.085820896 | AL29: =AK29/AJ29 -> 0.054454677 | AM29: =(BB29-BB27)/(R29-R27) -> 0.88904478 | AN29: =AM29/AJ29 -> 0.56411257 | AO29: =(AG29-AG27)/(R29-R27) -> 0.015703945 | AP29: =AO29/AJ29 -> 0.0099643941 | AQ29: =AN29+AL29 -> 0.61856725 | AR29: =$BC$17-BC29 -> 67.8584 | AS29: =BB29/R29 -> 0.52817204 | AT29: =BB29/AR29 -> 0.36193014 | AU29: =AC29/R29 -> 0.40913978 | AV29: =AC29/AR29 -> 0.28036323 | AW29: =AG29/R29 -> 0.066046851 | AX29: =AG29/AR29 -> 0.045258635 | AY29: =AT29+AV29 -> 0.64229336 | BA29: =IF(ISNUMBER(C29),C29*1000/100,0) -> 0 | BB29: =IF(ISNUMBER(D29),D29*1000/100,0) -> 24.56 | BC29: =IF(ISNUMBER(E29),E29*1000/100,0) -> 24.97 | BD29: =IF(ISNUMBER(F29),F29*1000/100,"") -> 1.57 | BE29: =IF(ISNUMBER(G29),G29*1000/100,"") | BF29: =IF(ISNUMBER(H29),H29*1000/100,"") | BG29: =IF(ISNUMBER(I29),I29*1000/100,"") | BH29: =IF(ISNUMBER(J29),J29*1000/100,"") | BI29: =IF(ISNUMBER(K29),K29*1000/100,"") | BJ29: =IF(ISNUMBER(L29),L29*1000/100,"") | BK29: =IF(ISNUMBER(M29),M29*1000/100,"") | BL29: =IF(ISNUMBER(N29),N29*1000/100,"") | BN29: =S31 -> r2 | BP29: =B27 -> Jeff_SloHot50_Biostat 2L-21-14 | BV29: =$BC$15-BC29 -> 50.1118 | BX29: =BV29/R31 -> 0.98742463 | BY29: =BV29-BV27 -> 26.3981 | BZ29: =BY29/(R31-R29) -> 6.2113176
B30: Jeff_SloHot50_Biostat 2L-21-17 | C30: 0.04456 | D30: 2.53698 | E30: 3.65939 | G30: 0.03189 | K30: 0.08932 | P30: 45588 | Q30: 0.51041667 | R30: 50.75 | S30: r1 | T30: 17 | U30: 3 | W30: 31.25 | X30: 283 | Y30: 6.6781 | Z30: 6.7719 | AA30: 8 | AB30: =Z30-Y30 -> 0.0938 | AC30: =AB30/(AA30/1000) -> 11.725 | AD30: 16 | AE30: =FAME!P134 -> 3.262 | AF30: =AE30/AD30 -> 0.203875 | AG30: =AF30*AC30 -> 2.3904344 | AH30: =W30/AC30 -> 2.6652452 | AI30: =BC28-BC30 -> 4.8761 | AJ30: =AI30/(R30-R28) -> 1.1473176 | AK30: =(AC30-AC28)/(R30-R28) -> -0.11470588 | AL30: =AK30/AJ30 -> -0.099977441 | AM30: =(BB30-BB28)/(R30-R28) -> 0.50112941 | AN30: =AM30/AJ30 -> 0.4367835 | AO30: =(AG30-AG28)/(R30-R28) -> -0.04693834 | AP30: =AO30/AJ30 -> -0.040911373 | AR30: =$BC$16-BC30 -> 62.6109 | AS30: =BB30/R30 -> 0.49989754 | AT30: =BB30/AR30 -> 0.40519782 | AU30: =AC30/R30 -> 0.23103448 | AV30: =AC30/AR30 -> 0.18726771 | AW30: =AG30/R30 -> 0.047102155 | AX30: =AG30/AR30 -> 0.038179205 | AY30: =AT30+AV30 -> 0.59246553 | BA30: =IF(ISNUMBER(C30),C30*1000/100,0) -> 0.4456 | BB30: =IF(ISNUMBER(D30),D30*1000/100,0) -> 25.3698 | BC30: =IF(ISNUMBER(E30),E30*1000/100,0) -> 36.5939 | BD30: =IF(ISNUMBER(F30),F30*1000/100,"") | BE30: =IF(ISNUMBER(G30),G30*1000/100,"") -> 0.3189 | BF30: =IF(ISNUMBER(H30),H30*1000/100,"") | BG30: =IF(ISNUMBER(I30),I30*1000/100,"") | BH30: =IF(ISNUMBER(J30),J30*1000/100,"") | BI30: =IF(ISNUMBER(K30),K30*1000/100,"") -> 0.8932 | BJ30: =IF(ISNUMBER(L30),L30*1000/100,"") | BK30: =IF(ISNUMBER(M30),M30*1000/100,"") | BL30: =IF(ISNUMBER(N30),N30*1000/100,"") | BP30: =B28 -> Biostat 21-15
B31: Jeff_SloHot50_Biostat 2L-21-18 | C31: 0.03731 | D31: 2.75503 | E31: 1.93496 | P31: 45588 | Q31: 0.51041667 | R31: 50.75 | S31: r2 | T31: 18 | U31: 3 | W31: 37.7 | X31: 345 | Y31: 6.7332 | Z31: 6.8749 | AA31: 8 | AB31: =Z31-Y31 -> 0.1417 | AC31: =AB31/(AA31/1000) -> 17.7125 | AD31: 14 | AE31: =FAME!P135 -> 2.5945 | AF31: =AE31/AD31 -> 0.18532143 | AG31: =AF31*AC31 -> 3.2825058 | AH31: =W31/AC31 -> 2.1284404 | AI31: =BC29-BC31 -> 5.6204 | AJ31: =AI31/(R31-R29) -> 1.3224471 | AK31: =(AC31-AC29)/(R31-R29) -> -0.30882353 | AL31: =AK31/AJ31 -> -0.2335243 | AM31: =(BB31-BB29)/(R31-R29) -> 0.7036 | AN31: =AM31/AJ31 -> 0.53204398 | AO31: =(AG31-AG29)/(R31-R29) -> 0.049724055 | AP31: =AO31/AJ31 -> 0.037600034 | AQ31: =AN31+AL31 -> 0.29851968 | AR31: =$BC$17-BC31 -> 73.4788 | AS31: =BB31/R31 -> 0.54286305 | AT31: =BB31/AR31 -> 0.37494216 | AU31: =AC31/R31 -> 0.34901478 | AV31: =AC31/AR31 -> 0.24105592 | AW31: =AG31/R31 -> 0.064679917 | AX31: =AG31/AR31 -> 0.044672828 | AY31: =AT31+AV31 -> 0.61599808 | BA31: =IF(ISNUMBER(C31),C31*1000/100,0) -> 0.3731 | BB31: =IF(ISNUMBER(D31),D31*1000/100,0) -> 27.5503 | BC31: =IF(ISNUMBER(E31),E31*1000/100,0) -> 19.3496 | BD31: =IF(ISNUMBER(F31),F31*1000/100,"") | BE31: =IF(ISNUMBER(G31),G31*1000/100,"") | BF31: =IF(ISNUMBER(H31),H31*1000/100,"") | BG31: =IF(ISNUMBER(I31),I31*1000/100,"") | BH31: =IF(ISNUMBER(J31),J31*1000/100,"") | BI31: =IF(ISNUMBER(K31),K31*1000/100,"") | BJ31: =IF(ISNUMBER(L31),L31*1000/100,"") | BK31: =IF(ISNUMBER(M31),M31*1000/100,"") | BL31: =IF(ISNUMBER(N31),N31*1000/100,"") | BP31: =B29 -> Biostat 21-16
B32: Biostat 21-19 | D32: 3.556 | E32: 1.893 | F32: 0.143 | P32: 45589 | Q32: 0.36458333 | R32: 71.25 | S32: r1 | T32: 19 | U32: 3 | W32: 31.72 | X32: 409 | Y32: 6.7264 | Z32: 6.8297 | AA32: 8 | AB32: =Z32-Y32 -> 0.1033 | AC32: =AB32/(AA32/1000) -> 12.9125 | AD32: 13 | AE32: =FAME!P136 -> 2.7415 | AF32: =AE32/AD32 -> 0.21088462 | AG32: =AF32*AC32 -> 2.7230476 | AH32: =W32/AC32 -> 2.4565344 | AI32: =BC30-BC32 -> 17.6639 | AJ32: =AI32/(R32-R30) -> 0.86165366 | AK32: =(AC32-AC30)/(R32-R30) -> 0.057926829 | AL32: =AK32/AJ32 -> 0.067227509 | AM32: =(BB32-BB30)/(R32-R30) -> 0.49708293 | AN32: =AM32/AJ32 -> 0.57689412 | AO32: =(AG32-AG30)/(R32-R30) -> 0.016225035 | AP32: =AO32/AJ32 -> 0.018830112 | AR32: =$BC$16-BC32 -> 80.2748 | AS32: =BB32/R32 -> 0.49908772 | AT32: =BB32/AR32 -> 0.44297837 | AU32: =AC32/R32 -> 0.18122807 | AV32: =AC32/AR32 -> 0.16085372 | AW32: =AG32/R32 -> 0.038218212 | AX32: =AG32/AR32 -> 0.033921574 | AY32: =AT32+AV32 -> 0.60383209 | BA32: =IF(ISNUMBER(C32),C32*1000/100,0) -> 0 | BB32: =IF(ISNUMBER(D32),D32*1000/100,0) -> 35.56 | BC32: =IF(ISNUMBER(E32),E32*1000/100,0) -> 18.93 | BD32: =IF(ISNUMBER(F32),F32*1000/100,"") -> 1.43 | BE32: =IF(ISNUMBER(G32),G32*1000/100,"") | BF32: =IF(ISNUMBER(H32),H32*1000/100,"") | BG32: =IF(ISNUMBER(I32),I32*1000/100,"") | BH32: =IF(ISNUMBER(J32),J32*1000/100,"") | BI32: =IF(ISNUMBER(K32),K32*1000/100,"") | BJ32: =IF(ISNUMBER(L32),L32*1000/100,"") | BK32: =IF(ISNUMBER(M32),M32*1000/100,"") | BL32: =IF(ISNUMBER(N32),N32*1000/100,"")
B33: Biostat 21-20 | D33: 4.266 | P33: 45589 | Q33: 0.36458333 | R33: 71.25 | S33: r2 | T33: 20 | U33: 3 | W33: 38.24 | X33: 514 | Y33: 6.6433 | Z33: 6.7959 | AA33: 8 | AB33: =Z33-Y33 -> 0.1526 | AC33: =AB33/(AA33/1000) -> 19.075 | AD33: 15 | AE33: =FAME!P137 -> 2.6685 | AF33: =AE33/AD33 -> 0.1779 | AG33: =AF33*AC33 -> 3.3934425 | AH33: =W33/AC33 -> 2.0047182 | AI33: =BC31-BC33 -> 19.3496 | AJ33: =AI33/(R33-R31) -> 0.94388293 | AK33: =(AC33-AC31)/(R33-R31) -> 0.066463415 | AL33: =AK33/AJ33 -> 0.070414892 | AM33: =(BB33-BB31)/(R33-R31) -> 0.73705854 | AN33: =AM33/AJ33 -> 0.78087919 | AO33: =(AG33-AG31)/(R33-R31) -> 0.0054115462 | AP33: =AO33/AJ33 -> 0.0057332811 | AQ33: =AN33+AL33 -> 0.85129408 | AR33: =$BC$17-BC33 -> 92.8284 | AS33: =BB33/R33 -> 0.59873684 | AT33: =BB33/AR33 -> 0.45955764 | AU33: =AC33/R33 -> 0.2677193 | AV33: =AC33/AR33 -> 0.20548668 | AW33: =AG33/R33 -> 0.047627263 | AX33: =AG33/AR33 -> 0.036556081 | AY33: =AT33+AV33 -> 0.66504432 | BA33: =IF(ISNUMBER(C33),C33*1000/100,0) -> 0 | BB33: =IF(ISNUMBER(D33),D33*1000/100,0) -> 42.66 | BC33: =IF(ISNUMBER(E33),E33*1000/100,0) -> 0 | BD33: =IF(ISNUMBER(F33),F33*1000/100,"") | BE33: =IF(ISNUMBER(G33),G33*1000/100,"") | BF33: =IF(ISNUMBER(H33),H33*1000/100,"") | BG33: =IF(ISNUMBER(I33),I33*1000/100,"") | BH33: =IF(ISNUMBER(J33),J33*1000/100,"") | BI33: =IF(ISNUMBER(K33),K33*1000/100,"") | BJ33: =IF(ISNUMBER(L33),L33*1000/100,"") | BK33: =IF(ISNUMBER(M33),M33*1000/100,"") | BL33: =IF(ISNUMBER(N33),N33*1000/100,"")
B34: Jeff_SloHot50_Biostat 2L-21-21 | C34: 0.04862 | D34: 3.89235 | E34: 1.51801 | G34: 0.0231 | P34: 45589 | Q34: 0.63541667 | R34: 77.75 | S34: r1 | T34: 21 | W34: 34.95 | X34: 446 | Y34: 6.7199 | Z34: 6.8032 | AA34: 8 | AB34: =Z34-Y34 -> 0.0833 | AC34: =AB34/(AA34/1000) -> 10.4125 | AD34: 16 | AE34: =FAME!P138 -> 3.24 | AF34: =AE34/AD34 -> 0.2025 | AG34: =AF34*AC34 -> 2.1085313 | AH34: =W34/AC34 -> 3.3565426 | AI34: =BC32-BC34 -> 3.7499 | AJ34: =AI34/(R34-R32) -> 0.57690769 | AK34: =(AC34-AC32)/(R34-R32) -> -0.38461538 | AL34: =AK34/AJ34 -> -0.66668444 | AM34: =(BB34-BB32)/(R34-R32) -> 0.51746154 | AN34: =AM34/AJ34 -> 0.89695725 | AO34: =(AG34-AG32)/(R34-R32) -> -0.094540976 | AP34: =AO34/AJ34 -> -0.1638754 | AR34: =$BC$16-BC34 -> 84.0247 | AS34: =BB34/R34 -> 0.50062379 | AT34: =BB34/AR34 -> 0.46323879 | AU34: =AC34/R34 -> 0.13392283 | AV34: =AC34/AR34 -> 0.12392189 | AW34: =AG34/R34 -> 0.027119373 | AX34: =AG34/AR34 -> 0.025094184 | AY34: =AT34+AV34 -> 0.58716068 | BA34: =IF(ISNUMBER(C34),C34*1000/100,0) -> 0.4862 | BB34: =IF(ISNUMBER(D34),D34*1000/100,0) -> 38.9235 | BC34: =IF(ISNUMBER(E34),E34*1000/100,0) -> 15.1801 | BD34: =IF(ISNUMBER(F34),F34*1000/100,"") | BE34: =IF(ISNUMBER(G34),G34*1000/100,"") -> 0.231 | BF34: =IF(ISNUMBER(H34),H34*1000/100,"") | BG34: =IF(ISNUMBER(I34),I34*1000/100,"") | BH34: =IF(ISNUMBER(J34),J34*1000/100,"") | BI34: =IF(ISNUMBER(K34),K34*1000/100,"") | BJ34: =IF(ISNUMBER(L34),L34*1000/100,"") | BK34: =IF(ISNUMBER(M34),M34*1000/100,"") | BL34: =IF(ISNUMBER(N34),N34*1000/100,"")
B35: Jeff_SloHot50_Biostat 2L-21-22 | C35: 0.02721 | D35: 4.26675 | P35: 45589 | Q35: 0.63541667 | R35: 77.75 | S35: r2 | T35: 22 | W35: 36.5 | X35: 526 | Y35: 6.7343 | Z35: 6.8563 | AA35: 8 | AB35: =Z35-Y35 -> 0.122 | AC35: =AB35/(AA35/1000) -> 15.25 | AD35: 11 | AE35: =FAME!P139 -> 1.9515 | AF35: =AE35/AD35 -> 0.17740909 | AG35: =AF35*AC35 -> 2.7054886 | AH35: =W35/AC35 -> 2.3934426 | AI35: =BC33-BC35 -> 0 | AJ35: =AI35/(R35-R33) -> 0 | AK35: =(AC35-AC33)/(R35-R33) -> -0.58846154 | AM35: =(BB35-BB33)/(R35-R33) -> 0.0011538462 | AN35: =AM35/AJ35 -> #DIV/0! | AO35: =(AG35-AG33)/(R35-R33) -> -0.10583906 | AR35: =$BC$17-BC35 -> 92.8284 | AS35: =BB35/R35 -> 0.54877814 | AT35: =BB35/AR35 -> 0.45963843 | AU35: =AC35/R35 -> 0.19614148 | AV35: =AC35/AR35 -> 0.16428162 | AW35: =AG35/R35 -> 0.034797281 | AX35: =AG35/AR35 -> 0.029145053 | AY35: =AT35+AV35 -> 0.62392005 | BA35: =IF(ISNUMBER(C35),C35*1000/100,0) -> 0.2721 | BB35: =IF(ISNUMBER(D35),D35*1000/100,0) -> 42.6675 | BC35: =IF(ISNUMBER(E35),E35*1000/100,0) -> 0 | BD35: =IF(ISNUMBER(F35),F35*1000/100,"") | BE35: =IF(ISNUMBER(G35),G35*1000/100,"") | BF35: =IF(ISNUMBER(H35),H35*1000/100,"") | BG35: =IF(ISNUMBER(I35),I35*1000/100,"") | BH35: =IF(ISNUMBER(J35),J35*1000/100,"") | BI35: =IF(ISNUMBER(K35),K35*1000/100,"") | BJ35: =IF(ISNUMBER(L35),L35*1000/100,"") | BK35: =IF(ISNUMBER(M35),M35*1000/100,"") | BL35: =IF(ISNUMBER(N35),N35*1000/100,"")
B36: Biostat 21-23 | D36: 4.552 | E36: 0.373 | P36: 45590 | Q36: 0.58333333 | R36: 100.5 | S36: r1 | T36: 23 | W36: 31.72 | X36: 537 | Y36: 6.7239 | Z36: 6.8281 | AA36: 8 | AB36: =Z36-Y36 -> 0.1042 | AC36: =AB36/(AA36/1000) -> 13.025 | AD36: 13 | AE36: =FAME!P140 -> 2.442 | AF36: =AE36/AD36 -> 0.18784615 | AG36: =AF36*AC36 -> 2.4466962 | AH36: =W36/AC36 -> 2.4353167 | AI36: =BC34-BC36 -> 11.4501 | AJ36: =AI36/(R36-R34) -> 0.5033011 | AK36: =(AC36-AC34)/(R36-R34) -> 0.11483516 | AL36: =AK36/AJ36 -> 0.22816395 | AM36: =(BB36-BB34)/(R36-R34) -> 0.28995604 | AN36: =AM36/AJ36 -> 0.57610851 | AO36: =(AG36-AG34)/(R36-R34) -> 0.014864391 | AP36: =AO36/AJ36 -> 0.029533795 | AR36: =$BC$16-BC36 -> 95.4748 | AS36: =BB36/R36 -> 0.45293532 | AT36: =BB36/AR36 -> 0.47677502 | AU36: =AC36/R36 -> 0.12960199 | AV36: =AC36/AR36 -> 0.13642343 | AW36: =AG36/R36 -> 0.024345235 | AX36: =AG36/AR36 -> 0.025626617 | AY36: =AT36+AV36 -> 0.61319846 | BA36: =IF(ISNUMBER(C36),C36*1000/100,0) -> 0 | BB36: =IF(ISNUMBER(D36),D36*1000/100,0) -> 45.52 | BC36: =IF(ISNUMBER(E36),E36*1000/100,0) -> 3.73 | BD36: =IF(ISNUMBER(F36),F36*1000/100,"") | BE36: =IF(ISNUMBER(G36),G36*1000/100,"") | BF36: =IF(ISNUMBER(H36),H36*1000/100,"") | BG36: =IF(ISNUMBER(I36),I36*1000/100,"") | BH36: =IF(ISNUMBER(J36),J36*1000/100,"") | BI36: =IF(ISNUMBER(K36),K36*1000/100,"") | BJ36: =IF(ISNUMBER(L36),L36*1000/100,"") | BK36: =IF(ISNUMBER(M36),M36*1000/100,"") | BL36: =IF(ISNUMBER(N36),N36*1000/100,"")
B37: Biostat 21-24 | D37: 4.313 | P37: 45590 | Q37: 0.58333333 | R37: 100.5 | S37: r2 | T37: 24 | W37: 39.42 | X37: 534 | Y37: 6.7188 | Z37: 6.8588 | AA37: 8 | AB37: =Z37-Y37 -> 0.14 | AC37: =AB37/(AA37/1000) -> 17.5 | AD37: 12 | AE37: =FAME!P141 -> 2.029 | AF37: =AE37/AD37 -> 0.16908333 | AG37: =AF37*AC37 -> 2.9589583 | AH37: =W37/AC37 -> 2.2525714 | AI37: =BC35-BC37 -> 0 | AJ37: =AI37/(R37-R35) -> 0 | AK37: =(AC37-AC35)/(R37-R35) -> 0.098901099 | AM37: =(BB37-BB35)/(R37-R35) -> 0.02032967 | AN37: =AM37/AJ37 -> #DIV/0! | AO37: =(AG37-AG35)/(R37-R35) -> 0.011141525 | AR37: =$BC$17-BC37 -> 92.8284 | AS37: =BB37/R37 -> 0.42915423 | AT37: =BB37/AR37 -> 0.46462074 | AU37: =AC37/R37 -> 0.17412935 | AV37: =AC37/AR37 -> 0.18851989 | AW37: =AG37/R37 -> 0.029442371 | AX37: =AG37/AR37 -> 0.031875572 | AY37: =AT37+AV37 -> 0.65314063 | BA37: =IF(ISNUMBER(C37),C37*1000/100,0) -> 0 | BB37: =IF(ISNUMBER(D37),D37*1000/100,0) -> 43.13 | BC37: =IF(ISNUMBER(E37),E37*1000/100,0) -> 0 | BD37: =IF(ISNUMBER(F37),F37*1000/100,"") | BE37: =IF(ISNUMBER(G37),G37*1000/100,"") | BF37: =IF(ISNUMBER(H37),H37*1000/100,"") | BG37: =IF(ISNUMBER(I37),I37*1000/100,"") | BH37: =IF(ISNUMBER(J37),J37*1000/100,"") | BI37: =IF(ISNUMBER(K37),K37*1000/100,"") | BJ37: =IF(ISNUMBER(L37),L37*1000/100,"") | BK37: =IF(ISNUMBER(M37),M37*1000/100,"") | BL37: =IF(ISNUMBER(N37),N37*1000/100,"")
U71: =390/24 -> 16.25

Sheet FAME
D1: CALIBRATION RANGE: | E1: Compound | F1: High Cal | G1: Low Cal
E2: C13:0 | F2: 2.4985 | G2: 0.048133983
E3: C14:0 | F3: 1 | G3: 0.0096267966
E4: C16:0 | F4: 2.5 | G4: 0.024066992
E5: C16:1 (cis9) | F5: 1 | G5: 0.0096267966
E6: C18:0 | F6: 1.2493 | G6: 0.024066992
E7: C18:1 (cis 9) | F7: 4.997 | G7: 0.096267966
E8: C18:2 (cis9,12) | F8: 4.997 | G8: 0.096267966
E9: C21:0 | F9: 2.4985 | G9: 0.048133983
E10: C24:0 | F10: 0.4997 | G10: 0.0096267966
A11: Quantitation Report (QT Reviewed) | H11: Quantitation Report (QT Reviewed) | O11: Quantitation Report (QT Reviewed) | V11: Quantitation Report (QT Reviewed) | AC11: Quantitation Report (QT Reviewed) | AJ11: Quantitation Report (QT Reviewed) | AQ11: Quantitation Report (QT Reviewed) | AX11: Quantitation Report (QT Reviewed) | BE11: Quantitation Report (QT Reviewed) | BL11: Quantitation Report (QT Reviewed) | BS11: Quantitation Report (QT Reviewed) | BZ11: Quantitation Report (QT Reviewed)
A13: Data Path : D:\MassHunter\GCMS\1\data\24-OCT-30-Jeff_FID_FAMES\ | H13: Data Path : D:\MassHunter\GCMS\1\data\24-OCT-30-Jeff_FID_FAMES\ | O13: Data Path : D:\MassHunter\GCMS\1\data\24-OCT-30-Jeff_FID_FAMES\ | V13: Data Path : D:\MassHunter\GCMS\1\data\24-OCT-30-Jeff_FID_FAMES\ | AC13: Data Path : D:\MassHunter\GCMS\1\data\24-OCT-30-Jeff_FID_FAMES\ | AJ13: Data Path : D:\MassHunter\GCMS\1\data\24-OCT-30-Jeff_FID_FAMES\ | AQ13: Data Path : D:\MassHunter\GCMS\1\data\24-OCT-30-Jeff_FID_FAMES\ | AX13: Data Path : D:\MassHunter\GCMS\1\data\24-OCT-30-Jeff_FID_FAMES\ | BE13: Data Path : D:\MassHunter\GCMS\1\data\24-OCT-30-Jeff_FID_FAMES\ | BL13: Data Path : D:\MassHunter\GCMS\1\data\24-OCT-30-Jeff_FID_FAMES\ | BS13: Data Path : D:\MassHunter\GCMS\1\data\24-OCT-30-Jeff_FID_FAMES\ | BZ13: Data Path : D:\MassHunter\GCMS\1\data\24-OCT-30-Jeff_FID_FAMES\
A14: Data File : BioStat-2L_21_01.D | H14: Data File : BioStat-2L_21_02.D | O14: Data File : BioStat-2L_21_03.D | V14: Data File : BioStat-2L_21_04.D | AC14: Data File : BioStat-2L_21_05.D | AJ14: Data File : BioStat-2L_21_06.D | AQ14: Data File : BioStat-2L_21_07.D | AX14: Data File : BioStat-2L_21_08.D | BE14: Data File : BioStat-2L_21_09.D | BL14: Data File : BioStat-2L_21_10.D | BS14: Data File : BioStat-2L_21_11.D | BZ14: Data File : BioStat-2L_21_12.D
A15: Signal(s) : FID1B.ch | H15: Signal(s) : FID1B.ch | O15: Signal(s) : FID1B.ch | V15: Signal(s) : FID1B.ch | AC15: Signal(s) : FID1B.ch | AJ15: Signal(s) : FID1B.ch | AQ15: Signal(s) : FID1B.ch | AX15: Signal(s) : FID1B.ch | BE15: Signal(s) : FID1B.ch | BL15: Signal(s) : FID1B.ch | BS15: Signal(s) : FID1B.ch | BZ15: Signal(s) : FID1B.ch
A16: Acq On : 31 Oct 2024 15:24 | H16: Acq On : 31 Oct 2024 15:58 | O16: Acq On : 31 Oct 2024 16:32 | V16: Acq On : 31 Oct 2024 17:06 | AC16: Acq On : 31 Oct 2024 17:40 | AJ16: Acq On : 31 Oct 2024 18:14 | AQ16: Acq On : 31 Oct 2024 18:48 | AX16: Acq On : 31 Oct 2024 19:22 | BE16: Acq On : 31 Oct 2024 19:56 | BL16: Acq On : 31 Oct 2024 20:30 | BS16: Acq On : 31 Oct 2024 21:39 | BZ16: Acq On : 31 Oct 2024 22:13
A17: Operator : | H17: Operator : | O17: Operator : | V17: Operator : | AC17: Operator : | AJ17: Operator : | AQ17: Operator : | AX17: Operator : | BE17: Operator : | BL17: Operator : | BS17: Operator : | BZ17: Operator :
A18: Sample : BioStat-2L_21_01 | H18: Sample : BioStat-2L_21_02 | O18: Sample : BioStat-2L_21_03 | V18: Sample : BioStat-2L_21_04 | AC18: Sample : BioStat-2L_21_05 | AJ18: Sample : BioStat-2L_21_06 | AQ18: Sample : BioStat-2L_21_07 | AX18: Sample : BioStat-2L_21_08 | BE18: Sample : BioStat-2L_21_09 | BL18: Sample : BioStat-2L_21_10 | BS18: Sample : BioStat-2L_21_11 | BZ18: Sample : BioStat-2L_21_12
A19: Misc : | H19: Misc : | O19: Misc : | V19: Misc : | AC19: Misc : | AJ19: Misc : | AQ19: Misc : | AX19: Misc : | BE19: Misc : | BL19: Misc : | BS19: Misc : | BZ19: Misc :
A20: ALS Vial : 46 Sample Multiplier: 1 | H20: ALS Vial : 47 Sample Multiplier: 1 | O20: ALS Vial : 48 Sample Multiplier: 1 | V20: ALS Vial : 49 Sample Multiplier: 1 | AC20: ALS Vial : 50 Sample Multiplier: 1 | AJ20: ALS Vial : 51 Sample Multiplier: 1 | AQ20: ALS Vial : 52 Sample Multiplier: 1 | AX20: ALS Vial : 53 Sample Multiplier: 1 | BE20: ALS Vial : 54 Sample Multiplier: 1 | BL20: ALS Vial : 55 Sample Multiplier: 1 | BS20: ALS Vial : 57 Sample Multiplier: 1 | BZ20: ALS Vial : 58 Sample Multiplier: 1
A22: Integration File: events.e | H22: Integration File: events.e | O22: Integration File: events.e | V22: Integration File: events.e | AC22: Integration File: events.e | AJ22: Integration File: events.e | AQ22: Integration File: events.e | AX22: Integration File: events.e | BE22: Integration File: events.e | BL22: Integration File: events.e | BS22: Integration File: events.e | BZ22: Integration File: events.e
A23: Quant Time: Nov 08 09:13:00 2024 | H23: Quant Time: Nov 08 09:13:42 2024 | O23: Quant Time: Nov 08 09:15:39 2024 | V23: Quant Time: Nov 08 09:16:07 2024 | AC23: Quant Time: Nov 08 09:16:32 2024 | AJ23: Quant Time: Nov 08 09:16:58 2024 | AQ23: Quant Time: Nov 08 09:17:26 2024 | AX23: Quant Time: Nov 08 09:17:57 2024 | BE23: Quant Time: Nov 08 09:18:24 2024 | BL23: Quant Time: Nov 08 09:18:59 2024 | BS23: Quant Time: Nov 08 08:04:36 2024 | BZ23: Quant Time: Nov 08 09:19:54 2024
A24: Quant Method : D:\MassHunter\GCMS\1\methods\FAMES_4_10_to_1_split_241031.M | H24: Quant Method : D:\MassHunter\GCMS\1\methods\FAMES_4_10_to_1_split_241031.M | O24: Quant Method : D:\MassHunter\GCMS\1\methods\FAMES_4_10_to_1_split_241031.M | V24: Quant Method : D:\MassHunter\GCMS\1\methods\FAMES_4_10_to_1_split_241031.M | AC24: Quant Method : D:\MassHunter\GCMS\1\methods\FAMES_4_10_to_1_split_241031.M | AJ24: Quant Method : D:\MassHunter\GCMS\1\methods\FAMES_4_10_to_1_split_241031.M | AQ24: Quant Method : D:\MassHunter\GCMS\1\methods\FAMES_4_10_to_1_split_241031.M | AX24: Quant Method : D:\MassHunter\GCMS\1\methods\FAMES_4_10_to_1_split_241031.M | BE24: Quant Method : D:\MassHunter\GCMS\1\methods\FAMES_4_10_to_1_split_241031.M | BL24: Quant Method : D:\MassHunter\GCMS\1\methods\FAMES_4_10_to_1_split_241031.M | BS24: Quant Method : D:\MassHunter\GCMS\1\methods\FAMES_4_10_to_1_split_241031.M | BZ24: Quant Method : D:\MassHunter\GCMS\1\methods\FAMES_4_10_to_1_split_241031.M
... A35: --------------------------------------------------------------------------- | H35: --------------------------------------------------------------------------- | O35: --------------------------------------------------------------------------- | V35: --------------------------------------------------------------------------- | AC35: --------------------------------------------------------------------------- | AJ35: --------------------------------------------------------------------------- | AQ35: --------------------------------------------------------------------------- | AX35: --------------------------------------------------------------------------- | BE35: --------------------------------------------------------------------------- | BL35: --------------------------------------------------------------------------- | BS35: --------------------------------------------------------------------------- | BZ35: ---------------------------------------------------------------------------
A37: Target Compounds | E37: mg/mL | H37: Target Compounds | L37: mg/mL | O37: Target Compounds | S37: mg/mL | V37: Target Compounds | Z37: mg/mL | AC37: Target Compounds | AG37: mg/mL | AJ37: Target Compounds | AN37: mg/mL | AQ37: Target Compounds | AU37: mg/mL | AX37: Target Compounds | BB37: mg/mL | BE37: Target Compounds | BI37: mg/mL | BL37: Target Compounds | BP37: mg/mL | BS37: Target Compounds | BW37: mg/mL | BZ37: Target Compounds | CD37: mg/mL
A38: 1) | B38: C13:0 | C38: 7.942 | D38: 73207602 | E38: 0.848 | H38: 1) | I38: C13:0 | J38: 7.943 | K38: 82043737 | L38: 0.952 | O38: 1) | P38: C13:0 | Q38: 7.941 | R38: 79164066 | S38: 0.918 | V38: 1) | W38: C13:0 | X38: 7.942 | Y38: 73987487 | Z38: 0.857 | AC38: 1) | AD38: C13:0 | AE38: 7.938 | AF38: 85283069 | AG38: 0.991 | AJ38: 1) | AK38: C13:0 | AL38: 7.939 | AM38: 87033580 | AN38: 1.012 | AQ38: 1) | AR38: C13:0 | AS38: 7.938 | AT38: 101830873 | AU38: 1.187 | AX38: 1) | AY38: C13:0 | AZ38: 7.938 | BA38: 76867734 | BB38: 0.891 | BE38: 1) | BF38: C13:0 | BG38: 7.94 | BH38: 71724761 | BI38: 0.83 | BL38: 1) | BM38: C13:0 | BN38: 7.927 | BO38: 63277539 | BP38: 0.73 | BS38: 1) | BT38: C13:0 | BU38: 7.936 | BV38: 82571561 | BW38: 0.959 | BZ38: 1) | CA38: C13:0 | CB38: 7.934 | CC38: 82702778 | CD38: 0.96
A39: 2) | B39: C14:0 | C39: 0 | D39: 0 | E39: N.D. | H39: 2) | I39: C14:0 | J39: 0 | K39: 0 | L39: N.D. | O39: 2) | P39: C14:0 | Q39: 0 | R39: 0 | S39: N.D. | T39: d | V39: 2) | W39: C14:0 | X39: 0 | Y39: 0 | Z39: N.D. | AC39: 2) | AD39: C14:0 | AE39: 0 | AF39: 0 | AG39: N.D. | AH39: d | AJ39: 2) | AK39: C14:0 | AL39: 0 | AM39: 0 | AN39: N.D. | AO39: d | AQ39: 2) | AR39: C14:0 | AS39: 0 | AT39: 0 | AU39: N.D. | AV39: d | AX39: 2) | AY39: C14:0 | AZ39: 0 | BA39: 0 | BB39: N.D. | BC39: d | BE39: 2) | BF39: C14:0 | BG39: 0 | BH39: 0 | BI39: N.D. | BJ39: d | BL39: 2) | BM39: C14:0 | BN39: 0 | BO39: 0 | BP39: N.D. | BQ39: d | BS39: 2) | BT39: C14:0 | BU39: 0 | BV39: 0 | BW39: N.D. | BZ39: 2) | CA39: C14:0 | CB39: 0 | CC39: 0 | CD39: N.D. | CE39: d
A40: 3) | B40: C16:0 | C40: 11.206 | D40: 11784375 | E40: 0.127 | F40: m | H40: 3) | I40: C16:0 | J40: 11.201 | K40: 12911640 | L40: 0.14 | M40: m | O40: 3) | P40: C16:0 | Q40: 11.18 | R40: 21409319 | S40: 0.239 | V40: 3) | W40: C16:0 | X40: 11.198 | Y40: 15680705 | Z40: 0.173 | AC40: 3) | AD40: C16:0 | AE40: 11.159 | AF40: 34320415 | AG40: 0.389 | AJ40: 3) | AK40: C16:0 | AL40: 11.183 | AM40: 20483066 | AN40: 0.228 | AQ40: 3) | AR40: C16:0 | AS40: 11.159 | AT40: 37605894 | AU40: 0.427 | AX40: 3) | AY40: C16:0 | AZ40: 11.162 | BA40: 30506773 | BB40: 0.345 | BE40: 3) | BF40: C16:0 | BG40: 11.139 | BH40: 71994163 | BI40: 0.826 | BL40: 3) | BM40: C16:0 | BN40: 11.138 | BO40: 29296334 | BP40: 0.331 | BS40: 3) | BT40: C16:0 | BU40: 11.13 | BV40: 96580554 | BW40: 1.111 | BZ40: 3) | CA40: C16:0 | CB40: 11.136 | CC40: 51975684 | CD40: 0.594
A41: 4) | B41: C16:1 | C41: 11.614 | D41: 3450060 | E41: 0.036 | F41: m | H41: 4) | I41: C16:1 | J41: 11.615 | K41: 1875453 | L41: 0.018 | M41: m | O41: 4) | P41: C16:1 | Q41: 11.584 | R41: 8250696 | S41: 0.091 | V41: 4) | W41: C16:1 | X41: 11.606 | Y41: 3494171 | Z41: 0.036 | AC41: 4) | AD41: C16:1 | AE41: 11.562 | AF41: 16507966 | AG41: 0.185 | AJ41: 4) | AK41: C16:1 | AL41: 11.586 | AM41: 6750010 | AN41: 0.073 | AQ41: 4) | AR41: C16:1 | AS41: 11.562 | AT41: 17164851 | AU41: 0.192 | AX41: 4) | AY41: C16:1 | AZ41: 11.564 | BA41: 12017832 | BB41: 0.134 | BE41: 4) | BF41: C16:1 | BG41: 11.541 | BH41: 51248684 | BI41: 0.581 | BL41: 4) | BM41: C16:1 | BN41: 11.538 | BO41: 15688928 | BP41: 0.175 | BS41: 4) | BT41: C16:1 | BU41: 11.531 | BV41: 74121318 | BW41: 0.842 | BZ41: 4) | CA41: C16:1 | CB41: 11.537 | CC41: 30332150 | CD41: 0.343
A42: 5) | B42: C18:0 | C42: 14.303 | D42: 6903485 | E42: 0.074 | F42: m | H42: 5) | I42: C18:0 | J42: 14.308 | K42: 8671699 | L42: 0.094 | M42: m | O42: 5) | P42: C18:0 | Q42: 14.263 | R42: 8857305 | S42: 0.096 | V42: 5) | W42: C18:0 | X42: 14.288 | Y42: 8367177 | Z42: 0.091 | AC42: 5) | AD42: C18:0 | AE42: 14.24 | AF42: 10145795 | AG42: 0.111 | AJ42: 5) | AK42: C18:0 | AL42: 14.261 | AM42: 8863956 | AN42: 0.096 | AQ42: 5) | AR42: C18:0 | AS42: 14.241 | AT42: 13412784 | AU42: 0.148 | AX42: 5) | AY42: C18:0 | AZ42: 14.236 | BA42: 10727024 | BB42: 0.117 | BE42: 5) | BF42: C18:0 | BG42: 14.233 | BH42: 25021982 | BI42: 0.278 | BL42: 5) | BM42: C18:0 | BN42: 14.215 | BO42: 14099329 | BP42: 0.155 | BS42: 5) | BT42: C18:0 | BU42: 14.237 | BV42: 34052626 | BW42: 0.380 m | BZ42: 5) | CA42: C18:0 | CB42: 14.23 | CC42: 24651724 | CD42: 0.274
A43: 6) | B43: C18:1 | C43: 14.756 | D43: 11635803 | E43: 0.115 | F43: m | H43: 6) | I43: C18:1 | J43: 14.765 | K43: 8530963 | L43: 0.081 | M43: m | O43: 6) | P43: C18:1 | Q43: 14.723 | R43: 27787826 | S43: 0.297 | V43: 6) | W43: C18:1 | X43: 14.743 | Y43: 12483814 | Z43: 0.125 | AC43: 6) | AD43: C18:1 | AE43: 14.707 | AF43: 61331457 | AG43: 0.674 | AJ43: 6) | AK43: C18:1 | AL43: 14.721 | AM43: 28577064 | AN43: 0.306 | AQ43: 6) | AR43: C18:1 | AS43: 14.711 | AT43: 65808964 | AU43: 0.725 | AX43: 6) | AY43: C18:1 | AZ43: 14.707 | BA43: 64906733 | BB43: 0.715 | BE43: 6) | BF43: C18:1 | BG43: 14.729 | BH43: 232707696 | BI43: 2.602 | BL43: 6) | BM43: C18:1 | BN43: 14.694 | BO43: 112694414 | BP43: 1.252 | BS43: 6) | BT43: C18:1 | BU43: 14.739 | BV43: 347285571 | BW43: 3.89 | BZ43: 6) | CA43: C18:1 | CB43: 14.717 | CC43: 215003461 | CD43: 2.403
A44: 7) | B44: C18:2 | C44: 15.749 | D44: 12140626 | E44: 0.128 | H44: 7) | I44: C18:2 | J44: 15.755 | K44: 7305351 | L44: 0.073 | O44: 7) | P44: C18:2 | Q44: 15.714 | R44: 45451013 | S44: 0.51 | V44: 7) | W44: C18:2 | X44: 15.734 | Y44: 20945459 | Z44: 0.229 | AC44: 7) | AD44: C18:2 | AE44: 15.695 | AF44: 83893622 | AG44: 0.951 | AJ44: 7) | AK44: C18:2 | AL44: 15.707 | AM44: 42694573 | AN44: 0.479 | AQ44: 7) | AR44: C18:2 | AS44: 15.694 | AT44: 54532672 | AU44: 0.614 | AX44: 7) | AY44: C18:2 | AZ44: 15.689 | BA44: 76401867 | BB44: 0.865 | BE44: 7) | BF44: C18:2 | BG44: 15.656 | BH44: 31377456 | BI44: 0.349 | BL44: 7) | BM44: C18:2 | BN44: 15.66 | BO44: 27206035 | BP44: 0.301 | BS44: 7) | BT44: C18:2 | BU44: 15.634 | BV44: 39738411 | BW44: 0.445 | BZ44: 7) | CA44: C18:2 | CB44: 15.651 | CC44: 44238077 | CD44: 0.496
