Workbook

Sheet info
A1: PPI Biostat Run #5.
B3: This biostat run will examine the oscillations vs control conditions.
B4: A seed culture was grown in the sixfors (250 mL, 400 rpm, 1 vvm, pH 5.6, 10% inoculation from YPD) over the weekend.
A7: Initial seed | C7: Culture | D7: OD600 final
C8: 2 mL YPD O/N | D8: 15.6 | E8: 45593
A12: Sixfor seed | F12: #estimated initial OD
B13: Reactor | C13: Description | D13: Volume (no seed) | E13: Volume (w/seed) | F13: OD600 initial$ | G13: OD600 final | H13: pH initial | I13: Time of inoculation | J13: date of Inoculation | K13: RPM control | L13: Aeration Control | M13: pH setpoint | N13: Temp setpoint © | O13: Medium | P13: Species | Q13: file | R13: Note
B14: R1 | C14: seed for Biostat20_2L | D14: 250 mL | E14: 251.5 | F14: =D8*1.5/E14 -> 0.09304175 | G14: 9.26 | I14: 0.69791667 | J14: 45594 | K14: 400 | L14: 1 vvm | M14: 5.6 | N14: 30 | O14: YNB50-CN40 | P14: Ylip (W29) | Q14: PPI_Bst22_seed_R1 | R14: *pH overshot to 6.7 when changed a parameter on pH PID.
B15: R3 | C15: seed for Biostat20_2L | D15: 250 mL | E15: 251.5 | F15: =D8*1.5/E15 -> 0.09304175 | G15: 9.26 | I15: 0.69791667 | J15: 45594 | K15: 400 | L15: 1 vvm | M15: 5.6 | N15: 30 | O15: YNB50-CN40 | P15: Ylip (W29) | Q15: PPI_Bst22_seed_R3 | R15: *combined two reactors for seed OD600 measurement.
A21: Biostat2L
B22: Reactor | C22: Description | D22: Volume (no seed) | E22: Volume (w/seed) | F22: OD600 initial | G22: pH initial | H22: Time of inoculation | I22: date of Inoculation | J22: RPM control | K22: Aeration Control | L22: pH setpoint | M22: Temp setpoint © | N22: Medium | O22: Species | P22: Note
B23: R1 | C23: Control | D23: 1.35 | E23: 1.45 | F23: =0.1*9.26/1.45 -> 0.63862069 | H23: 0.67708333 | I23: 45595 | J23: 400 (0%)-600(50%)-800(100%) | K23: 0.375 (0%)- 0.375 (50%) - 1.5 (100%) | L23: 5.6 | M23: 28 | N23: YNB100-0.5g/LYE-CN100 | O23: Ylp (W29) | P23: Control
B24: R2 | C24: Oscillations | D24: 1.35 | E24: 1.45 | F24: =0.1*9.26/1.45 -> 0.63862069 | H24: 0.67708333 | I24: 45595 | J24: 500 (4 h) - 600 | K24: 0.5 (4 h) - 1.125 | L24: 5.6 | M24: 28 | N24: YNB100-0.5g/LYE-CN100 | O24: Ylp (W29) | P24: Oscillations
G28: Oscillations Controls * Changing O2 to N2
G30: Caculations active: | I30: formula | K30: logic | L30: Notes
H31: count_BDCU2 | I31: count_BDCU2.Value = Shared._MFCSCalcCycle.Value | K31: Variable for counting hours | L31: NOT USED IN control
H32: STIRR_step | I32: STIRR.setpoint = (_BatchAge.Value >= 4) * 600 + (_BatchAge.Value < 4) * 500 | K32: 500 rpm till 4 h, then 600 rpm
H33: AIRSP_A_Oscilate | I33: AIRSP_A_Setpoint = 0.375 * (_BatchAge.Value < 4) + (Count.Value <= 60)*1.125 *(_BatchAge.Value > 4) | K33: 0.375 LPM of air until 4 hour, then 1.125 when Counter is less than 1 min (60 sec)
H34: Counter | I34: Count.Value = (Count.Value+ Shared._MFCSCalcCycle.Value)*(Count.Value < 120) | K34: Counter - counts to 120 sec, then resets to 0
H35: O2SP_A_oscillate | I35: O2SP_A.Setpoint = (Count.Value >60)*1.125 * (_BatchAge.Value >4) | K35: 0 LPM until 4 h, then 1.125 when Counter is greater than 60 sec.

Sheet medium
A1: Medium | AA1: redford ratio
B2: Initial Medium. | AA2: 4.4277894 | AB2: C:N:P
AA3: C/N | AB3: =106/16 -> 6.625
D4: YNB-glucose | P4: molecular weight (m.w., g/mol) | S4: Yeast Nitrogen Base W/out Amino acids and Ammonium Sulfate (product number Y1251) | AA4: C/P | AB4: =106 -> 106
B5: Media | C5: YNB Seeds. | F5: High | G5: low | K5: low | L5: high | O5: Potassium Phosphate monobasic | P5: 136.086 | T5: chrome-extension://efaidnbmnnnibpcajpcglclefindmkaj/https://www.sigmaaldrich.com/deepweb/assets/sigmaaldrich/product/documents/411/890/Y1251dat.pdf | AA5: N/P | AB5: 16
B6: 1 | C6: YNB-glucose-AC | D6: Conc (g/L) | E6: Component | F6: C/N ratio | G6: C/N ratio | H6: C/P ratio* | I6: N/P ratio* | J6: mol C | K6: mol N/L | L6: mol N/L | M6: mol P/L | O6: Ammonium Sulfate | P6: 132.14 | T6: Conc (g/L) | U6: Component | V6: molecular weight (g/mol) | X6: mol/L
C7: =D7*3.2 -> 5.44 | D7: 1.7 | E7: Yeast Nitrogen Base W/out Amino acids and Ammonium Sulfate (product number Y1251) | F7: =J7/K7 -> 100.53919 | G7: =J7/L7 -> 97.389212 | H7: =J7/M7 -> 453.2272 | I7: =K7/M7 -> 4.5079657 | J7: =D9/$P$7*6 -> 3.3304469 | K7: =D8/P$12+D10*F14/100*1/14 -> 0.03312586 | L7: =D8/P$12+D10*G14/100*1/14 -> 0.034197288 | M7: =T7/$P$5 -> 0.0073482945 | O7: Glucose | P7: 180.156 | T7: 1 | U7: Potassium Phosphate monobasic | V7: 136.086
C8: =D8*3.2 -> 5.12 | D8: 1.6 | E8: Ammonium Chloride | O8: Xylose | P8: 150.13 | T8: 0.5 | U8: magnesium sulfate
C9: =D9*3.2 -> 320 | D9: 100 | E9: Glucose | O9: Glycerol | P9: 92.094 | T9: 0.1 | U9: sodium chloride
C10: =D10*3.2 -> 1.6 | D10: 0.5 | E10: Yeast extract | O10: Acetate | P10: 59.044 | T10: 0.1 | U10: calcium chloride
O11: Citric acid | P11: 192.194 | T11: =SUM(T7:T10) -> 1.7 | U11: g/L total
F12: low (%) | G12: high (%) | O12: Ammonium Chloride | P12: 53.491 | T12: Trace elements
E13: Peptone Nitrogen range | F13: 14.2 | G13: 17.4 | O13: urea | P13: 60.06 | T13: Conc (µg/L) | U13: Component
E14: Yeast extract Nitrogen range | F14: 9 | G14: 12 | T14: 500 | U14: Boric acid
T15: 40 | U15: Copper sulfate
T16: 100 | U16: Potassium iodide
T17: 200 | U17: Ferric Chloride
T18: 400 | U18: Manganese sulfate
T19: 200 | U19: Sodium molybdate
T20: 400 | U20: Zinc Sulfate
T21: =SUM(T14:T20)/1000000 -> 0.00184 | U21: g/L total
T22: Vitamins
T23: Conc (µg/L) | U23: Component
T24: 2 | U24: Biotin | X24: =550*0.3 -> 165
T25: 400 | U25: Calcium pantothenate
T26: 2 | U26: Folic acid
T27: 2000 | U27: Inositol
T28: 400 | U28: Niacin
T29: 200 | U29: p-Aminobeznoic acid
T30: 400 | U30: Pyridoxine hydrochloride
T31: 200 | U31: Riboflavin
T32: 400 | U32: Thiamine hydrochloride
T35: =SUM(T24:T32)/1000000 -> 0.004004 | U35: g/L total
P48: to add
P49: =D7*1.5 -> 2.55
P50: =D8*1.5 -> 2.4
P51: =D9*1.5 -> 150
P52: =D10*1.5 -> 0.75
C54: 2 | D54: YNB-glucose-AC | E54: Conc (g/L) | F54: Component | G54: C/N ratio | H54: C/P ratio* | I54: N/P ratio* | J54: mol C | K54: mol N/L | L54: mol P/L
E55: 1.7 | F55: Yeast Nitrogen Base W/out Amino acids and Ammonium Sulfate (product number Y1251) | G55: =J55/K55 -> 60.594877 | H55: =J55/L55 -> 226.6136 | I55: =K55/L55 -> 3.7398145 | J55: =E57/$P$7*6 -> 1.6652235 | K55: =E56/P$12 -> 0.027481259 | L55: =T7/$P$5 -> 0.0073482945
...

Sheet vessel setup
A1: Agitation Propellers.
B2: Adjusted propellers to account for feeding of liquid into the medium.
B4: 2 cm from bottom for bottom impeller
B5: 4 cm from bottom impeller for top impeller

Sheet history_

Sheet metadata
B4: Strain | C4: inoculation | D4: initial working volume (L) | E4: Temperature (C ) | F4: Agitation | G4: Aeration | H4: Initial medium | I4: feed

Sheet data
V12: moxiflow | Y12: DCW | AO12: rate | BD12: Results in g/L | BQ12: Calculations
A13: # | B13: SampleName | C13: Trehalose | D13: Citric Acid | E13: Glucose | F13: Xylose | G13: Erythritol | H13: Lactic Acid | I13: Glycerol | J13: Acetic Acid | K13: Ethanol | L13: Oxalic Acid | M13: Succinic Acid | N13: Fumaric | P13: date | Q13: time | R13: hour | S13: reactor | T13: sample number | U13: sample volume (mL) | V13: moxiflow D (µm) | W13: OD600 | X13: BASE (mL) | Y13: pre | Z13: post | AA13: volume | AB13: weight (g) | AC13: DCW (g/L) | AD13: FAME bio weight (mg) | AE13: FAME (mg) | AF13: FAME yield (g/g biomass) | AG13: FAME titer (g/L) | AI13: sugar consumed | AJ13: citrate rate | AK13: citrate yield | AL13: biomass rate | AM13: biomass yield | AN13: Fame rate (g/L/h) | AO13: FAME yield (g/g substrate) | AP13: specific sugar consumed (g/L) | AQ13: specific sugar consumed (g/L/h) | AR13: specific biomass rate (g/L/h) | AS13: specific biomass yield (g/g substrate) | AT13: specific citrate rate (g/L/h) | AU13: specific citrate yield (g/g substrate) | AV13: specific Fame (g/L/h) | AW13: total yields (g/g substrate) | BD13: Trehalose | BE13: Citric Acid | BF13: Glucose | BG13: Xylose | BH13: Erythritol | BI13: Lactic Acid | BJ13: Glycerol | BK13: Acetic Acid | BL13: Ethanol | BM13: Oxalic Acid | BN13: Succinic Acid | BO13: Fumaric Acid | BP13: date | BQ13: BLANK | BU13: Citrate (g/L) | BV13: estimated titer with evaporation | BW13: total sugar (g/L) | BX13: equivilant titer (g/L) | BY13: sugar consumed (g/L) | CA13: sugar consumption rates (g/L/h) | CB13: sugar consumed / timepoint | CC13: specific sugar consumption rate (g/L/h) | CD13: specifc biomass formation | CE13: biomass yield
B14: Jeff_SloHot50_Biostat 2L-22-1 | E14: 9.94374 | P14: 45595 | Q14: 0.70833333 | R14: 0.75 | S14: r1 | T14: 1 | V14: - | Y14: 6.7347 | Z14: 6.7367 | AA14: 8 | AB14: 0.002 | AC14: 0.25 | AD14: 2.5 | AE14: =FAMES!N15 -> 0.234 | AF14: =AE14/AD14 -> 0.0936 | AG14: =AF14*AC14 -> 0.0234 | AI14: =$BF$14-BF14 -> 0 | AJ14: =BE14/R14 -> 0 | AK14: =BE14/AI14 -> #DIV/0! | AL14: =AC14/R14 -> 0.33333333 | AM14: =AC14/AI14 -> #DIV/0! | AO14: =AG14/AI14 -> #DIV/0! | BD14: =IF(ISNUMBER(C14),C14*1000/100,"") | BE14: =IF(ISNUMBER(D14),D14*1000/100,0) -> 0 | BF14: =IF(ISNUMBER(E14),E14*1000/100,"") -> 99.4374 | BG14: =IF(ISNUMBER(F14),F14*1000/100,"") | BH14: =IF(ISNUMBER(G14),G14*1000/100,"") | BI14: =IF(ISNUMBER(H14),H14*1000/100,"") | BJ14: =IF(ISNUMBER(I14),I14*1000/100,"") | BK14: =IF(ISNUMBER(J14),J14*1000/100,"") | BL14: =IF(ISNUMBER(K14),K14*1000/100,"") | BM14: =IF(ISNUMBER(L14),L14*1000/100,"") | ... BO14: =IF(ISNUMBER(N14),N14*1000/100,"") | BQ14: =S14 -> r1 | BS14: =B14 -> Jeff_SloHot50_Biostat 2L-22-1 | BU14: =BE14 -> 0 | BY14: =$BF$14-BF14 -> 0 | CA14: =BY14/R14 -> 0
B15: Jeff_SloHot50_Biostat 2L-22-2 | E15: 9.93931 | P15: 45595 | Q15: 0.70833333 | R15: 0.75 | S15: r2 | T15: 2 | V15: - | Y15: 6.7378 | Z15: 6.7417 | AA15: 8 | AB15: 0.0039 | AC15: 0.4875 | AD15: 1.5 | AE15: =FAMES!N16 -> 0.1525 | AF15: =AE15/AD15 -> 0.10166667 | AG15: =AF15*AC15 -> 0.0495625 | AI15: =$BF$15-BF15 -> 0 | AJ15: =BE15/R15 -> 0 | AK15: =BE15/AI15 -> #DIV/0! | AL15: =AC15/R15 -> 0.65 | AM15: =AC15/AI15 -> #DIV/0! | AO15: =AG15/AI15 -> #DIV/0! | BD15: =IF(ISNUMBER(C15),C15*1000/100,"") | BE15: =IF(ISNUMBER(D15),D15*1000/100,0) -> 0 | BF15: =IF(ISNUMBER(E15),E15*1000/100,"") -> 99.3931 | BG15: =IF(ISNUMBER(F15),F15*1000/100,"") | BH15: =IF(ISNUMBER(G15),G15*1000/100,"") | BI15: =IF(ISNUMBER(H15),H15*1000/100,"") | BJ15: =IF(ISNUMBER(I15),I15*1000/100,"") | BK15: =IF(ISNUMBER(J15),J15*1000/100,"") | BL15: =IF(ISNUMBER(K15),K15*1000/100,"") | BM15: =IF(ISNUMBER(L15),L15*1000/100,"") | ... BO15: =IF(ISNUMBER(N15),N15*1000/100,"") | BQ15: =S15 -> r2 | BS15: =B15 -> Jeff_SloHot50_Biostat 2L-22-2 | BU15: =BE15 -> 0 | BY15: =$BF$15-BF15 -> 0 | CA15: =BY15/R15 -> 0
B16: Jeff_SloHot50_Biostat 2L-22-3 | C16: 0.01585 | E16: 8.9716 | P16: 45596 | Q16: 0.35416667 | R16: =R14+12+3.5 -> 16.25 | S16: r1 | T16: 3 | V16: - | W16: 7.91 | X16: 28 | Y16: 6.7126 | Z16: 6.7543 | AA16: 8 | AB16: 0.0417 | AC16: 5.2125 | AD16: 13.5 | AE16: =FAMES!N17 -> 0.8145 | AF16: =AE16/AD16 -> 0.060333333 | AG16: =AF16*AC16 -> 0.3144875 | AI16: =$BF$14-BF16 -> 9.7214 | AJ16: =BE16/R16 -> 0 | AK16: =BE16/AI16 -> 0 | AL16: =AC16/R16 -> 0.32076923 | AM16: =AC16/AI16 -> 0.5361882 | AN16: =AG16/R16 -> 0.019353077 | AO16: =AG16/AI16 -> 0.032350022 | AP16: =BF14-BF16 -> 9.7214 | AQ16: =AP16/(R16-R14) -> 0.6271871 | AR16: =(AC16-AC14)/(AI16-AI14) -> 0.51047174 | AS16: =AR16/AQ16 -> 0.81390664 | AT16: =(BE16-BE14)/(AI16-AI14) -> 0 | AU16: =AT16/AP16 -> 0 | AW16: =AK16+AM16 -> 0.5361882 | BD16: =IF(ISNUMBER(C16),C16*1000/100,"") -> 0.1585 | BE16: =IF(ISNUMBER(D16),D16*1000/100,0) -> 0 | BF16: =IF(ISNUMBER(E16),E16*1000/100,"") -> 89.716 | BG16: =IF(ISNUMBER(F16),F16*1000/100,"") | BH16: =IF(ISNUMBER(G16),G16*1000/100,"") | BI16: =IF(ISNUMBER(H16),H16*1000/100,"") | BJ16: =IF(ISNUMBER(I16),I16*1000/100,"") | BK16: =IF(ISNUMBER(J16),J16*1000/100,"") | BL16: =IF(ISNUMBER(K16),K16*1000/100,"") | BM16: =IF(ISNUMBER(L16),L16*1000/100,"") | ... BO16: =IF(ISNUMBER(N16),N16*1000/100,"") | BQ16: =S16 -> r1 | BS16: =B16 -> Jeff_SloHot50_Biostat 2L-22-3 | BU16: =BE16 -> 0 | BY16: =$BF$14-BF16 -> 9.7214 | CA16: =BY16/R16 -> 0.59824 | CB16: =BY16-BY14 -> 9.7214 | CC16: =CB16/(R16-R14) -> 0.6271871 | CD16: =AC16-AC14 -> 4.9625 | CE16: =CD16/CB16 -> 0.51047174
B17: Jeff_SloHot50_Biostat 2L-22-4 | C17: 0.00925 | E17: 9.86148 | R17: =R15+12+3.5 -> 16.25 | S17: r2 | T17: 4 | V17: - | W17: 1.24 | X17: 4 | Y17: 6.6825 | Z17: 6.6884 | AA17: 8 | AB17: 0.0059 | AC17: 0.7375 | AD17: 1.7 | AE17: =FAMES!N18 -> 0.203 | AF17: =AE17/AD17 -> 0.11941176 | AG17: =AF17*AC17 -> 0.088066176 | AI17: =$BF$15-BF17 -> 0.7783 | AJ17: =BE17/R17 -> 0 | AK17: =BE17/AI17 -> 0 | AL17: =AC17/R17 -> 0.045384615 | AM17: =AC17/AI17 -> 0.94757805 | AN17: =AG17/R17 -> 0.005419457 | AO17: =AG17/AI17 -> 0.11315197 | AP17: =BF15-BF17 -> 0.7783 | AQ17: =AP17/(R17-R15) -> 0.050212903 | AR17: =(AC17-AC15)/(AI17-AI15) -> 0.3212129 | AS17: =AR17/AQ17 -> 6.3970191 | AT17: =(BE17-BE15)/(AI17-AI15) -> 0 | AU17: =AT17/AP17 -> 0 | AW17: =AK17+AM17 -> 0.94757805 | BD17: =IF(ISNUMBER(C17),C17*1000/100,"") -> 0.0925 | BE17: =IF(ISNUMBER(D17),D17*1000/100,0) -> 0 | BF17: =IF(ISNUMBER(E17),E17*1000/100,"") -> 98.6148 | BG17: =IF(ISNUMBER(F17),F17*1000/100,"") | BH17: =IF(ISNUMBER(G17),G17*1000/100,"") | BI17: =IF(ISNUMBER(H17),H17*1000/100,"") | BJ17: =IF(ISNUMBER(I17),I17*1000/100,"") | BK17: =IF(ISNUMBER(J17),J17*1000/100,"") | BL17: =IF(ISNUMBER(K17),K17*1000/100,"") | BM17: =IF(ISNUMBER(L17),L17*1000/100,"") | ... BO17: =IF(ISNUMBER(N17),N17*1000/100,"") | BQ17: =S17 -> r2 | BS17: =B17 -> Jeff_SloHot50_Biostat 2L-22-4 | BU17: =BE17 -> 0 | BY17: =$BF$15-BF17 -> 0.7783 | CA17: =BY17/R17 -> 0.047895385 | CB17: =BY17-BY15 -> 0.7783 | CC17: =CB17/(R17-R15) -> 0.050212903 | CD17: =AC17-AC15 -> 0.25 | CE17: =CD17/CB17 -> 0.3212129
B18: Jeff_SloHot50_Biostat 2L-22-5 | C18: 0.02782 | D18: 0.025 | E18: 8.66793 | Q18: 0.53125 | R18: =R17+4+0.25 -> 20.5 | S18: r1 | T18: 5 | V18: - | W18: 13.24 | X18: 29 | Y18: 6.7449 | Z18: 6.8002 | AA18: 8 | AB18: 0.0553 | AC18: 6.9125 | AD18: 12.3 | AE18: =FAMES!N19 -> 0.8185 | AF18: =AE18/AD18 -> 0.066544715 | AG18: =AF18*AC18 -> 0.45999035 | AI18: =$BF$14-BF18 -> 12.7581 | AJ18: =BE18/R18 -> 0.012195122 | AK18: =BE18/AI18 -> 0.019595394 | AL18: =AC18/R18 -> 0.33719512 | AM18: =AC18/AI18 -> 0.54181265 | AN18: =AG18/R18 -> 0.022438553 | AO18: =AG18/AI18 -> 0.036054769 | AP18: =BF16-BF18 -> 3.0367 | AQ18: =AP18/(R18-R16) -> 0.71451765 | AR18: =(AC18-AC16)/(AI18-AI16) -> 0.55981822 | AS18: =AR18/AQ18 -> 0.78349111 | AT18: =(BE18-BE16)/(AI18-AI16) -> 0.082326209 | AU18: =AT18/AP18 -> 0.027110419 | AW18: =AK18+AM18 -> 0.56140805 | BD18: =IF(ISNUMBER(C18),C18*1000/100,"") -> 0.2782 | BE18: =IF(ISNUMBER(D18),D18*1000/100,0) -> 0.25 | BF18: =IF(ISNUMBER(E18),E18*1000/100,"") -> 86.6793 | BG18: =IF(ISNUMBER(F18),F18*1000/100,"") | BH18: =IF(ISNUMBER(G18),G18*1000/100,"") | BI18: =IF(ISNUMBER(H18),H18*1000/100,"") | BJ18: =IF(ISNUMBER(I18),I18*1000/100,"") | BK18: =IF(ISNUMBER(J18),J18*1000/100,"") | BL18: =IF(ISNUMBER(K18),K18*1000/100,"") | BM18: =IF(ISNUMBER(L18),L18*1000/100,"") | ... BO18: =IF(ISNUMBER(N18),N18*1000/100,"") | BQ18: =S18 -> r1 | BS18: =B18 -> Jeff_SloHot50_Biostat 2L-22-5 | BU18: =BE18 -> 0.25 | BY18: =$BF$14-BF18 -> 12.7581 | CA18: =BY18/R18 -> 0.62234634 | CB18: =BY18-BY16 -> 3.0367 | CC18: =CB18/(R18-R16) -> 0.71451765
B19: Jeff_SloHot50_Biostat 2L-22-6 | C19: 0.01326 | E19: 9.69598 | R19: =R18 -> 20.5 | S19: r2 | T19: 6 | V19: - | W19: 2.08 | X19: 9 | Y19: 6.6885 | Z19: 6.7029 | AA19: 8 | AB19: 0.0144 | AC19: 1.8 | AD19: 5.6 | AE19: =FAMES!N20 -> 0.297 | AF19: =AE19/AD19 -> 0.053035714 | AG19: =AF19*AC19 -> 0.095464286 | AI19: =$BF$15-BF19 -> 2.4333 | AJ19: =BE19/R19 -> 0 | AK19: =BE19/AI19 -> 0 | AL19: =AC19/R19 -> 0.087804878 | AM19: =AC19/AI19 -> 0.73973616 | AN19: =AG19/R19 -> 0.0046567944 | AO19: =AG19/AI19 -> 0.039232436 | AP19: =BF17-BF19 -> 1.655 | AQ19: =AP19/(R19-R17) -> 0.38941176 | AR19: =(AC19-AC17)/(AI19-AI17) -> 0.64199396 | AS19: =AR19/AQ19 -> 1.648625 | AT19: =(BE19-BE17)/(AI19-AI17) -> 0 | AU19: =AT19/AP19 -> 0 | AW19: =AK19+AM19 -> 0.73973616 | BD19: =IF(ISNUMBER(C19),C19*1000/100,"") -> 0.1326 | BE19: =IF(ISNUMBER(D19),D19*1000/100,0) -> 0 | BF19: =IF(ISNUMBER(E19),E19*1000/100,"") -> 96.9598 | BG19: =IF(ISNUMBER(F19),F19*1000/100,"") | BH19: =IF(ISNUMBER(G19),G19*1000/100,"") | BI19: =IF(ISNUMBER(H19),H19*1000/100,"") | BJ19: =IF(ISNUMBER(I19),I19*1000/100,"") | BK19: =IF(ISNUMBER(J19),J19*1000/100,"") | BL19: =IF(ISNUMBER(K19),K19*1000/100,"") | BM19: =IF(ISNUMBER(L19),L19*1000/100,"") | ... BO19: =IF(ISNUMBER(N19),N19*1000/100,"") | BQ19: =S19 -> r2 | BS19: =B19 -> Jeff_SloHot50_Biostat 2L-22-6 | BU19: =BE19 -> 0 | BY19: =$BF$15-BF19 -> 2.4333 | CA19: =BY19/R19 -> 0.11869756 | CB19: =BY19-BY17 -> 1.655 | CC19: =CB19/(R19-R17) -> 0.38941176
B20: Jeff_SloHot50_Biostat 2L-22-7 | C20: 0.0279 | D20: 0.12189 | E20: 8.25176 | Q20: 0.75 | R20: =R18+5+0.25 -> 25.75 | S20: r1 | T20: 7 | V20: - | W20: 17.68 | X20: 33 | Y20: 6.7062 | Z20: 6.7798 | AA20: 8 | AB20: 0.0736 | AC20: 9.2 | AD20: 13.7 | AE20: =FAMES!N21 -> 1.0755 | AF20: =AE20/AD20 -> 0.07850365 | AG20: =AF20*AC20 -> 0.72223358 | AI20: =$BF$14-BF20 -> 16.9198 | AJ20: =BE20/R20 -> 0.047335922 | AK20: =BE20/AI20 -> 0.072039859 | AL20: =AC20/R20 -> 0.35728155 | AM20: =AC20/AI20 -> 0.54374165 | AN20: =AG20/R20 -> 0.028047906 | AO20: =AG20/AI20 -> 0.042685704 | AP20: =BF18-BF20 -> 4.1617 | AQ20: =AP20/(R20-R18) -> 0.79270476 | AR20: =(AC20-AC18)/(AI20-AI18) -> 0.54965519 | AS20: =AR20/AQ20 -> 0.69339206 | AT20: =(BE20-BE18)/(AI20-AI18) -> 0.23281351 | AU20: =AT20/AP20 -> 0.055941926 | AW20: =AK20+AM20 -> 0.61578151 | BD20: =IF(ISNUMBER(C20),C20*1000/100,"") -> 0.279 | BE20: =IF(ISNUMBER(D20),D20*1000/100,0) -> 1.2189 | BF20: =IF(ISNUMBER(E20),E20*1000/100,"") -> 82.5176 | BG20: =IF(ISNUMBER(F20),F20*1000/100,"") | BH20: =IF(ISNUMBER(G20),G20*1000/100,"") | BI20: =IF(ISNUMBER(H20),H20*1000/100,"") | BJ20: =IF(ISNUMBER(I20),I20*1000/100,"") | BK20: =IF(ISNUMBER(J20),J20*1000/100,"") | BL20: =IF(ISNUMBER(K20),K20*1000/100,"") | BM20: =IF(ISNUMBER(L20),L20*1000/100,"") | ... BO20: =IF(ISNUMBER(N20),N20*1000/100,"") | BQ20: =S20 -> r1 | BS20: =B20 -> Jeff_SloHot50_Biostat 2L-22-7 | BU20: =BE20 -> 1.2189 | BY20: =$BF$14-BF20 -> 16.9198 | CA20: =BY20/R20 -> 0.65707961 | CB20: =BY20-BY18 -> 4.1617 | CC20: =CB20/(R20-R18) -> 0.79270476
B21: Jeff_SloHot50_Biostat 2L-22-8 | C21: 0.02085 | E21: 9.45292 | R21: =R19+5+0.25 -> 25.75 | S21: r2 | T21: 8 | V21: - | W21: 5.8 | X21: 12 | Y21: 6.6623 | Z21: 6.6954 | AA21: 8 | AB21: 0.0331 | AC21: 4.1375 | AD21: 19.1 | AE21: =FAMES!N22 -> 0.8685 | AF21: =AE21/AD21 -> 0.045471204 | AG21: =AF21*AC21 -> 0.18813711 | AI21: =$BF$15-BF21 -> 4.8639 | AJ21: =BE21/R21 -> 0 | AK21: =BE21/AI21 -> 0 | AL21: =AC21/R21 -> 0.16067961 | AM21: =AC21/AI21 -> 0.85065482 | AN21: =AG21/R21 -> 0.0073062954 | AO21: =AG21/AI21 -> 0.038680299 | AP21: =BF19-BF21 -> 2.4306 | AQ21: =AP21/(R21-R19) -> 0.46297143 | AR21: =(AC21-AC19)/(AI21-AI19) -> 0.9616967 | AS21: =AR21/AQ21 -> 2.0772269 | AT21: =(BE21-BE19)/(AI21-AI19) -> 0 | AU21: =AT21/AP21 -> 0 | AW21: =AK21+AM21 -> 0.85065482 | BD21: =IF(ISNUMBER(C21),C21*1000/100,"") -> 0.2085 | BE21: =IF(ISNUMBER(D21),D21*1000/100,0) -> 0 | BF21: =IF(ISNUMBER(E21),E21*1000/100,"") -> 94.5292 | BG21: =IF(ISNUMBER(F21),F21*1000/100,"") | BH21: =IF(ISNUMBER(G21),G21*1000/100,"") | BI21: =IF(ISNUMBER(H21),H21*1000/100,"") | BJ21: =IF(ISNUMBER(I21),I21*1000/100,"") | BK21: =IF(ISNUMBER(J21),J21*1000/100,"") | BL21: =IF(ISNUMBER(K21),K21*1000/100,"") | BM21: =IF(ISNUMBER(L21),L21*1000/100,"") | ... BO21: =IF(ISNUMBER(N21),N21*1000/100,"") | BQ21: =S21 -> r2 | BS21: =B21 -> Jeff_SloHot50_Biostat 2L-22-8 | BU21: =BE21 -> 0 | BY21: =$BF$15-BF21 -> 4.8639 | CA21: =BY21/R21 -> 0.18888932 | CB21: =BY21-BY19 -> 2.4306 | CC21: =CB21/(R21-R19) -> 0.46297143
B22: Jeff_SloHot50_Biostat 2L-22-9 | C22: 0.02996 | D22: 0.55422 | E22: 7.35477 | P22: 45597 | Q22: 0.3125 | R22: =R20+12+1.5 -> 39.25 | S22: r1 | T22: 9 | V22: - | W22: 23.88 | X22: 49 | Y22: 7.1312 | Z22: 7.2228 | AA22: 8 | AB22: 0.0916 | AC22: 11.45 | AD22: 17.7 | AE22: =FAMES!N23 -> 2.1605 | AF22: =AE22/AD22 -> 0.12206215 | AG22: =AF22*AC22 -> 1.3976116 | AI22: =$BF$14-BF22 -> 25.8897 | AJ22: =BE22/R22 -> 0.14120255 | AK22: =BE22/AI22 -> 0.21406969 | AL22: =AC22/R22 -> 0.29171975 | AM22: =AC22/AI22 -> 0.44226082 | AN22: =AG22/R22 -> 0.035607938 | AO22: =AG22/AI22 -> 0.053983305 | AP22: =BF20-BF22 -> 8.9699 | AQ22: =AP22/(R22-R20) -> 0.66443704 | AR22: =(AC22-AC20)/(AI22-AI20) -> 0.25083892 | AS22: =AR22/AQ22 -> 0.37752097 | AT22: =(BE22-BE20)/(AI22-AI20) -> 0.48197862 | AU22: =AT22/AP22 -> 0.053732886 | AW22: =AK22+AM22 -> 0.65633051 | BD22: =IF(ISNUMBER(C22),C22*1000/100,"") -> 0.2996 | BE22: =IF(ISNUMBER(D22),D22*1000/100,0) -> 5.5422 | BF22: =IF(ISNUMBER(E22),E22*1000/100,"") -> 73.5477 | BG22: =IF(ISNUMBER(F22),F22*1000/100,"") | BH22: =IF(ISNUMBER(G22),G22*1000/100,"") | BI22: =IF(ISNUMBER(H22),H22*1000/100,"") | BJ22: =IF(ISNUMBER(I22),I22*1000/100,"") | BK22: =IF(ISNUMBER(J22),J22*1000/100,"") | BL22: =IF(ISNUMBER(K22),K22*1000/100,"") | BM22: =IF(ISNUMBER(L22),L22*1000/100,"") | ... BO22: =IF(ISNUMBER(N22),N22*1000/100,"") | BQ22: =S24 -> r1 | BS22: =B22 -> Jeff_SloHot50_Biostat 2L-22-9 | BU22: =BE22 -> 5.5422 | BY22: =$BF$14-BF22 -> 25.8897 | CA22: =BY22/R24 -> 0.54504632 | CB22: =BY22-BY20 -> 8.9699 | CC22: =CB22/(R24-R20) -> 0.4124092 | CD22: =AC22-AC16 -> 6.2375 | CE22: =CD22/CB22 -> 0.69538122
B23: Jeff_SloHot50_Biostat 2L-22-10 | C23: 0.02787 | D23: 0.03014 | E23: 8.53307 | R23: =R21+12+1.5 -> 39.25 | S23: r2 | T23: 10 | V23: - | W23: 10.82 | X23: 18 | Y23: 7.1579 | Z23: 7.2158 | AA23: 8 | AB23: 0.0579 | AC23: 7.2375 | AD23: 13.8 | AE23: =FAMES!N24 -> 1.214 | AF23: =AE23/AD23 -> 0.087971014 | AG23: =AF23*AC23 -> 0.63669022 | AI23: =$BF$15-BF23 -> 14.0624 | AJ23: =BE23/R23 -> 0.0076789809 | AK23: =BE23/AI23 -> 0.021433041 | AL23: =AC23/R23 -> 0.1843949 | AM23: =AC23/AI23 -> 0.51467033 | AN23: =AG23/R23 -> 0.016221407 | AO23: =AG23/AI23 -> 0.045276071 | AP23: =BF21-BF23 -> 9.1985 | AQ23: =AP23/(R23-R21) -> 0.68137037 | AR23: =(AC23-AC21)/(AI23-AI21) -> 0.33701147 | AS23: =AR23/AQ23 -> 0.49460834 | AT23: =(BE23-BE21)/(AI23-AI21) -> 0.032766212 | AU23: =AT23/AP23 -> 0.0035621256 | AW23: =AK23+AM23 -> 0.53610337 | BD23: =IF(ISNUMBER(C23),C23*1000/100,"") -> 0.2787 | BE23: =IF(ISNUMBER(D23),D23*1000/100,0) -> 0.3014 | BF23: =IF(ISNUMBER(E23),E23*1000/100,"") -> 85.3307 | BG23: =IF(ISNUMBER(F23),F23*1000/100,"") | BH23: =IF(ISNUMBER(G23),G23*1000/100,"") | BI23: =IF(ISNUMBER(H23),H23*1000/100,"") | BJ23: =IF(ISNUMBER(I23),I23*1000/100,"") | BK23: =IF(ISNUMBER(J23),J23*1000/100,"") | BL23: =IF(ISNUMBER(K23),K23*1000/100,"") | BM23: =IF(ISNUMBER(L23),L23*1000/100,"") | ... BO23: =IF(ISNUMBER(N23),N23*1000/100,"") | BQ23: =S25 -> r2 | BS23: =B23 -> Jeff_SloHot50_Biostat 2L-22-10 | BU23: =BE23 -> 0.3014 | BY23: =$BF$15-BF23 -> 14.0624 | CA23: =BY23/R25 -> 0.29605053 | CB23: =BY23-BY21 -> 9.1985 | CC23: =CB23/(R25-R21) -> 0.42291954 | CD23: =AC23-AC17 -> 6.5 | CE23: =CD23/CB23 -> 0.70663695
B24: Jeff_SloHot50_Biostat 2L-22-11 | C24: 0.03128 | D24: 0.81966 | E24: 6.88848 | Q24: 0.65625 | R24: =R22+5+3.25 -> 47.5 | S24: r1 | T24: 11 | V24: - | W24: 24 | X24: 58 | Y24: 7.1309 | Z24: 7.2214 | AA24: 8 | AB24: 0.0905 | AC24: 11.3125 | AD24: 18 | AE24: =FAMES!N25 -> 2.0115 | AF24: =AE24/AD24 -> 0.11175 | AG24: =AF24*AC24 -> 1.2641719 | AI24: =$BF$14-BF24 -> 30.5526 | AJ24: =BE24/R24 -> 0.17256 | AK24: =BE24/AI24 -> 0.26827831 | AL24: =AC24/R24 -> 0.23815789 | AM24: =AC24/AI24 -> 0.37026309 | AN24: =AG24/R24 -> 0.026614145 | AO24: =AG24/AI24 -> 0.0413769 | AP24: =BF22-BF24 -> 4.6629 | AQ24: =AP24/(R24-R22) -> 0.5652 | AR24: =(AC24-AC22)/(AI24-AI22) -> -0.029488087 | AS24: =AR24/AQ24 -> -0.052172836 | AT24: =(BE24-BE22)/(AI24-AI22) -> 0.56925947 | AU24: =AT24/AP24 -> 0.12208271 | AW24: =AK24+AM24 -> 0.6385414 | BD24: =IF(ISNUMBER(C24),C24*1000/100,"") -> 0.3128 | BE24: =IF(ISNUMBER(D24),D24*1000/100,0) -> 8.1966 | BF24: =IF(ISNUMBER(E24),E24*1000/100,"") -> 68.8848 | BG24: =IF(ISNUMBER(F24),F24*1000/100,"") | BH24: =IF(ISNUMBER(G24),G24*1000/100,"") | BI24: =IF(ISNUMBER(H24),H24*1000/100,"") | BJ24: =IF(ISNUMBER(I24),I24*1000/100,"") | BK24: =IF(ISNUMBER(J24),J24*1000/100,"") | BL24: =IF(ISNUMBER(K24),K24*1000/100,"") | BM24: =IF(ISNUMBER(L24),L24*1000/100,"") | ... BO24: =IF(ISNUMBER(N24),N24*1000/100,"") | BQ24: =S26 -> r1 | BS24: =B24 -> Jeff_SloHot50_Biostat 2L-22-11 | BU24: =BE24 -> 8.1966 | BY24: =$BF$14-BF24 -> 30.5526 | CA24: =BY24/R26 -> 0.48114331 | CB24: =BY24-BY22 -> 4.6629 | CC24: =CB24/(R26-R24) -> 0.29143125
B25: Jeff_SloHot50_Biostat 2L-22-12 | C25: 0.02866 | D25: 0.14153 | E25: 8.0579 | R25: =R23+5+3.25 -> 47.5 | S25: r2 | T25: 12 | V25: - | W25: 16.26 | X25: 22 | Y25: 7.1527 | Z25: 7.2238 | AA25: 8 | AB25: 0.0711 | AC25: 8.8875 | AD25: 17.7 | AE25: =FAMES!N26 -> 1.5075 | AF25: =AE25/AD25 -> 0.085169492 | AG25: =AF25*AC25 -> 0.75694386 | AI25: =$BF$15-BF25 -> 18.8141 | AJ25: =BE25/R25 -> 0.029795789 | AK25: =BE25/AI25 -> 0.075225496 | AL25: =AC25/R25 -> 0.18710526 | AM25: =AC25/AI25 -> 0.47238507 | AN25: =AG25/R25 -> 0.01593566 | AO25: =AG25/AI25 -> 0.040232796 | AP25: =BF23-BF25 -> 4.7517 | AQ25: =AP25/(R25-R23) -> 0.57596364 | AR25: =(AC25-AC23)/(AI25-AI23) -> 0.34724414 | AS25: =AR25/AQ25 -> 0.60289248 | AT25: =(BE25-BE23)/(AI25-AI23) -> 0.23442136 | AU25: =AT25/AP25 -> 0.04933421 | AW25: =AK25+AM25 -> 0.54761057 | BD25: =IF(ISNUMBER(C25),C25*1000/100,"") -> 0.2866 | BE25: =IF(ISNUMBER(D25),D25*1000/100,0) -> 1.4153 | BF25: =IF(ISNUMBER(E25),E25*1000/100,"") -> 80.579 | BG25: =IF(ISNUMBER(F25),F25*1000/100,"") | BH25: =IF(ISNUMBER(G25),G25*1000/100,"") | BI25: =IF(ISNUMBER(H25),H25*1000/100,"") | BJ25: =IF(ISNUMBER(I25),I25*1000/100,"") | BK25: =IF(ISNUMBER(J25),J25*1000/100,"") | BL25: =IF(ISNUMBER(K25),K25*1000/100,"") | BM25: =IF(ISNUMBER(L25),L25*1000/100,"") | ... BO25: =IF(ISNUMBER(N25),N25*1000/100,"") | BQ25: =S27 -> r2 | BS25: =B25 -> Jeff_SloHot50_Biostat 2L-22-12 | BU25: =BE25 -> 1.4153 | BY25: =$BF$15-BF25 -> 18.8141 | CA25: =BY25/R27 -> 0.29628504 | CB25: =BY25-BY23 -> 4.7517 | CC25: =CB25/(R27-R25) -> 0.29698125
B26: Jeff_SloHot50_Biostat 2L-22-13 | C26: 0.03656 | D26: 1.34696 | E26: 5.97274 | P26: 45598 | Q26: 0.32291667 | R26: =R24+12+4 -> 63.5 | S26: r1 | T26: 13 | V26: - | W26: 25.36 | X26: 77 | Y26: 7.1221 | Z26: 7.2319 | AA26: 8 | AB26: =Z26-Y26 -> 0.1098 | AC26: =AB26/(AA26/1000) -> 13.725 | AD26: 17.5 | AE26: =FAMES!N27 -> 2.8355 | AF26: =AE26/AD26 -> 0.16202857 | AG26: =AF26*AC26 -> 2.2238421 | AI26: =$BF$14-BF26 -> 39.71 | AJ26: =BE26/R26 -> 0.21211969 | AK26: =BE26/AI26 -> 0.33919919 | AL26: =AC26/R26 -> 0.21614173 | AM26: =AC26/AI26 -> 0.34563082 | AN26: =AG26/R26 -> 0.035021136 | AO26: =AG26/AI26 -> 0.056002069 | AP26: =BF24-BF26 -> 9.1574 | AQ26: =AP26/(R26-R24) -> 0.5723375 | AR26: =(AC26-AC24)/(AI26-AI24) -> 0.26344814 | AS26: =AR26/AQ26 -> 0.46030208 | AT26: =(BE26-BE24)/(AI26-AI24) -> 0.57581846 | AU26: =AT26/AP26 -> 0.062880126 | AW26: =AK26+AM26 -> 0.68483002 | BD26: =IF(ISNUMBER(C26),C26*1000/100,"") -> 0.3656 | BE26: =IF(ISNUMBER(D26),D26*1000/100,0) -> 13.4696 | BF26: =IF(ISNUMBER(E26),E26*1000/100,"") -> 59.7274 | BG26: =IF(ISNUMBER(F26),F26*1000/100,"") | BH26: =IF(ISNUMBER(G26),G26*1000/100,"") | BI26: =IF(ISNUMBER(H26),H26*1000/100,"") | BJ26: =IF(ISNUMBER(I26),I26*1000/100,"") | BK26: =IF(ISNUMBER(J26),J26*1000/100,"") | BL26: =IF(ISNUMBER(K26),K26*1000/100,"") | BM26: =IF(ISNUMBER(L26),L26*1000/100,"") | ... BO26: =IF(ISNUMBER(N26),N26*1000/100,"") | BQ26: =S28 -> r1 | BS26: =B26 -> Jeff_SloHot50_Biostat 2L-22-13 | BU26: =BE26 -> 13.4696 | BY26: =$BF$15-BF26 -> 39.6657 | CA26: =BY26/R28 -> 0.54336575 | CB26: =BY26-BY24 -> 9.1131 | CC26: =CB26/(R28-R26) -> 0.95927368
B27: Jeff_SloHot50_Biostat 2L-22-14 | C27: 0.03325 | D27: 0.565 | E27: 7.16421 | R27: =R25+12+4 -> 63.5 | S27: r2 | T27: 14 | V27: - | W27: 24.48 | X27: 36 | Y27: 7.2475 | Z27: 7.3458 | AA27: 8 | AB27: =Z27-Y27 -> 0.0983 | AC27: =AB27/(AA27/1000) -> 12.2875 | AD27: 20 | AE27: =FAMES!N28 -> 3.076 | AF27: =AE27/AD27 -> 0.1538 | AG27: =AF27*AC27 -> 1.8898175 | AI27: =$BF$15-BF27 -> 27.751 | AJ27: =BE27/R27 -> 0.088976378 | AK27: =BE27/AI27 -> 0.20359627 | AL27: =AC27/R27 -> 0.19350394 | AM27: =AC27/AI27 -> 0.44277684 | AN27: =AG27/R27 -> 0.029760906 | AO27: =AG27/AI27 -> 0.068099078 | AP27: =BF25-BF27 -> 8.9369 | AQ27: =AP27/(R27-R25) -> 0.55855625 | AR27: =(AC27-AC25)/(AI27-AI25) -> 0.38044512 | AS27: =AR27/AQ27 -> 0.68112231 | AT27: =(BE27-BE25)/(AI27-AI25) -> 0.4738444 | AU27: =AT27/AP27 -> 0.053021114 | AW27: =AK27+AM27 -> 0.6463731 | BD27: =IF(ISNUMBER(C27),C27*1000/100,"") -> 0.3325 | BE27: =IF(ISNUMBER(D27),D27*1000/100,0) -> 5.65 | BF27: =IF(ISNUMBER(E27),E27*1000/100,"") -> 71.6421 | BG27: =IF(ISNUMBER(F27),F27*1000/100,"") | BH27: =IF(ISNUMBER(G27),G27*1000/100,"") | BI27: =IF(ISNUMBER(H27),H27*1000/100,"") | BJ27: =IF(ISNUMBER(I27),I27*1000/100,"") | BK27: =IF(ISNUMBER(J27),J27*1000/100,"") | BL27: =IF(ISNUMBER(K27),K27*1000/100,"") | BM27: =IF(ISNUMBER(L27),L27*1000/100,"") | ... BO27: =IF(ISNUMBER(N27),N27*1000/100,"") | BQ27: =S29 -> r2 | BS27: =B27 -> Jeff_SloHot50_Biostat 2L-22-14 | BU27: =BE27 -> 5.65 | BY27: =$BF$15-BF27 -> 27.751 | CA27: =BY27/R29 -> 0.38015068 | CB27: =BY27-BY25 -> 8.9369 | CC27: =CB27/(R29-R27) -> 0.94072632
B28: Jeff_SloHot50_Biostat 2L-22-15 | C28: 0.04059 | D28: 1.62715 | E28: 5.56637 | Q28: 0.71875 | R28: =R26+5+4.5 -> 73 | S28: r1 | T28: 15 | W28: 22.76 | X28: 87 | Y28: 7.1732 | Z28: 7.2678 | AA28: 8 | AB28: =Z28-Y28 -> 0.0946 | AC28: =AB28/(AA28/1000) -> 11.825 | AD28: 13.4 | AE28: =FAMES!N29 -> 2.166 | AF28: =AE28/AD28 -> 0.16164179 | AG28: =AF28*AC28 -> 1.9114142 | AI28: =$BF$14-BF28 -> 43.7737 | AJ28: =BE28/R28 -> 0.22289726 | AK28: =BE28/AI28 -> 0.37171863 | AL28: =AC28/R28 -> 0.1619863 | AM28: =AC28/AI28 -> 0.27013938 | AN28: =AG28/R28 -> 0.026183756 | AO28: =AG28/AI28 -> 0.043665813 | AP28: =BF26-BF28 -> 4.0637 | AQ28: =AP28/(R28-R26) -> 0.42775789 | AR28: =(AC28-AC26)/(AI28-AI26) -> -0.4675542 | AS28: =AR28/AQ28 -> -1.0930346 | AT28: =(BE28-BE26)/(AI28-AI26) -> 0.6894948 | AU28: =AT28/AP28 -> 0.16967168 | AW28: =AK28+AM28 -> 0.64185801 | BD28: =IF(ISNUMBER(C28),C28*1000/100,"") -> 0.4059 | BE28: =IF(ISNUMBER(D28),D28*1000/100,0) -> 16.2715 | BF28: =IF(ISNUMBER(E28),E28*1000/100,"") -> 55.6637 | BG28: =IF(ISNUMBER(F28),F28*1000/100,"") | BH28: =IF(ISNUMBER(G28),G28*1000/100,"") | BI28: =IF(ISNUMBER(H28),H28*1000/100,"") | BJ28: =IF(ISNUMBER(I28),I28*1000/100,"") | BK28: =IF(ISNUMBER(J28),J28*1000/100,"") | BL28: =IF(ISNUMBER(K28),K28*1000/100,"") | BM28: =IF(ISNUMBER(L28),L28*1000/100,"") | ... BO28: =IF(ISNUMBER(N28),N28*1000/100,"") | BQ28: =S30 -> r1 | BS28: =B28 -> Jeff_SloHot50_Biostat 2L-22-15 | BU28: =BE28 -> 16.2715 | BY28: =$BF$15-BF28 -> 43.7294 | CA28: =BY28/R30 -> 0.47403144 | CB28: =BY28-BY26 -> 4.0637 | CC28: =CB28/(R30-R28) -> 0.2111013
B29: Jeff_SloHot50_Biostat 2L-22-16 | C29: 0.03641 | D29: 0.86907 | E29: 6.63243 | R29: =R27+5+4.5 -> 73 | S29: r2 | T29: 16 | W29: 22.36 | X29: 46 | Y29: 7.1475 | Z29: 7.2345 | AA29: 8 | AB29: =Z29-Y29 -> 0.087 | AC29: =AB29/(AA29/1000) -> 10.875 | AD29: 13.5 | AE29: =FAMES!N30 -> 2.2275 | AF29: =AE29/AD29 -> 0.165 | AG29: =AF29*AC29 -> 1.794375 | AI29: =$BF$15-BF29 -> 33.0688 | AJ29: =BE29/R29 -> 0.11905068 | AK29: =BE29/AI29 -> 0.26280663 | AL29: =AC29/R29 -> 0.1489726 | AM29: =AC29/AI29 -> 0.32885983 | AN29: =AG29/R29 -> 0.024580479 | AO29: =AG29/AI29 -> 0.054261872 | AP29: =BF27-BF29 -> 5.3178 | AQ29: =AP29/(R29-R27) -> 0.55976842 | AR29: =(AC29-AC27)/(AI29-AI27) -> -0.26561736 | AS29: =AR29/AQ29 -> -0.47451294 | AT29: =(BE29-BE27)/(AI29-AI27) -> 0.57179661 | AU29: =AT29/AP29 -> 0.10752503 | AW29: =AK29+AM29 -> 0.59166647 | BD29: =IF(ISNUMBER(C29),C29*1000/100,"") -> 0.3641 | BE29: =IF(ISNUMBER(D29),D29*1000/100,0) -> 8.6907 | BF29: =IF(ISNUMBER(E29),E29*1000/100,"") -> 66.3243 | BG29: =IF(ISNUMBER(F29),F29*1000/100,"") | BH29: =IF(ISNUMBER(G29),G29*1000/100,"") | BI29: =IF(ISNUMBER(H29),H29*1000/100,"") | BJ29: =IF(ISNUMBER(I29),I29*1000/100,"") | BK29: =IF(ISNUMBER(J29),J29*1000/100,"") | BL29: =IF(ISNUMBER(K29),K29*1000/100,"") | BM29: =IF(ISNUMBER(L29),L29*1000/100,"") | ... BO29: =IF(ISNUMBER(N29),N29*1000/100,"") | BQ29: =S31 -> r2 | BS29: =B29 -> Jeff_SloHot50_Biostat 2L-22-16 | BU29: =BE29 -> 8.6907 | BY29: =$BF$15-BF29 -> 33.0688 | CA29: =BY29/R31 -> 0.35846938 | CB29: =BY29-BY27 -> 5.3178 | CC29: =CB29/(R31-R29) -> 0.27624935
B30: Jeff_SloHot50_Biostat 2L-22-17 | C30: 0.04231 | D30: 2.16096 | E30: 4.71948 | P30: 45599 | Q30: 0.52083333 | R30: =R28+12+7+0.25 -> 92.25 | S30: r1 | T30: 17 | W30: 24.72 | X30: 108 | Y30: 7.1382 | Z30: 7.2331 | AA30: 8 | AB30: =Z30-Y30 -> 0.0949 | AC30: =AB30/(AA30/1000) -> 11.8625 | AD30: 13.2 | AE30: =FAMES!N31 -> 2.266 | AF30: =AE30/AD30 -> 0.17166667 | AG30: =AF30*AC30 -> 2.0363958 | AI30: =$BF$14-BF30 -> 52.2426 | AJ30: =BE30/R30 -> 0.23425041 | AK30: =BE30/AI30 -> 0.41363944 | AL30: =AC30/R30 -> 0.12859079 | AM30: =AC30/AI30 -> 0.22706565 | AN30: =AG30/R30 -> 0.022074752 | AO30: =AG30/AI30 -> 0.038979603 | AP30: =BF28-BF30 -> 8.4689 | AQ30: =AP30/(R30-R28) -> 0.43994286 | AR30: =(AC30-AC28)/(AI30-AI28) -> 0.0044279659 | AS30: =AR30/AQ30 -> 0.010064866 | AT30: =(BE30-BE28)/(AI30-AI28) -> 0.63031799 | AU30: =AT30/AP30 -> 0.074427374 | AW30: =AK30+AM30 -> 0.6407051 | BD30: =IF(ISNUMBER(C30),C30*1000/100,"") -> 0.4231 | BE30: =IF(ISNUMBER(D30),D30*1000/100,0) -> 21.6096 | BF30: =IF(ISNUMBER(E30),E30*1000/100,"") -> 47.1948 | BG30: =IF(ISNUMBER(F30),F30*1000/100,"") | BH30: =IF(ISNUMBER(G30),G30*1000/100,"") | BI30: =IF(ISNUMBER(H30),H30*1000/100,"") | BJ30: =IF(ISNUMBER(I30),I30*1000/100,"") | BK30: =IF(ISNUMBER(J30),J30*1000/100,"") | BL30: =IF(ISNUMBER(K30),K30*1000/100,"") | BM30: =IF(ISNUMBER(L30),L30*1000/100,"") | ... BO30: =IF(ISNUMBER(N30),N30*1000/100,"") | BQ30: r1 | BS30: =B30 -> Jeff_SloHot50_Biostat 2L-22-17 | BU30: =BE30 -> 21.6096
B31: Jeff_SloHot50_Biostat 2L-22-18 | C31: 0.04455 | D31: 1.5276 | E31: 5.63602 | R31: =R29+12+7+0.25 -> 92.25 | S31: r2 | T31: 18 | W31: 23.68 | X31: 67 | Y31: 7.1741 | Z31: 7.2712 | AA31: 8 | AB31: =Z31-Y31 -> 0.0971 | AC31: =AB31/(AA31/1000) -> 12.1375 | AD31: 17.7 | AE31: =FAMES!N32 -> 3.2105 | AF31: =AE31/AD31 -> 0.18138418 | AG31: =AF31*AC31 -> 2.2015505 | AI31: =$BF$15-BF31 -> 43.0329 | AJ31: =BE31/R31 -> 0.1655935 | AK31: =BE31/AI31 -> 0.35498421 | AL31: =AC31/R31 -> 0.13157182 | AM31: =AC31/AI31 -> 0.28205164 | AN31: =AG31/R31 -> 0.023865046 | AO31: =AG31/AI31 -> 0.051159706 | AP31: =BF29-BF31 -> 9.9641 | AQ31: =AP31/(R31-R29) -> 0.51761558 | AR31: =(AC31-AC29)/(AI31-AI29) -> 0.12670487 | AS31: =AR31/AQ31 -> 0.24478566 | AT31: =(BE31-BE29)/(AI31-AI29) -> 0.66090264 | AU31: =AT31/AP31 -> 0.066328383 | AW31: =AK31+AM31 -> 0.63703585 | BD31: =IF(ISNUMBER(C31),C31*1000/100,"") -> 0.4455 | BE31: =IF(ISNUMBER(D31),D31*1000/100,0) -> 15.276 | BF31: =IF(ISNUMBER(E31),E31*1000/100,"") -> 56.3602 | BG31: =IF(ISNUMBER(F31),F31*1000/100,"") | BH31: =IF(ISNUMBER(G31),G31*1000/100,"") | BI31: =IF(ISNUMBER(H31),H31*1000/100,"") | BJ31: =IF(ISNUMBER(I31),I31*1000/100,"") | BK31: =IF(ISNUMBER(J31),J31*1000/100,"") | BL31: =IF(ISNUMBER(K31),K31*1000/100,"") | BM31: =IF(ISNUMBER(L31),L31*1000/100,"") | ... BO31: =IF(ISNUMBER(N31),N31*1000/100,"") | BQ31: r2 | BS31: =B31 -> Jeff_SloHot50_Biostat 2L-22-18 | BU31: =BE31 -> 15.276
BU32: =BE32 -> 0
BU33: =BE33 -> 0
BU34: =BE34 -> 0
BU35: =BE35 -> 0
BU36: =BE36 -> 0
BU37: =BE37 -> 0
U71: =390/24 -> 16.25

Sheet FAMES
B1: 1 | C1: 2 | D1: 3 | E1: 4 | F1: 5 | G1: 6 | H1: 7 | I1: 8 | J1: 9 | K1: 10 | L1: 11 | M1: 12 | N1: 13 | O1: 14 | P1: 15 | Q1: 16 | R1: 17 | S1: 18
A2: C13:0 | B2: 0.78 | C2: 0.793 | D2: 0.862 | E2: 0.884 | F2: 0.883 | G2: 0.827 | H2: 0.747 | I2: 0.841 | J2: 0.872 | K2: 1.015 | L2: 0.934 | M2: 0.711 | N2: 0.979 | O2: 0.982 | P2: 0.85 | Q2: 0.995 | R2: 0.723 | S2: 0.968
A3: C14:0 | B3: N.D. | C3: N.D. | D3: N.D. | E3: N.D. | F3: N.D. | G3: N.D. | H3: N.D. | I3: N.D. | J3: N.D. | K3: N.D. | L3: N.D. | M3: 0.016 | N3: 0.003 | O3: N.D. | P3: N.D. | Q3: N.D. | R3: N.D. | S3: N.D.
A4: C16:0 | B4: 0.155 | C4: 0.135 | D4: 0.287 | E4: 0.16 | F4: 0.277 | G4: 0.156 | H4: 0.334 | I4: 0.289 | J4: 0.682 | K4: 0.382 | L4: 0.69 | M4: 0.391 | N4: 0.927 | O4: 0.871 | P4: 0.714 | Q4: 0.671 | R4: 0.721 | S4: 0.91
A5: C16:1 | B5: 0.018 | C5: 0.005 | D5: 0.092 | E5: 0.012 | F5: 0.089 | G5: 0.035 | H5: 0.126 | I5: 0.104 | J5: 0.346 | K5: 0.178 | L5: 0.341 | M5: 0.227 | N5: 0.503 | O5: 0.516 | P5: 0.391 | Q5: 0.374 | R5: 0.408 | S5: 0.563
A6: C18:0 | B6: 0.111 | C6: 0.103 | D6: 0.158 | E6: 0.116 | F6: 0.161 | G6: 0.092 | H6: 0.194 | I6: 0.135 | J6: 0.342 | K6: 0.209 | L6: 0.318 | M6: 0.223 | N6: 0.428 | O6: 0.495 | P6: 0.342 | Q6: 0.394 | R6: 0.358 | S6: 0.538
A7: C18:1 | B7: 0.097 | C7: 0.025 | D7: 0.749 | E7: 0.062 | F7: 0.825 | G7: 0.141 | H7: 1.163 | I7: 0.682 | J7: 2.398 | K7: 1.14 | L7: 2.092 | M7: 1.573 | N7: 3.037 | O7: 3.267 | P7: 2.335 | Q7: 2.33 | R7: 2.476 | S7: 3.457
A8: C18:2 | B8: 0.08 | C8: 0.031 | D8: 0.322 | E8: 0.05 | F8: 0.252 | G8: 0.164 | H8: 0.281 | I8: 0.509 | J8: 0.441 | K8: 0.47 | L8: 0.478 | M8: 0.498 | N8: 0.63 | O8: 0.822 | P8: 0.446 | Q8: 0.555 | R8: 0.466 | S8: 0.774
A9: C21:0 | B9: N.D. | C9: N.D. | D9: N.D. | E9: N.D. | F9: N.D. | G9: N.D. | H9: N.D. | I9: N.D. | J9: N.D. | K9: N.D. | L9: N.D. | M9: N.D. | N9: N.D. | O9: N.D. | P9: N.D. | Q9: N.D. | R9: N.D. | S9: N.D.
A10: C24:0 | B10: 0.007 | C10: 0.006 | D10: 0.021 | E10: 0.006 | F10: 0.033 | G10: 0.006 | H10: 0.053 | I10: 0.018 | J10: 0.112 | K10: 0.049 | L10: 0.104 | M10: 0.087 | N10: 0.143 | O10: 0.181 | P10: 0.104 | Q10: 0.131 | R10: 0.103 | S10: 0.179
C14: C13:0 | D14: C14:0 | E14: C16:0 | F14: C16:1 | G14: C18:0 | H14: C18:1 | I14: C18:2 | J14: C21:0 | K14: C24:0 | M14: total mg/mL | N14: mg in 500 uL hexane
B15: 1 | C15: 0.78 | D15: N.D. | E15: 0.155 | F15: 0.018 | G15: 0.111 | H15: 0.097 | I15: 0.08 | J15: N.D. | K15: 0.007 | M15: =SUM(D15:K15) -> 0.468 | N15: =M15*0.5 -> 0.234
B16: 2 | C16: 0.793 | D16: N.D. | E16: 0.135 | F16: 0.005 | G16: 0.103 | H16: 0.025 | I16: 0.031 | J16: N.D. | K16: 0.006 | M16: =SUM(D16:K16) -> 0.305 | N16: =M16*0.5 -> 0.1525
B17: 3 | C17: 0.862 | D17: N.D. | E17: 0.287 | F17: 0.092 | G17: 0.158 | H17: 0.749 | I17: 0.322 | J17: N.D. | K17: 0.021 | M17: =SUM(D17:K17) -> 1.629 | N17: =M17*0.5 -> 0.8145
B18: 4 | C18: 0.884 | D18: N.D. | E18: 0.16 | F18: 0.012 | G18: 0.116 | H18: 0.062 | I18: 0.05 | J18: N.D. | K18: 0.006 | M18: =SUM(D18:K18) -> 0.406 | N18: =M18*0.5 -> 0.203
B19: 5 | C19: 0.883 | D19: N.D. | E19: 0.277 | F19: 0.089 | G19: 0.161 | H19: 0.825 | I19: 0.252 | J19: N.D. | K19: 0.033 | M19: =SUM(D19:K19) -> 1.637 | N19: =M19*0.5 -> 0.8185
B20: 6 | C20: 0.827 | D20: N.D. | E20: 0.156 | F20: 0.035 | G20: 0.092 | H20: 0.141 | I20: 0.164 | J20: N.D. | K20: 0.006 | M20: =SUM(D20:K20) -> 0.594 | N20: =M20*0.5 -> 0.297
B21: 7 | C21: 0.747 | D21: N.D. | E21: 0.334 | F21: 0.126 | G21: 0.194 | H21: 1.163 | I21: 0.281 | J21: N.D. | K21: 0.053 | M21: =SUM(D21:K21) -> 2.151 | N21: =M21*0.5 -> 1.0755
B22: 8 | C22: 0.841 | D22: N.D. | E22: 0.289 | F22: 0.104 | G22: 0.135 | H22: 0.682 | I22: 0.509 | J22: N.D. | K22: 0.018 | M22: =SUM(D22:K22) -> 1.737 | N22: =M22*0.5 -> 0.8685
B23: 9 | C23: 0.872 | D23: N.D. | E23: 0.682 | F23: 0.346 | G23: 0.342 | H23: 2.398 | I23: 0.441 | J23: N.D. | K23: 0.112 | M23: =SUM(D23:K23) -> 4.321 | N23: =M23*0.5 -> 2.1605
B24: 10 | C24: 1.015 | D24: N.D. | E24: 0.382 | F24: 0.178 | G24: 0.209 | H24: 1.14 | I24: 0.47 | J24: N.D. | K24: 0.049 | M24: =SUM(D24:K24) -> 2.428 | N24: =M24*0.5 -> 1.214
B25: 11 | C25: 0.934 | D25: N.D. | E25: 0.69 | F25: 0.341 | G25: 0.318 | H25: 2.092 | I25: 0.478 | J25: N.D. | K25: 0.104 | M25: =SUM(D25:K25) -> 4.023 | N25: =M25*0.5 -> 2.0115
B26: 12 | C26: 0.711 | D26: 0.016 | E26: 0.391 | F26: 0.227 | G26: 0.223 | H26: 1.573 | I26: 0.498 | J26: N.D. | K26: 0.087 | M26: =SUM(D26:K26) -> 3.015 | N26: =M26*0.5 -> 1.5075
B27: 13 | C27: 0.979 | D27: 0.003 | E27: 0.927 | F27: 0.503 | G27: 0.428 | H27: 3.037 | I27: 0.63 | J27: N.D. | K27: 0.143 | M27: =SUM(D27:K27) -> 5.671 | N27: =M27*0.5 -> 2.8355
B28: 14 | C28: 0.982 | D28: N.D. | E28: 0.871 | F28: 0.516 | G28: 0.495 | H28: 3.267 | I28: 0.822 | J28: N.D. | K28: 0.181 | M28: =SUM(D28:K28) -> 6.152 | N28: =M28*0.5 -> 3.076
B29: 15 | C29: 0.85 | D29: N.D. | E29: 0.714 | F29: 0.391 | G29: 0.342 | H29: 2.335 | I29: 0.446 | J29: N.D. | K29: 0.104 | M29: =SUM(D29:K29) -> 4.332 | N29: =M29*0.5 -> 2.166
B30: 16 | C30: 0.995 | D30: N.D. | E30: 0.671 | F30: 0.374 | G30: 0.394 | H30: 2.33 | I30: 0.555 | J30: N.D. | K30: 0.131 | M30: =SUM(D30:K30) -> 4.455 | N30: =M30*0.5 -> 2.2275
B31: 17 | C31: 0.723 | D31: N.D. | E31: 0.721 | F31: 0.408 | G31: 0.358 | H31: 2.476 | I31: 0.466 | J31: N.D. | K31: 0.103 | M31: =SUM(D31:K31) -> 4.532 | N31: =M31*0.5 -> 2.266
B32: 18 | C32: 0.968 | D32: N.D. | E32: 0.91 | F32: 0.563 | G32: 0.538 | H32: 3.457 | I32: 0.774 | J32: N.D. | K32: 0.179 | M32: =SUM(D32:K32) -> 6.421 | N32: =M32*0.5 -> 3.2105

Sheet questions

Sheet seedCultureNotes
